Workbook

Sheet ÍNDICE
A1: ÍNDICE — CLIQUE NO NOME PARA ABRIR A ABA [MODELO EM BRANCO — pronto para uma semana nova]
A3: ABAS DE TRABALHO
A4: =HYPERLINK("#'Entrada de Dados'!A1","Entrada de Dados") | B4: onde você digita pedido e entrega
A5: =HYPERLINK("#'RESUMO'!A1","RESUMO") | B5: o resultado final, calculado sozinho
A6: =HYPERLINK("#'BALANÇO FINANCEIRO'!A1","BALANÇO FINANCEIRO") | B6: custos reais da semana e saldo (positivo ou negativo)
A7: =HYPERLINK("#'DIFERENÇA'!A1","DIFERENÇA") | B7: quanto faltou entregar, produto por produto
A8: =HYPERLINK("#'MAPA DE MONTAGEM'!A1","MAPA DE MONTAGEM") | B8: separação da carga por rota — segunda e terça
A9: =HYPERLINK("#'MAPA DE PRODUÇÃO'!A1","MAPA DE PRODUÇÃO") | B9: quem planta o quê, por mês
A10: =HYPERLINK("#'MOTIVO'!A1","MOTIVO") | B10: lista de motivos de devolução
A12: COMO USAR — PASSO A PASSO DA SEMANA
A13: 1. Pedido da prefeitura chega
A14: Aba "Entrada de Dados", bloco de cima (ESCOLAS): digite a quantidade de cada produto, na linha da escola e coluna do produto.
A15: 2. Divisão entre produtores + pedido a eles
A16: Decisão da cooperativa (fora da planilha). Depois, aba "Entrada de Dados", bloco do meio (PEDIDO PRODUTORES): digite quanto foi pedido a cada produtor. A partir daqui, a ficha de cada produtor (clique no nome) já mostra o Pedido e a Entrega (vêm sozinhos da Entrada de Dados) — dá pra imprimir e entregar antes da entrega chegar, como referência de quanto ele deve trazer. É a mesma ficha que depois vira o romaneio: quando ele chegar, digite a quantidade em ENTREGA PRODUTORES (passo 3 abaixo) e, se o galpão rejeitar algo, a Devolução direto na ficha do produtor — sem criar outro documento.
A17: 3. Recebimento e rejeição no galpão
A18: Aba "Entrada de Dados", bloco de baixo (ENTREGA PRODUTORES): digite quanto cada produtor trouxe. Depois abra a ficha do produtor (clique no nome) e digite a Devolução, se o galpão rejeitar algo.
A20: 4. Complemento, se faltar produto — aba "COMPLEMENTOS": bloco B (Recebimento no galpão) uma linha por entrega, gera o pagamento. Bloco C (Entrega às escolas): escolha o Nº do recebimento, produtor/produto vêm sozinhos. Só 15 linhas aparecem por bloco — clique no "+" à esquerda da grade pra abrir mais. Pra imprimir um comprovante de complemento, use o seletor no topo da própria aba (Tipo + Nº) — o documento muda sozinho, sem mexer nos dados.
A21: 5. Montagem e carregamento
A22: Aba "MAPA DE MONTAGEM": as quantidades de cada rota aparecem sozinhas. Preencha só Peso Embarcado, Veículo e Motorista no rodapé de cada rota, na hora de carregar. Imprima a rota pra levar no caminhão.
A23: 6. Entrega e assinatura na escola
A24: Imprima a ficha da escola em 4 cópias antes de sair — é o romaneio. A merendeira/diretora confere, anota o que recebeu de próprio punho no papel, e assina.
... A42: ESCOLAS
A43: CÓDIGO | B43: ESCOLA (clique para abrir) | C43: BAIRRO
A44: ='E M ABELARDO DE LAMARE'!B5 | B44: =HYPERLINK("#'E M ABELARDO DE LAMARE'!A1",'E M ABELARDO DE LAMARE'!B2) | C44: ='E M ABELARDO DE LAMARE'!B3
A45: ='E M BATAILLARD'!B5 | B45: =HYPERLINK("#'E M BATAILLARD'!A1",'E M BATAILLARD'!B2) | C45: ='E M BATAILLARD'!B3
A46: ='E M LEONARDO BOFF'!B5 | B46: =HYPERLINK("#'E M LEONARDO BOFF'!A1",'E M LEONARDO BOFF'!B2) | C46: ='E M LEONARDO BOFF'!B3
A47: ='E M CLEMENTE FERNANDES'!B5 | B47: =HYPERLINK("#'E M CLEMENTE FERNANDES'!A1",'E M CLEMENTE FERNANDES'!B2) | C47: ='E M CLEMENTE FERNANDES'!B3
A48: ='E M DOM PEDRO DE ALCÂNTARA'!B5 | B48: =HYPERLINK("#'E M DOM PEDRO DE ALCÂNTARA'!A1",'E M DOM PEDRO DE ALCÂNTARA'!B2) | C48: ='E M DOM PEDRO DE ALCÂNTARA'!B3
A49: ='E M DUQUE DE CAXIAS'!B5 | B49: =HYPERLINK("#'E M DUQUE DE CAXIAS'!A1",'E M DUQUE DE CAXIAS'!B2) | C49: ='E M DUQUE DE CAXIAS'!B3
A50: ='E M LUIZ CARLOS SOARES'!B5 | B50: =HYPERLINK("#'E M LUIZ CARLOS SOARES'!A1",'E M LUIZ CARLOS SOARES'!B2) | C50: ='E M LUIZ CARLOS SOARES'!B3
A51: ='ESCOLA MUNICIPAL GENERAL HEITOR'!B5 | B51: =HYPERLINK("#'ESCOLA MUNICIPAL GENERAL HEITOR'!A1",'ESCOLA MUNICIPAL GENERAL HEITOR'!B2) | C51: ='ESCOLA MUNICIPAL GENERAL HEITOR'!B3
A52: ='E M JOÃO KOPKE'!B5 | B52: =HYPERLINK("#'E M JOÃO KOPKE'!A1",'E M JOÃO KOPKE'!B2) | C52: ='E M JOÃO KOPKE'!B3
A53: ='ESCOLA MUNICIPAL ODETTE FONSECA'!B5 | B53: =HYPERLINK("#'ESCOLA MUNICIPAL ODETTE FONSECA'!A1",'ESCOLA MUNICIPAL ODETTE FONSECA'!B2) | C53: ='ESCOLA MUNICIPAL ODETTE FONSECA'!B3
A54: ='E M GOVERNADOR MARCELLO ALENCAR'!B5 | B54: =HYPERLINK("#'E M GOVERNADOR MARCELLO ALENCAR'!A1",'E M GOVERNADOR MARCELLO ALENCAR'!B2) | C54: ='E M GOVERNADOR MARCELLO ALENCAR'!B3
A55: ='E M PROF JOAQUIM DEISTER'!B5 | B55: =HYPERLINK("#'E M PROF JOAQUIM DEISTER'!A1",'E M PROF JOAQUIM DEISTER'!B2) | C55: ='E M PROF JOAQUIM DEISTER'!B3
A56: ='E M ROBERT KENNEDY'!B5 | B56: =HYPERLINK("#'E M ROBERT KENNEDY'!A1",'E M ROBERT KENNEDY'!B2) | C56: ='E M ROBERT KENNEDY'!B3
A57: ='E M ROTARY'!B5 | B57: =HYPERLINK("#'E M ROTARY'!A1",'E M ROTARY'!B2) | C57: ='E M ROTARY'!B3
A58: ='E M ROSALINA NICOLAY'!B5 | B58: =HYPERLINK("#'E M ROSALINA NICOLAY'!A1",'E M ROSALINA NICOLAY'!B2) | C58: ='E M ROSALINA NICOLAY'!B3
A59: ='E M DE EDUCAÇÃO ESPECIAL SANTOS'!B5 | B59: =HYPERLINK("#'E M DE EDUCAÇÃO ESPECIAL SANTOS'!A1",'E M DE EDUCAÇÃO ESPECIAL SANTOS'!B2) | C59: ='E M DE EDUCAÇÃO ESPECIAL SANTOS'!B3
A60: ='E M SOROPTIMISTA'!B5 | B60: =HYPERLINK("#'E M SOROPTIMISTA'!A1",'E M SOROPTIMISTA'!B2) | C60: ='E M SOROPTIMISTA'!B3
...

Sheet Entrada de Dados
A1: ENTRADA DE DADOS
A2: PREÇO (R$/kg) | C2: 15.57 | D2: 7.7 | E2: 16.94 | F2: 14.62 | G2: 12.05 | H2: 11.59 | I2: 9.87 | J2: 13.67 | K2: 10.2 | L2: 25.1 | M2: 8.56 | N2: 14.6 | O2: 19.11 | P2: 11.22 | Q2: 16.63 | R2: 65.68 | S2: 15.45 | T2: 10.24 | U2: 13.55
A4: PEDIDO DAS ESCOLAS (kg)
A5: CÓDIGO | B5: ESCOLA | C5: Abacate | D5: Abobrinha | E5: Agrião | F5: Alface lisa | G5: Banana prata | H5: Batata inglesa | I5: Beterraba | J5: Brócolis | K5: Cenoura | L5: Cheiro verde | M5: Chuchu | N5: Couve manteiga | O5: Couve-flor | P5: Espinafre | Q5: Maçã gala | R5: Mel | S5: Ovos (dz) | T5: Repolho | U5: Tangerina ponkan | V5: Aba real (ref.)
A6: ='E M ABELARDO DE LAMARE'!B5 | B6: =HYPERLINK("#'E M ABELARDO DE LAMARE'!A1",'E M ABELARDO DE LAMARE'!B2) | V6: E M ABELARDO DE LAMARE
A7: ='E M BATAILLARD'!B5 | B7: =HYPERLINK("#'E M BATAILLARD'!A1",'E M BATAILLARD'!B2) | V7: E M BATAILLARD
A8: ='E M LEONARDO BOFF'!B5 | B8: =HYPERLINK("#'E M LEONARDO BOFF'!A1",'E M LEONARDO BOFF'!B2) | V8: E M LEONARDO BOFF
A9: ='E M CLEMENTE FERNANDES'!B5 | B9: =HYPERLINK("#'E M CLEMENTE FERNANDES'!A1",'E M CLEMENTE FERNANDES'!B2) | V9: E M CLEMENTE FERNANDES
A10: ='E M DOM PEDRO DE ALCÂNTARA'!B5 | B10: =HYPERLINK("#'E M DOM PEDRO DE ALCÂNTARA'!A1",'E M DOM PEDRO DE ALCÂNTARA'!B2) | V10: E M DOM PEDRO DE ALCÂNTARA
A11: ='E M DUQUE DE CAXIAS'!B5 | B11: =HYPERLINK("#'E M DUQUE DE CAXIAS'!A1",'E M DUQUE DE CAXIAS'!B2) | V11: E M DUQUE DE CAXIAS
A12: ='E M LUIZ CARLOS SOARES'!B5 | B12: =HYPERLINK("#'E M LUIZ CARLOS SOARES'!A1",'E M LUIZ CARLOS SOARES'!B2) | V12: E M LUIZ CARLOS SOARES
A13: ='ESCOLA MUNICIPAL GENERAL HEITOR'!B5 | B13: =HYPERLINK("#'ESCOLA MUNICIPAL GENERAL HEITOR'!A1",'ESCOLA MUNICIPAL GENERAL HEITOR'!B2) | V13: ESCOLA MUNICIPAL GENERAL HEITOR
A14: ='E M JOÃO KOPKE'!B5 | B14: =HYPERLINK("#'E M JOÃO KOPKE'!A1",'E M JOÃO KOPKE'!B2) | V14: E M JOÃO KOPKE
A15: ='ESCOLA MUNICIPAL ODETTE FONSECA'!B5 | B15: =HYPERLINK("#'ESCOLA MUNICIPAL ODETTE FONSECA'!A1",'ESCOLA MUNICIPAL ODETTE FONSECA'!B2) | V15: ESCOLA MUNICIPAL ODETTE FONSECA
A16: ='E M GOVERNADOR MARCELLO ALENCAR'!B5 | B16: =HYPERLINK("#'E M GOVERNADOR MARCELLO ALENCAR'!A1",'E M GOVERNADOR MARCELLO ALENCAR'!B2) | V16: E M GOVERNADOR MARCELLO ALENCAR
A17: ='E M PROF JOAQUIM DEISTER'!B5 | B17: =HYPERLINK("#'E M PROF JOAQUIM DEISTER'!A1",'E M PROF JOAQUIM DEISTER'!B2) | V17: E M PROF JOAQUIM DEISTER
A18: ='E M ROBERT KENNEDY'!B5 | B18: =HYPERLINK("#'E M ROBERT KENNEDY'!A1",'E M ROBERT KENNEDY'!B2) | V18: E M ROBERT KENNEDY
A19: ='E M ROTARY'!B5 | B19: =HYPERLINK("#'E M ROTARY'!A1",'E M ROTARY'!B2) | V19: E M ROTARY
A20: ='E M ROSALINA NICOLAY'!B5 | B20: =HYPERLINK("#'E M ROSALINA NICOLAY'!A1",'E M ROSALINA NICOLAY'!B2) | V20: E M ROSALINA NICOLAY
A21: ='E M DE EDUCAÇÃO ESPECIAL SANTOS'!B5 | B21: =HYPERLINK("#'E M DE EDUCAÇÃO ESPECIAL SANTOS'!A1",'E M DE EDUCAÇÃO ESPECIAL SANTOS'!B2) | V21: E M DE EDUCAÇÃO ESPECIAL SANTOS
A22: ='E M SOROPTIMISTA'!B5 | B22: =HYPERLINK("#'E M SOROPTIMISTA'!A1",'E M SOROPTIMISTA'!B2) | V22: E M SOROPTIMISTA
A23: ='LICEU MUN PREFEITO CORDOLINO AM'!B5 | B23: =HYPERLINK("#'LICEU MUN PREFEITO CORDOLINO AM'!A1",'LICEU MUN PREFEITO CORDOLINO AM'!B2) | V23: LICEU MUN PREFEITO CORDOLINO AM
A24: ='E M ANTÔNIO LEITE GARCIA'!B5 | B24: =HYPERLINK("#'E M ANTÔNIO LEITE GARCIA'!A1",'E M ANTÔNIO LEITE GARCIA'!B2) | V24: E M ANTÔNIO LEITE GARCIA
A25: ='ESCOLA MUNICIPAL JORGE AMADO'!B5 | B25: =HYPERLINK("#'ESCOLA MUNICIPAL JORGE AMADO'!A1",'ESCOLA MUNICIPAL JORGE AMADO'!B2) | V25: ESCOLA MUNICIPAL JORGE AMADO
A26: ='ESCOLA MUNICIPAL LÚCIA DE ALMEI'!B5 | B26: =HYPERLINK("#'ESCOLA MUNICIPAL LÚCIA DE ALMEI'!A1",'ESCOLA MUNICIPAL LÚCIA DE ALMEI'!B2) | V26: ESCOLA MUNICIPAL LÚCIA DE ALMEI
A27: ='E M MAGDALENA TAGLIAFERRO'!B5 | B27: =HYPERLINK("#'E M MAGDALENA TAGLIAFERRO'!A1",'E M MAGDALENA TAGLIAFERRO'!B2) | V27: E M MAGDALENA TAGLIAFERRO
A28: ='ESCOLA MUNICIPAL MAJOR JÚLIO FR'!B5 | B28: =HYPERLINK("#'ESCOLA MUNICIPAL MAJOR JÚLIO FR'!A1",'ESCOLA MUNICIPAL MAJOR JÚLIO FR'!B2) | V28: ESCOLA MUNICIPAL MAJOR JÚLIO FR
A29: ='E M MARIETA GONÇALVES'!B5 | B29: =HYPERLINK("#'E M MARIETA GONÇALVES'!A1",'E M MARIETA GONÇALVES'!B2) | V29: E M MARIETA GONÇALVES
A30: ='ESCOLA MUNICIPAL ODETTE YOUNG M'!B5 | B30: =HYPERLINK("#'ESCOLA MUNICIPAL ODETTE YOUNG M'!A1",'ESCOLA MUNICIPAL ODETTE YOUNG M'!B2) | V30: ESCOLA MUNICIPAL ODETTE YOUNG M
A31: ='E M FÁBRICA DO SABER'!B5 | B31: =HYPERLINK("#'E M FÁBRICA DO SABER'!A1",'E M FÁBRICA DO SABER'!B2) | V31: E M FÁBRICA DO SABER
A32: ='ESCOLA MUNICIPAL PROFESSOR PAUL'!B5 | B32: =HYPERLINK("#'ESCOLA MUNICIPAL PROFESSOR PAUL'!A1",'ESCOLA MUNICIPAL PROFESSOR PAUL'!B2) | V32: ESCOLA MUNICIPAL PROFESSOR PAUL
A33: ='E M ROSEMIRA DE OLIVEIRA CAVALC'!B5 | B33: =HYPERLINK("#'E M ROSEMIRA DE OLIVEIRA CAVALC'!A1",'E M ROSEMIRA DE OLIVEIRA CAVALC'!B2) | V33: E M ROSEMIRA DE OLIVEIRA CAVALC
A34: ='E M AMÉLIA ANTUNES RABELLO'!B5 | B34: =HYPERLINK("#'E M AMÉLIA ANTUNES RABELLO'!A1",'E M AMÉLIA ANTUNES RABELLO'!B2) | V34: E M AMÉLIA ANTUNES RABELLO
A35: ='ESCOLA MUNICIPAL AUGUSTO PUGNAL'!B5 | B35: =HYPERLINK("#'ESCOLA MUNICIPAL AUGUSTO PUGNAL'!A1",'ESCOLA MUNICIPAL AUGUSTO PUGNAL'!B2) | V35: ESCOLA MUNICIPAL AUGUSTO PUGNAL
A36: ='ESCOLA MUNICIPAL CELINA SCHECHN'!B5 | B36: =HYPERLINK("#'ESCOLA MUNICIPAL CELINA SCHECHN'!A1",'ESCOLA MUNICIPAL CELINA SCHECHN'!B2) | V36: ESCOLA MUNICIPAL CELINA SCHECHN
A37: ='E M DARCY CORREA DA VEIGA'!B5 | B37: =HYPERLINK("#'E M DARCY CORREA DA VEIGA'!A1",'E M DARCY CORREA DA VEIGA'!B2) | V37: E M DARCY CORREA DA VEIGA
A38: ='E M DR PAULA BUARQUE'!B5 | B38: =HYPERLINK("#'E M DR PAULA BUARQUE'!A1",'E M DR PAULA BUARQUE'!B2) | V38: E M DR PAULA BUARQUE
A39: ='E M DR THEODORO MACHADO'!B5 | B39: =HYPERLINK("#'E M DR THEODORO MACHADO'!A1",'E M DR THEODORO MACHADO'!B2) | V39: E M DR THEODORO MACHADO
A40: ='E M ARNALDO DYCKERHOFF'!B5 | B40: =HYPERLINK("#'E M ARNALDO DYCKERHOFF'!A1",'E M ARNALDO DYCKERHOFF'!B2) | V40: E M ARNALDO DYCKERHOFF
A41: ='E M CARLOS CANEDO'!B5 | B41: =HYPERLINK("#'E M CARLOS CANEDO'!A1",'E M CARLOS CANEDO'!B2) | V41: E M CARLOS CANEDO
...

Sheet RESUMO
A1: RESUMO GERAL | H1: =HYPERLINK("#'ÍNDICE'!A1","◄ Voltar ao Índice")
A3: 🏫 ESCOLAS — PEDIDO × DEVOLUÇÃO × VALOR A COBRAR DA PREFEITURA
A4: PRODUTO | B4: PEDIDO (kg) | C4: REJEITADO NA ESCOLA (kg) | D4: ACEITO (kg) | E4: VALOR (R$/kg) | F4: VALOR A COBRAR (R$)
A5: ='Entrada de Dados'!C5 | B5: ='Entrada de Dados'!C197 | C5: ='E M ROTARY'!D9+'E M DE EDUCAÇÃO ESPECIAL SANTOS'!D9+'LICEU MUN PREFEITO CORDOLINO AM'!D9+'E M PREFEITO JAMIL SABRÁ'!D9+'LICEU MUNICIPAL CARLOS CHAGAS F'!D9+'E M PAULO FREIRE'!D9+'E M PROFª MARIA CAMPOS DA SILVA'!D9+'CASA DA EDUCAÇÃO VISCONDE DE MA'!D9+'CENTRO DE REFERÊNCIA EM EDUCAÇÃ'!D9+'ESCOLA SANTA LUIZA DE MARILLAC'!D9+'ESCOLA DOMÉSTICA NOSSA SENHORA '!D9+'ESCOLA MONSENHOR GENTIL'!D9+'ESCOLA PAROQUIAL NOSSA SENHORA '!D9+'ESCOLA PAROQUIAL SÃO PEDRO DE A'!D9+'CEI TERRA SANTA'!D9+'CEI PRIMEIRA INFÂNCIA'!D9+'CEI PROFª PATRÍCIA FERREIRA E S'!D9+'CEI DRA ZILDA ARNS NEUMANN'!D9+'CENTRO DE EDUCAÇÃO INFANTIL PRO'!D9+'CEI MONSENHOR PAULO ELIAS DAHER'!D9+'COLÉGIO GUNNAR VINGREN DE PETRÓ'!D9+'EDUCANDÁRIO TERRA SANTA'!D9+'CEI LIONS CLUBE DE PETRÓPOLIS'!D9+'ESCOLA PAROQUIAL NOSSA SENHO 2'!D9+'CENTRO DE EDUCAÇÃO INFANTIL IRM'!D9+'E M LUIZ CARLOS SOARES'!D9+'ESCOLA GERMANO VALENTE'!D9+'ESCOLA PAROQUIAL NOSSA SENHO 3'!D9+'CEI JORGE ROLANDO DA SILVA'!D9+'E M CLEMENTE FERNANDES'!D9+'E M GERALDO VENTURA DIAS'!D9+'ESCOLA DAS COMUNIDADES SANTO AN'!D9+'CEI PROFª ROSANGELA DA SILVA LE'!D9+'CEI DEISE ELOY GOMES'!D9+'CEI PROFª SONIA REGINA SCUDESE '!D9+'CEI TIA ALICE'!D9+'E M BATAILLARD'!D9+'E M SOROPTIMISTA'!D9+'E M SALVADOR KLING'!D9+'ESCOLA MUNICIPALIZADA FREI ANIC'!D9+'ESCOLA SÃO JUDAS TADEU'!D9+'CEI PEDRAS BRANCAS'!D9+'CEI MARIA THEREZA KLING DO VALL'!D9+'CEI DONA ESPERANZA DE BOURBON D'!D9+'CEI GIUSEPPE-NEVA VOLONTERIO'!D9+'CENTRO DE EDUCAÇÃO INFANTIL SÃO'!D9+'E M LEONARDO BOFF'!D9+'ESCOLA MUNICIPAL GENERAL HEITOR'!D9+'E M JOHANN NOEL'!D9+'ESCOLA SANTA MARIA GORETTI'!D9+'ESCOLA SANTA RITA DE CASSIA'!D9+'ESCOLA SÃO JOÃO BATISTA'!D9+'CEI CASA DA SOLIDARIEDADE DE NO'!D9+'CEI A SEMENTEIRA'!D9+'CEI VILA SAO JOSE'!D9+'E M DR RUBENS DE CASTRO BOMTEMP'!D9+'CEI FREI LEÃO'!D9+'CEI SÃO JOÃO BATISTA'!D9+'CEI JURACI PINTO DO AMARAL DE C'!D9+'E M PEDRO AMADO'!D9+'E M ABELARDO DE LAMARE'!D9+'ESCOLA MUNICIPAL SENADOR MARIO '!D9+'ESCOLA PAROQUIAL SÃO PIO X'!D9+'CEI SÃO CHARBEL'!D9+'E M ROSALINA NICOLAY'!D9+'CEI INÊS BELARMINO DE SOUZA'!D9+'E M PROFª MARIA DA GLÓRIA QUEIR'!D9+'CENTRO EDUCACIONAL COMUNIDADE S'!D9+'CEI ROMANO CANAVESE'!D9+'CEI CÉLIA LÔBO PAULO'!D9+'CEI PROFª DORA KILLER'!D9+'CEI ALTO INDEPENDÊNCIA'!D9+'ESCOLA MUNICIPAL ALTO INDEPENDÊ'!D9+'E M PAPA JOÃO PAULO II'!D9+'CEI ANDRÉ REBOUÇAS'!D9+'CEI PROFª HERMÍNIA MATHEUS'!D9+'ESCOLA MUNICIPAL MAJOR JÚLIO FR'!D9+'E M ALMIRANTE TAMANDARÉ'!D9+'ESCOLA PAROQUIAL CARLOS DEMIÁ'!D9+'CENTRO PAROQUIAL DE EDUCAÇÃO IN'!D9+'CEI IRMÃ SILVANA'!D9+'CEI OLÍVIA MACHADO DA COSTA NOG'!D9+'E M GOVERNADOR MARCELLO ALENCAR'!D9+'E M PROFESSOR FLÁVIO MACIEL'!D9+'E M PROFª JANDIRA PEIXOTO BORDI'!D9+'E M STEFAN ZWEIG'!D9+'ESCOLA PAROQUIAL BOM JESUS'!D9+'CEI MARLI SOARES FERREIRA NETTO'!D9+'CENTRO DE EDUCAÇÃO INFANTIL CHI'!D9+'CEI VILA IPANEMA'!D9+'E M ROBERT KENNEDY'!D9+'ESCOLA MUNICIPAL ANA MOHAMMAD'!D9+'ESCOLA SÃO CRISTÓVÃO'!D9+'CEI DÉA LÚCIA CORDEIRO'!D9+'CEI SAGRADA FAMÍLIA'!D9+'CEI SÃO JOSÉ DAS OBLATAS DE NAZ'!D9+'ESCOLA MUNICIPAL JORGE AMADO'!D9+'E M FÁBRICA DO SABER'!D9+'CIEP BRIZOLÃO 474 MAESTRO GUERR'!D9+'CENTRO DE ENSINO PROF DARCY RIB'!D9+'CEI ANDRÉ VANZAN'!D9+'CENTRO DE EDUCAÇÃO INFANTIL CAR'!D9+'CEI BOA VISTA'!D9+'ASSOCIAÇÃO DA CRECHE SÃO FRANCI'!D9+'ESCOLA MUNICIPAL PAULO SALDANHA'!D9+'ESCOLA MUNICIPAL LÚCIA DE ALMEI'!D9+'E M DOM MANOEL PEDRO DA CUNHA C'!D9+'ESCOLA SÃO GERALDO'!D9+'CEI LULU MONTEIRO DE CASTRO'!D9+'CEI CARANGOLA'!D9+'ASSOCIAÇÃO RECREAR'!D9+'CENTRO DE EDUCAÇÃO INFANTIL CAS'!D9+'E M ROSEMIRA DE OLIVEIRA CAVALC'!D9+'E MZDA CARMEM NUNES MARTINS'!D9+'CEI SÃO JOSÉ DO ITAMARATI'!D9+'E M DUQUE DE CAXIAS'!D9+'CENTRO DE EDUCAÇÃO INFANTIL 2'!D9+'E M ANTÔNIO LEITE GARCIA'!D9+'ESCOLA PAROQUIAL DA ALCOBAÇA'!D9+'CENTRO DE EDUCAÇÃO INFANTIL LOT'!D9+'ESCOLA PAROQUIAL DO LOTEAMENTO '!D9+'E M PROF JOAQUIM DEISTER'!D9+'E M MARIETA GONÇALVES'!D9+'ESCOLA MUNICIPAL ODETTE YOUNG M'!D9+'ESCOLA MUNICIPAL PROFESSOR JOSE'!D9+'E M HERCÍLIA HENRIQUES MORET'!D9+'COLEGIO VICENTINO PADRE CORRÊA'!D9+'CEI PROFª MARLUCE DE SOUZA PEST'!D9+'CEI IRINEU MARINHO'!D9+'CEI DAGMAR ROLANDO DE OLIVEIRA'!D9+'CEI NOSSA SENHORA DA GLÓRIA'!D9+'E M PROF NILTON COSTA PEREIRA D'!D9+'CENTRO DE EDUCAÇÃO INFANTIL SÉR'!D9+'CEI SANTO ANTÔNIO AGOSTINHO'!D9+'CEI OSWALDO CRUZ'!D9+'E M MAGDALENA TAGLIAFERRO'!D9+'ESCOLA SÃO JOSÉ DO CAETITU'!D9+'CRECHE-ESCOLA CASTELO SÃO MANOE'!D9+'CEI THEREZINHA DE JESUS LIMA'!D9+'ESCOLA MUNICIPAL PROFESSOR PAUL'!D9+'COLÉGIO ANGLICANO DE ARARAS'!D9+'ESCOLA PAROQUIAL SANTA BERNADET'!D9+'CEI VISTA ALEGRE'!D9+'CEI DENISE BESSA DE OLIVA MAYA'!D9+'CEI VIDEIRINHA'!D9+'E M AMÉRICO FERNANDES RIBEIRO'!D9+'ESCOLA MUNICIPAL AUGUSTO PUGNAL'!D9+'ESCOLA MUNICIPAL CELINA SCHECHN'!D9+'E M DARCY CORREA DA VEIGA'!D9+'E M DR PAULA BUARQUE'!D9+'LICEU SÃO JOSÉ DE ITAIPAVA'!D9+'CEI LUIZ MARCHIORI'!D9+'CENTRO DE EDUCAÇÃO INFANTIL AUG'!D9+'CEI PROFª ADRIANA CONSTÂNCIO TR'!D9+'E M AMÉLIA ANTUNES RABELLO'!D9+'CEI PREFEITO SÉRGIO FADEL'!D9+'E M DR THEODORO MACHADO'!D9+'ESCOLA SANTO ANTÔNIO'!D9+'E M TAQUARIL'!D9+'E M MONSENHOR JOÃO DE DEUS RODR'!D9+'CENTRO DE REFERÊNCIA EM EDUC 2'!D9+'CEI PROFª GRAÇA COSTA'!D9+'CEI VILA LEOPOLDINA'!D9+'CEI NILO PEÇANHA'!D9+'E MZDA SANTA TEREZINHA'!D9+'CEI CRIANÇA SANTA EDWIGES'!D9+'E M ARNALDO DYCKERHOFF'!D9+'E M CARLOS CANEDO'!D9+'E M BEATRIZ ZALESKI'!D9+'E M ANTÔNIO JOSÉ DE LIMA'!D9+'E M FELIX WAN ERVEN DE BARROS'!D9+'ESCOLA MUNICIPAL HILDEBRANDO DE'!D9+'E M OSWALDO DA COSTA FRIAS'!D9+'E MZDA AVELINO DE CARVALHO'!D9+'ESCOLA MUNICIPALIZADA MOYSÉS FU'!D9+'CEI ANGELA MARIA DA CONCEIÇÃO S'!D9+'CEI JOSÉ GONÇALVES DA MOTTA'!D9+'E M DR BARROS FRANCO'!D9+'E M MAJOR THEÓFILO DE CARVALHO'!D9+'E M JOÃO KOPKE'!D9+'CEI ASSOCIAÇÃO BENEFICENTE FAZE'!D9+'ESCOLA SAO FRANCISCO DE ASSIS'!D9+'CEI SÃO FRANCISCO ASSIS'!D9+'CEI ALDEIA DA CRIANCA'!D9+'ESCOLA MUNICIPAL ODETTE FONSECA'!D9+'CEI ANA CAROLINA TELLES'!D9+'E M SEBASTIÃO LACERDA'!D9+'E M DOM PEDRO DE ALCÂNTARA'!D9+'ESCOLA NOSSA SENHORA DE FÁTIMA'!D9+'ESCOLA PAROQUIAL SÃO FRANCISCO '!D9+'E M MONSENHOR CIRILLO CALAON'!D9 | D5: ='E M ABELARDO DE LAMARE'!M9+'E M BATAILLARD'!M9+'E M LEONARDO BOFF'!M9+'E M CLEMENTE FERNANDES'!M9+'E M DOM PEDRO DE ALCÂNTARA'!M9+'E M DUQUE DE CAXIAS'!M9+'E M LUIZ CARLOS SOARES'!M9+'ESCOLA MUNICIPAL GENERAL HEITOR'!M9+'E M JOÃO KOPKE'!M9+'ESCOLA MUNICIPAL ODETTE FONSECA'!M9+'E M GOVERNADOR MARCELLO ALENCAR'!M9+'E M PROF JOAQUIM DEISTER'!M9+'E M ROBERT KENNEDY'!M9+'E M ROTARY'!M9+'E M ROSALINA NICOLAY'!M9+'E M DE EDUCAÇÃO ESPECIAL SANTOS'!M9+'E M SOROPTIMISTA'!M9+'LICEU MUN PREFEITO CORDOLINO AM'!M9+'E M ANTÔNIO LEITE GARCIA'!M9+'ESCOLA MUNICIPAL JORGE AMADO'!M9+'ESCOLA MUNICIPAL LÚCIA DE ALMEI'!M9+'E M MAGDALENA TAGLIAFERRO'!M9+'ESCOLA MUNICIPAL MAJOR JÚLIO FR'!M9+'E M MARIETA GONÇALVES'!M9+'ESCOLA MUNICIPAL ODETTE YOUNG M'!M9+'E M FÁBRICA DO SABER'!M9+'ESCOLA MUNICIPAL PROFESSOR PAUL'!M9+'E M ROSEMIRA DE OLIVEIRA CAVALC'!M9+'E M AMÉLIA ANTUNES RABELLO'!M9+'ESCOLA MUNICIPAL AUGUSTO PUGNAL'!M9+'ESCOLA MUNICIPAL CELINA SCHECHN'!M9+'E M DARCY CORREA DA VEIGA'!M9+'E M DR PAULA BUARQUE'!M9+'E M DR THEODORO MACHADO'!M9+'E M ARNALDO DYCKERHOFF'!M9+'E M CARLOS CANEDO'!M9+'E M DR BARROS FRANCO'!M9+'E M MAJOR THEÓFILO DE CARVALHO'!M9+'E M TAQUARIL'!M9+'E M BEATRIZ ZALESKI'!M9+'E M ANTÔNIO JOSÉ DE LIMA'!M9+'E M FELIX WAN ERVEN DE BARROS'!M9+'ESCOLA MUNICIPAL HILDEBRANDO DE'!M9+'E M OSWALDO DA COSTA FRIAS'!M9+'E MZDA CARMEM NUNES MARTINS'!M9+'E MZDA AVELINO DE CARVALHO'!M9+'E M GERALDO VENTURA DIAS'!M9+'E M SALVADOR KLING'!M9+'E M PREFEITO JAMIL SABRÁ'!M9+'LICEU MUNICIPAL CARLOS CHAGAS F'!M9+'ESCOLA MUNICIPAL ANA MOHAMMAD'!M9+'ESCOLA MUNICIPAL ALTO INDEPENDÊ'!M9+'E M ALMIRANTE TAMANDARÉ'!M9+'ESCOLA MUNICIPALIZADA FREI ANIC'!M9+'E M PEDRO AMADO'!M9+'E M PROFª MARIA DA GLÓRIA QUEIR'!M9+'E M SEBASTIÃO LACERDA'!M9+'E M PROFESSOR FLÁVIO MACIEL'!M9+'ESCOLA MUNICIPAL PAULO SALDANHA'!M9+'ESCOLA MUNICIPAL PROFESSOR JOSE'!M9+'E M MONSENHOR CIRILLO CALAON'!M9+'E M AMÉRICO FERNANDES RIBEIRO'!M9+'E M PROFª JANDIRA PEIXOTO BORDI'!M9+'E M MONSENHOR JOÃO DE DEUS RODR'!M9+'E M DOM MANOEL PEDRO DA CUNHA C'!M9+'E M JOHANN NOEL'!M9+'E MZDA SANTA TEREZINHA'!M9+'E M PAPA JOÃO PAULO II'!M9+'E M STEFAN ZWEIG'!M9+'ESCOLA MUNICIPAL SENADOR MARIO '!M9+'E M DR RUBENS DE CASTRO BOMTEMP'!M9+'E M PAULO FREIRE'!M9+'E M PROFª MARIA CAMPOS DA SILVA'!M9+'E M HERCÍLIA HENRIQUES MORET'!M9+'ESCOLA MUNICIPALIZADA MOYSÉS FU'!M9+'CIEP BRIZOLÃO 474 MAESTRO GUERR'!M9+'CENTRO DE ENSINO PROF DARCY RIB'!M9+'CASA DA EDUCAÇÃO VISCONDE DE MA'!M9+'CENTRO DE REFERÊNCIA EM EDUCAÇÃ'!M9+'E M PROF NILTON COSTA PEREIRA D'!M9+'COLÉGIO GUNNAR VINGREN DE PETRÓ'!M9+'CENTRO DE REFERÊNCIA EM EDUC 2'!M9+'ESCOLA SANTA LUIZA DE MARILLAC'!M9+'CENTRO EDUCACIONAL COMUNIDADE S'!M9+'EDUCANDÁRIO TERRA SANTA'!M9+'ESCOLA GERMANO VALENTE'!M9+'ESCOLA DAS COMUNIDADES SANTO AN'!M9+'ESCOLA DOMÉSTICA NOSSA SENHORA '!M9+'ESCOLA PAROQUIAL NOSSA SENHO 3'!M9+'ESCOLA MONSENHOR GENTIL'!M9+'ESCOLA PAROQUIAL BOM JESUS'!M9+'ESCOLA PAROQUIAL CARLOS DEMIÁ'!M9+'ESCOLA PAROQUIAL NOSSA SENHO 2'!M9+'ESCOLA PAROQUIAL NOSSA SENHORA '!M9+'ESCOLA PAROQUIAL SÃO PEDRO DE A'!M9+'ESCOLA SANTA MARIA GORETTI'!M9+'ESCOLA SANTA RITA DE CASSIA'!M9+'ESCOLA SÃO CRISTÓVÃO'!M9+'ESCOLA PAROQUIAL SÃO FRANCISCO '!M9+'ESCOLA SAO FRANCISCO DE ASSIS'!M9+'ESCOLA SÃO JOÃO BATISTA'!M9+'ESCOLA SÃO JUDAS TADEU'!M9+'ESCOLA PAROQUIAL SÃO PIO X'!M9+'COLÉGIO ANGLICANO DE ARARAS'!M9+'COLEGIO VICENTINO PADRE CORRÊA'!M9+'ESCOLA NOSSA SENHORA DE FÁTIMA'!M9+'ESCOLA PAROQUIAL DA ALCOBAÇA'!M9+'ESCOLA PAROQUIAL DO LOTEAMENTO '!M9+'ESCOLA PAROQUIAL SANTA BERNADET'!M9+'ESCOLA SÃO GERALDO'!M9+'ESCOLA SANTO ANTÔNIO'!M9+'LICEU SÃO JOSÉ DE ITAIPAVA'!M9+'ESCOLA SÃO JOSÉ DO CAETITU'!M9+'CEI ASSOCIAÇÃO BENEFICENTE FAZE'!M9+'CEI CASA DA SOLIDARIEDADE DE NO'!M9+'CEI LULU MONTEIRO DE CASTRO'!M9+'CEI SÃO JOÃO BATISTA'!M9+'CEI SÃO FRANCISCO ASSIS'!M9+'CEI A SEMENTEIRA'!M9+'CEI FREI LEÃO'!M9+'CEI ROMANO CANAVESE'!M9+'CEI ANDRÉ VANZAN'!M9+'CEI CRIANÇA SANTA EDWIGES'!M9+'CENTRO DE EDUCAÇÃO INFANTIL IRM'!M9+'CEI PEDRAS BRANCAS'!M9+'CEI INÊS BELARMINO DE SOUZA'!M9+'CEI PROFª ROSANGELA DA SILVA LE'!M9+'CEI VILA SAO JOSE'!M9+'CEI MARIA THEREZA KLING DO VALL'!M9+'CEI DEISE ELOY GOMES'!M9+'CENTRO PAROQUIAL DE EDUCAÇÃO IN'!M9+'CEI VISTA ALEGRE'!M9+'CEI ALDEIA DA CRIANCA'!M9+'CEI DÉA LÚCIA CORDEIRO'!M9+'CENTRO DE EDUCAÇÃO INFANTIL CAR'!M9+'CEI IRMÃ SILVANA'!M9+'CEI MARLI SOARES FERREIRA NETTO'!M9+'CEI PROFª SONIA REGINA SCUDESE '!M9+'CEI DONA ESPERANZA DE BOURBON D'!M9+'CEI PREFEITO SÉRGIO FADEL'!M9+'CEI ANDRÉ REBOUÇAS'!M9+'CENTRO DE EDUCAÇÃO INFANTIL CHI'!M9+'CEI TIA ALICE'!M9+'CEI TERRA SANTA'!M9+'CEI JORGE ROLANDO DA SILVA'!M9+'CEI CARANGOLA'!M9+'CEI CÉLIA LÔBO PAULO'!M9+'CEI LIONS CLUBE DE PETRÓPOLIS'!M9+'CEI PROFª GRAÇA COSTA'!M9+'CEI ANGELA MARIA DA CONCEIÇÃO S'!M9+'CEI LUIZ MARCHIORI'!M9+'CEI PROFª MARLUCE DE SOUZA PEST'!M9+'CEI OLÍVIA MACHADO DA COSTA NOG'!M9+'CEI VILA IPANEMA'!M9+'CEI VILA LEOPOLDINA'!M9+'CENTRO DE EDUCAÇÃO INFANTIL CAS'!M9+'CEI PRIMEIRA INFÂNCIA'!M9+'CEI PROFª DORA KILLER'!M9+'CEI PROFª PATRÍCIA FERREIRA E S'!M9+'CEI DRA ZILDA ARNS NEUMANN'!M9+'CEI DENISE BESSA DE OLIVA MAYA'!M9+'CEI GIUSEPPE-NEVA VOLONTERIO'!M9+'CENTRO DE EDUCAÇÃO INFANTIL LOT'!M9+'CEI IRINEU MARINHO'!M9+'CEI OSWALDO CRUZ'!M9+'CEI ANA CAROLINA TELLES'!M9+'CEI JOSÉ GONÇALVES DA MOTTA'!M9+'CEI SAGRADA FAMÍLIA'!M9+'CEI PROFª HERMÍNIA MATHEUS'!M9+'CENTRO DE EDUCAÇÃO INFANTIL PRO'!M9+'CEI MONSENHOR PAULO ELIAS DAHER'!M9+'CEI DAGMAR ROLANDO DE OLIVEIRA'!M9+'CENTRO DE EDUCAÇÃO INFANTIL 2'!M9+'CEI BOA VISTA'!M9+'CEI NILO PEÇANHA'!M9+'CENTRO DE EDUCAÇÃO INFANTIL AUG'!M9+'CEI THEREZINHA DE JESUS LIMA'!M9+'CEI VIDEIRINHA'!M9+'CEI PROFª ADRIANA CONSTÂNCIO TR'!M9+'CENTRO DE EDUCAÇÃO INFANTIL SÉR'!M9+'CEI JURACI PINTO DO AMARAL DE C'!M9+'CEI NOSSA SENHORA DA GLÓRIA'!M9+'CEI ALTO INDEPENDÊNCIA'!M9+'CEI SÃO JOSÉ DAS OBLATAS DE NAZ'!M9+'CEI SANTO ANTÔNIO AGOSTINHO'!M9+'CEI SÃO CHARBEL'!M9+'ASSOCIAÇÃO DA CRECHE SÃO FRANCI'!M9+'CEI SÃO JOSÉ DO ITAMARATI'!M9+'ASSOCIAÇÃO RECREAR'!M9+'CRECHE-ESCOLA CASTELO SÃO MANOE'!M9+'CENTRO DE EDUCAÇÃO INFANTIL SÃO'!M9 | E5: ='Entrada de Dados'!C2 | F5: =D5*E5
A6: ='Entrada de Dados'!D5 | B6: ='Entrada de Dados'!D197 | C6: ='E M ROTARY'!D10+'E M DE EDUCAÇÃO ESPECIAL SANTOS'!D10+'LICEU MUN PREFEITO CORDOLINO AM'!D10+'E M PREFEITO JAMIL SABRÁ'!D10+'LICEU MUNICIPAL CARLOS CHAGAS F'!D10+'E M PAULO FREIRE'!D10+'E M PROFª MARIA CAMPOS DA SILVA'!D10+'CASA DA EDUCAÇÃO VISCONDE DE MA'!D10+'CENTRO DE REFERÊNCIA EM EDUCAÇÃ'!D10+'ESCOLA SANTA LUIZA DE MARILLAC'!D10+'ESCOLA DOMÉSTICA NOSSA SENHORA '!D10+'ESCOLA MONSENHOR GENTIL'!D10+'ESCOLA PAROQUIAL NOSSA SENHORA '!D10+'ESCOLA PAROQUIAL SÃO PEDRO DE A'!D10+'CEI TERRA SANTA'!D10+'CEI PRIMEIRA INFÂNCIA'!D10+'CEI PROFª PATRÍCIA FERREIRA E S'!D10+'CEI DRA ZILDA ARNS NEUMANN'!D10+'CENTRO DE EDUCAÇÃO INFANTIL PRO'!D10+'CEI MONSENHOR PAULO ELIAS DAHER'!D10+'COLÉGIO GUNNAR VINGREN DE PETRÓ'!D10+'EDUCANDÁRIO TERRA SANTA'!D10+'CEI LIONS CLUBE DE PETRÓPOLIS'!D10+'ESCOLA PAROQUIAL NOSSA SENHO 2'!D10+'CENTRO DE EDUCAÇÃO INFANTIL IRM'!D10+'E M LUIZ CARLOS SOARES'!D10+'ESCOLA GERMANO VALENTE'!D10+'ESCOLA PAROQUIAL NOSSA SENHO 3'!D10+'CEI JORGE ROLANDO DA SILVA'!D10+'E M CLEMENTE FERNANDES'!D10+'E M GERALDO VENTURA DIAS'!D10+'ESCOLA DAS COMUNIDADES SANTO AN'!D10+'CEI PROFª ROSANGELA DA SILVA LE'!D10+'CEI DEISE ELOY GOMES'!D10+'CEI PROFª SONIA REGINA SCUDESE '!D10+'CEI TIA ALICE'!D10+'E M BATAILLARD'!D10+'E M SOROPTIMISTA'!D10+'E M SALVADOR KLING'!D10+'ESCOLA MUNICIPALIZADA FREI ANIC'!D10+'ESCOLA SÃO JUDAS TADEU'!D10+'CEI PEDRAS BRANCAS'!D10+'CEI MARIA THEREZA KLING DO VALL'!D10+'CEI DONA ESPERANZA DE BOURBON D'!D10+'CEI GIUSEPPE-NEVA VOLONTERIO'!D10+'CENTRO DE EDUCAÇÃO INFANTIL SÃO'!D10+'E M LEONARDO BOFF'!D10+'ESCOLA MUNICIPAL GENERAL HEITOR'!D10+'E M JOHANN NOEL'!D10+'ESCOLA SANTA MARIA GORETTI'!D10+'ESCOLA SANTA RITA DE CASSIA'!D10+'ESCOLA SÃO JOÃO BATISTA'!D10+'CEI CASA DA SOLIDARIEDADE DE NO'!D10+'CEI A SEMENTEIRA'!D10+'CEI VILA SAO JOSE'!D10+'E M DR RUBENS DE CASTRO BOMTEMP'!D10+'CEI FREI LEÃO'!D10+'CEI SÃO JOÃO BATISTA'!D10+'CEI JURACI PINTO DO AMARAL DE C'!D10+'E M PEDRO AMADO'!D10+'E M ABELARDO DE LAMARE'!D10+'ESCOLA MUNICIPAL SENADOR MARIO '!D10+'ESCOLA PAROQUIAL SÃO PIO X'!D10+'CEI SÃO CHARBEL'!D10+'E M ROSALINA NICOLAY'!D10+'CEI INÊS BELARMINO DE SOUZA'!D10+'E M PROFª MARIA DA GLÓRIA QUEIR'!D10+'CENTRO EDUCACIONAL COMUNIDADE S'!D10+'CEI ROMANO CANAVESE'!D10+'CEI CÉLIA LÔBO PAULO'!D10+'CEI PROFª DORA KILLER'!D10+'CEI ALTO INDEPENDÊNCIA'!D10+'ESCOLA MUNICIPAL ALTO INDEPENDÊ'!D10+'E M PAPA JOÃO PAULO II'!D10+'CEI ANDRÉ REBOUÇAS'!D10+'CEI PROFª HERMÍNIA MATHEUS'!D10+'ESCOLA MUNICIPAL MAJOR JÚLIO FR'!D10+'E M ALMIRANTE TAMANDARÉ'!D10+'ESCOLA PAROQUIAL CARLOS DEMIÁ'!D10+'CENTRO PAROQUIAL DE EDUCAÇÃO IN'!D10+'CEI IRMÃ SILVANA'!D10+'CEI OLÍVIA MACHADO DA COSTA NOG'!D10+'E M GOVERNADOR MARCELLO ALENCAR'!D10+'E M PROFESSOR FLÁVIO MACIEL'!D10+'E M PROFª JANDIRA PEIXOTO BORDI'!D10+'E M STEFAN ZWEIG'!D10+'ESCOLA PAROQUIAL BOM JESUS'!D10+'CEI MARLI SOARES FERREIRA NETTO'!D10+'CENTRO DE EDUCAÇÃO INFANTIL CHI'!D10+'CEI VILA IPANEMA'!D10+'E M ROBERT KENNEDY'!D10+'ESCOLA MUNICIPAL ANA MOHAMMAD'!D10+'ESCOLA SÃO CRISTÓVÃO'!D10+'CEI DÉA LÚCIA CORDEIRO'!D10+'CEI SAGRADA FAMÍLIA'!D10+'CEI SÃO JOSÉ DAS OBLATAS DE NAZ'!D10+'ESCOLA MUNICIPAL JORGE AMADO'!D10+'E M FÁBRICA DO SABER'!D10+'CIEP BRIZOLÃO 474 MAESTRO GUERR'!D10+'CENTRO DE ENSINO PROF DARCY RIB'!D10+'CEI ANDRÉ VANZAN'!D10+'CENTRO DE EDUCAÇÃO INFANTIL CAR'!D10+'CEI BOA VISTA'!D10+'ASSOCIAÇÃO DA CRECHE SÃO FRANCI'!D10+'ESCOLA MUNICIPAL PAULO SALDANHA'!D10+'ESCOLA MUNICIPAL LÚCIA DE ALMEI'!D10+'E M DOM MANOEL PEDRO DA CUNHA C'!D10+'ESCOLA SÃO GERALDO'!D10+'CEI LULU MONTEIRO DE CASTRO'!D10+'CEI CARANGOLA'!D10+'ASSOCIAÇÃO RECREAR'!D10+'CENTRO DE EDUCAÇÃO INFANTIL CAS'!D10+'E M ROSEMIRA DE OLIVEIRA CAVALC'!D10+'E MZDA CARMEM NUNES MARTINS'!D10+'CEI SÃO JOSÉ DO ITAMARATI'!D10+'E M DUQUE DE CAXIAS'!D10+'CENTRO DE EDUCAÇÃO INFANTIL 2'!D10+'E M ANTÔNIO LEITE GARCIA'!D10+'ESCOLA PAROQUIAL DA ALCOBAÇA'!D10+'CENTRO DE EDUCAÇÃO INFANTIL LOT'!D10+'ESCOLA PAROQUIAL DO LOTEAMENTO '!D10+'E M PROF JOAQUIM DEISTER'!D10+'E M MARIETA GONÇALVES'!D10+'ESCOLA MUNICIPAL ODETTE YOUNG M'!D10+'ESCOLA MUNICIPAL PROFESSOR JOSE'!D10+'E M HERCÍLIA HENRIQUES MORET'!D10+'COLEGIO VICENTINO PADRE CORRÊA'!D10+'CEI PROFª MARLUCE DE SOUZA PEST'!D10+'CEI IRINEU MARINHO'!D10+'CEI DAGMAR ROLANDO DE OLIVEIRA'!D10+'CEI NOSSA SENHORA DA GLÓRIA'!D10+'E M PROF NILTON COSTA PEREIRA D'!D10+'CENTRO DE EDUCAÇÃO INFANTIL SÉR'!D10+'CEI SANTO ANTÔNIO AGOSTINHO'!D10+'CEI OSWALDO CRUZ'!D10+'E M MAGDALENA TAGLIAFERRO'!D10+'ESCOLA SÃO JOSÉ DO CAETITU'!D10+'CRECHE-ESCOLA CASTELO SÃO MANOE'!D10+'CEI THEREZINHA DE JESUS LIMA'!D10+'ESCOLA MUNICIPAL PROFESSOR PAUL'!D10+'COLÉGIO ANGLICANO DE ARARAS'!D10+'ESCOLA PAROQUIAL SANTA BERNADET'!D10+'CEI VISTA ALEGRE'!D10+'CEI DENISE BESSA DE OLIVA MAYA'!D10+'CEI VIDEIRINHA'!D10+'E M AMÉRICO FERNANDES RIBEIRO'!D10+'ESCOLA MUNICIPAL AUGUSTO PUGNAL'!D10+'ESCOLA MUNICIPAL CELINA SCHECHN'!D10+'E M DARCY CORREA DA VEIGA'!D10+'E M DR PAULA BUARQUE'!D10+'LICEU SÃO JOSÉ DE ITAIPAVA'!D10+'CEI LUIZ MARCHIORI'!D10+'CENTRO DE EDUCAÇÃO INFANTIL AUG'!D10+'CEI PROFª ADRIANA CONSTÂNCIO TR'!D10+'E M AMÉLIA ANTUNES RABELLO'!D10+'CEI PREFEITO SÉRGIO FADEL'!D10+'E M DR THEODORO MACHADO'!D10+'ESCOLA SANTO ANTÔNIO'!D10+'E M TAQUARIL'!D10+'E M MONSENHOR JOÃO DE DEUS RODR'!D10+'CENTRO DE REFERÊNCIA EM EDUC 2'!D10+'CEI PROFª GRAÇA COSTA'!D10+'CEI VILA LEOPOLDINA'!D10+'CEI NILO PEÇANHA'!D10+'E MZDA SANTA TEREZINHA'!D10+'CEI CRIANÇA SANTA EDWIGES'!D10+'E M ARNALDO DYCKERHOFF'!D10+'E M CARLOS CANEDO'!D10+'E M BEATRIZ ZALESKI'!D10+'E M ANTÔNIO JOSÉ DE LIMA'!D10+'E M FELIX WAN ERVEN DE BARROS'!D10+'ESCOLA MUNICIPAL HILDEBRANDO DE'!D10+'E M OSWALDO DA COSTA FRIAS'!D10+'E MZDA AVELINO DE CARVALHO'!D10+'ESCOLA MUNICIPALIZADA MOYSÉS FU'!D10+'CEI ANGELA MARIA DA CONCEIÇÃO S'!D10+'CEI JOSÉ GONÇALVES DA MOTTA'!D10+'E M DR BARROS FRANCO'!D10+'E M MAJOR THEÓFILO DE CARVALHO'!D10+'E M JOÃO KOPKE'!D10+'CEI ASSOCIAÇÃO BENEFICENTE FAZE'!D10+'ESCOLA SAO FRANCISCO DE ASSIS'!D10+'CEI SÃO FRANCISCO ASSIS'!D10+'CEI ALDEIA DA CRIANCA'!D10+'ESCOLA MUNICIPAL ODETTE FONSECA'!D10+'CEI ANA CAROLINA TELLES'!D10+'E M SEBASTIÃO LACERDA'!D10+'E M DOM PEDRO DE ALCÂNTARA'!D10+'ESCOLA NOSSA SENHORA DE FÁTIMA'!D10+'ESCOLA PAROQUIAL SÃO FRANCISCO '!D10+'E M MONSENHOR CIRILLO CALAON'!D10 | D6: ='E M ABELARDO DE LAMARE'!M10+'E M BATAILLARD'!M10+'E M LEONARDO BOFF'!M10+'E M CLEMENTE FERNANDES'!M10+'E M DOM PEDRO DE ALCÂNTARA'!M10+'E M DUQUE DE CAXIAS'!M10+'E M LUIZ CARLOS SOARES'!M10+'ESCOLA MUNICIPAL GENERAL HEITOR'!M10+'E M JOÃO KOPKE'!M10+'ESCOLA MUNICIPAL ODETTE FONSECA'!M10+'E M GOVERNADOR MARCELLO ALENCAR'!M10+'E M PROF JOAQUIM DEISTER'!M10+'E M ROBERT KENNEDY'!M10+'E M ROTARY'!M10+'E M ROSALINA NICOLAY'!M10+'E M DE EDUCAÇÃO ESPECIAL SANTOS'!M10+'E M SOROPTIMISTA'!M10+'LICEU MUN PREFEITO CORDOLINO AM'!M10+'E M ANTÔNIO LEITE GARCIA'!M10+'ESCOLA MUNICIPAL JORGE AMADO'!M10+'ESCOLA MUNICIPAL LÚCIA DE ALMEI'!M10+'E M MAGDALENA TAGLIAFERRO'!M10+'ESCOLA MUNICIPAL MAJOR JÚLIO FR'!M10+'E M MARIETA GONÇALVES'!M10+'ESCOLA MUNICIPAL ODETTE YOUNG M'!M10+'E M FÁBRICA DO SABER'!M10+'ESCOLA MUNICIPAL PROFESSOR PAUL'!M10+'E M ROSEMIRA DE OLIVEIRA CAVALC'!M10+'E M AMÉLIA ANTUNES RABELLO'!M10+'ESCOLA MUNICIPAL AUGUSTO PUGNAL'!M10+'ESCOLA MUNICIPAL CELINA SCHECHN'!M10+'E M DARCY CORREA DA VEIGA'!M10+'E M DR PAULA BUARQUE'!M10+'E M DR THEODORO MACHADO'!M10+'E M ARNALDO DYCKERHOFF'!M10+'E M CARLOS CANEDO'!M10+'E M DR BARROS FRANCO'!M10+'E M MAJOR THEÓFILO DE CARVALHO'!M10+'E M TAQUARIL'!M10+'E M BEATRIZ ZALESKI'!M10+'E M ANTÔNIO JOSÉ DE LIMA'!M10+'E M FELIX WAN ERVEN DE BARROS'!M10+'ESCOLA MUNICIPAL HILDEBRANDO DE'!M10+'E M OSWALDO DA COSTA FRIAS'!M10+'E MZDA CARMEM NUNES MARTINS'!M10+'E MZDA AVELINO DE CARVALHO'!M10+'E M GERALDO VENTURA DIAS'!M10+'E M SALVADOR KLING'!M10+'E M PREFEITO JAMIL SABRÁ'!M10+'LICEU MUNICIPAL CARLOS CHAGAS F'!M10+'ESCOLA MUNICIPAL ANA MOHAMMAD'!M10+'ESCOLA MUNICIPAL ALTO INDEPENDÊ'!M10+'E M ALMIRANTE TAMANDARÉ'!M10+'ESCOLA MUNICIPALIZADA FREI ANIC'!M10+'E M PEDRO AMADO'!M10+'E M PROFª MARIA DA GLÓRIA QUEIR'!M10+'E M SEBASTIÃO LACERDA'!M10+'E M PROFESSOR FLÁVIO MACIEL'!M10+'ESCOLA MUNICIPAL PAULO SALDANHA'!M10+'ESCOLA MUNICIPAL PROFESSOR JOSE'!M10+'E M MONSENHOR CIRILLO CALAON'!M10+'E M AMÉRICO FERNANDES RIBEIRO'!M10+'E M PROFª JANDIRA PEIXOTO BORDI'!M10+'E M MONSENHOR JOÃO DE DEUS RODR'!M10+'E M DOM MANOEL PEDRO DA CUNHA C'!M10+'E M JOHANN NOEL'!M10+'E MZDA SANTA TEREZINHA'!M10+'E M PAPA JOÃO PAULO II'!M10+'E M STEFAN ZWEIG'!M10+'ESCOLA MUNICIPAL SENADOR MARIO '!M10+'E M DR RUBENS DE CASTRO BOMTEMP'!M10+'E M PAULO FREIRE'!M10+'E M PROFª MARIA CAMPOS DA SILVA'!M10+'E M HERCÍLIA HENRIQUES MORET'!M10+'ESCOLA MUNICIPALIZADA MOYSÉS FU'!M10+'CIEP BRIZOLÃO 474 MAESTRO GUERR'!M10+'CENTRO DE ENSINO PROF DARCY RIB'!M10+'CASA DA EDUCAÇÃO VISCONDE DE MA'!M10+'CENTRO DE REFERÊNCIA EM EDUCAÇÃ'!M10+'E M PROF NILTON COSTA PEREIRA D'!M10+'COLÉGIO GUNNAR VINGREN DE PETRÓ'!M10+'CENTRO DE REFERÊNCIA EM EDUC 2'!M10+'ESCOLA SANTA LUIZA DE MARILLAC'!M10+'CENTRO EDUCACIONAL COMUNIDADE S'!M10+'EDUCANDÁRIO TERRA SANTA'!M10+'ESCOLA GERMANO VALENTE'!M10+'ESCOLA DAS COMUNIDADES SANTO AN'!M10+'ESCOLA DOMÉSTICA NOSSA SENHORA '!M10+'ESCOLA PAROQUIAL NOSSA SENHO 3'!M10+'ESCOLA MONSENHOR GENTIL'!M10+'ESCOLA PAROQUIAL BOM JESUS'!M10+'ESCOLA PAROQUIAL CARLOS DEMIÁ'!M10+'ESCOLA PAROQUIAL NOSSA SENHO 2'!M10+'ESCOLA PAROQUIAL NOSSA SENHORA '!M10+'ESCOLA PAROQUIAL SÃO PEDRO DE A'!M10+'ESCOLA SANTA MARIA GORETTI'!M10+'ESCOLA SANTA RITA DE CASSIA'!M10+'ESCOLA SÃO CRISTÓVÃO'!M10+'ESCOLA PAROQUIAL SÃO FRANCISCO '!M10+'ESCOLA SAO FRANCISCO DE ASSIS'!M10+'ESCOLA SÃO JOÃO BATISTA'!M10+'ESCOLA SÃO JUDAS TADEU'!M10+'ESCOLA PAROQUIAL SÃO PIO X'!M10+'COLÉGIO ANGLICANO DE ARARAS'!M10+'COLEGIO VICENTINO PADRE CORRÊA'!M10+'ESCOLA NOSSA SENHORA DE FÁTIMA'!M10+'ESCOLA PAROQUIAL DA ALCOBAÇA'!M10+'ESCOLA PAROQUIAL DO LOTEAMENTO '!M10+'ESCOLA PAROQUIAL SANTA BERNADET'!M10+'ESCOLA SÃO GERALDO'!M10+'ESCOLA SANTO ANTÔNIO'!M10+'LICEU SÃO JOSÉ DE ITAIPAVA'!M10+'ESCOLA SÃO JOSÉ DO CAETITU'!M10+'CEI ASSOCIAÇÃO BENEFICENTE FAZE'!M10+'CEI CASA DA SOLIDARIEDADE DE NO'!M10+'CEI LULU MONTEIRO DE CASTRO'!M10+'CEI SÃO JOÃO BATISTA'!M10+'CEI SÃO FRANCISCO ASSIS'!M10+'CEI A SEMENTEIRA'!M10+'CEI FREI LEÃO'!M10+'CEI ROMANO CANAVESE'!M10+'CEI ANDRÉ VANZAN'!M10+'CEI CRIANÇA SANTA EDWIGES'!M10+'CENTRO DE EDUCAÇÃO INFANTIL IRM'!M10+'CEI PEDRAS BRANCAS'!M10+'CEI INÊS BELARMINO DE SOUZA'!M10+'CEI PROFª ROSANGELA DA SILVA LE'!M10+'CEI VILA SAO JOSE'!M10+'CEI MARIA THEREZA KLING DO VALL'!M10+'CEI DEISE ELOY GOMES'!M10+'CENTRO PAROQUIAL DE EDUCAÇÃO IN'!M10+'CEI VISTA ALEGRE'!M10+'CEI ALDEIA DA CRIANCA'!M10+'CEI DÉA LÚCIA CORDEIRO'!M10+'CENTRO DE EDUCAÇÃO INFANTIL CAR'!M10+'CEI IRMÃ SILVANA'!M10+'CEI MARLI SOARES FERREIRA NETTO'!M10+'CEI PROFª SONIA REGINA SCUDESE '!M10+'CEI DONA ESPERANZA DE BOURBON D'!M10+'CEI PREFEITO SÉRGIO FADEL'!M10+'CEI ANDRÉ REBOUÇAS'!M10+'CENTRO DE EDUCAÇÃO INFANTIL CHI'!M10+'CEI TIA ALICE'!M10+'CEI TERRA SANTA'!M10+'CEI JORGE ROLANDO DA SILVA'!M10+'CEI CARANGOLA'!M10+'CEI CÉLIA LÔBO PAULO'!M10+'CEI LIONS CLUBE DE PETRÓPOLIS'!M10+'CEI PROFª GRAÇA COSTA'!M10+'CEI ANGELA MARIA DA CONCEIÇÃO S'!M10+'CEI LUIZ MARCHIORI'!M10+'CEI PROFª MARLUCE DE SOUZA PEST'!M10+'CEI OLÍVIA MACHADO DA COSTA NOG'!M10+'CEI VILA IPANEMA'!M10+'CEI VILA LEOPOLDINA'!M10+'CENTRO DE EDUCAÇÃO INFANTIL CAS'!M10+'CEI PRIMEIRA INFÂNCIA'!M10+'CEI PROFª DORA KILLER'!M10+'CEI PROFª PATRÍCIA FERREIRA E S'!M10+'CEI DRA ZILDA ARNS NEUMANN'!M10+'CEI DENISE BESSA DE OLIVA MAYA'!M10+'CEI GIUSEPPE-NEVA VOLONTERIO'!M10+'CENTRO DE EDUCAÇÃO INFANTIL LOT'!M10+'CEI IRINEU MARINHO'!M10+'CEI OSWALDO CRUZ'!M10+'CEI ANA CAROLINA TELLES'!M10+'CEI JOSÉ GONÇALVES DA MOTTA'!M10+'CEI SAGRADA FAMÍLIA'!M10+'CEI PROFª HERMÍNIA MATHEUS'!M10+'CENTRO DE EDUCAÇÃO INFANTIL PRO'!M10+'CEI MONSENHOR PAULO ELIAS DAHER'!M10+'CEI DAGMAR ROLANDO DE OLIVEIRA'!M10+'CENTRO DE EDUCAÇÃO INFANTIL 2'!M10+'CEI BOA VISTA'!M10+'CEI NILO PEÇANHA'!M10+'CENTRO DE EDUCAÇÃO INFANTIL AUG'!M10+'CEI THEREZINHA DE JESUS LIMA'!M10+'CEI VIDEIRINHA'!M10+'CEI PROFª ADRIANA CONSTÂNCIO TR'!M10+'CENTRO DE EDUCAÇÃO INFANTIL SÉR'!M10+'CEI JURACI PINTO DO AMARAL DE C'!M10+'CEI NOSSA SENHORA DA GLÓRIA'!M10+'CEI ALTO INDEPENDÊNCIA'!M10+'CEI SÃO JOSÉ DAS OBLATAS DE NAZ'!M10+'CEI SANTO ANTÔNIO AGOSTINHO'!M10+'CEI SÃO CHARBEL'!M10+'ASSOCIAÇÃO DA CRECHE SÃO FRANCI'!M10+'CEI SÃO JOSÉ DO ITAMARATI'!M10+'ASSOCIAÇÃO RECREAR'!M10+'CRECHE-ESCOLA CASTELO SÃO MANOE'!M10+'CENTRO DE EDUCAÇÃO INFANTIL SÃO'!M10 | E6: ='Entrada de Dados'!D2 | F6: =D6*E6
A7: ='Entrada de Dados'!E5 | B7: ='Entrada de Dados'!E197 | C7: ='E M ROTARY'!D11+'E M DE EDUCAÇÃO ESPECIAL SANTOS'!D11+'LICEU MUN PREFEITO CORDOLINO AM'!D11+'E M PREFEITO JAMIL SABRÁ'!D11+'LICEU MUNICIPAL CARLOS CHAGAS F'!D11+'E M PAULO FREIRE'!D11+'E M PROFª MARIA CAMPOS DA SILVA'!D11+'CASA DA EDUCAÇÃO VISCONDE DE MA'!D11+'CENTRO DE REFERÊNCIA EM EDUCAÇÃ'!D11+'ESCOLA SANTA LUIZA DE MARILLAC'!D11+'ESCOLA DOMÉSTICA NOSSA SENHORA '!D11+'ESCOLA MONSENHOR GENTIL'!D11+'ESCOLA PAROQUIAL NOSSA SENHORA '!D11+'ESCOLA PAROQUIAL SÃO PEDRO DE A'!D11+'CEI TERRA SANTA'!D11+'CEI PRIMEIRA INFÂNCIA'!D11+'CEI PROFª PATRÍCIA FERREIRA E S'!D11+'CEI DRA ZILDA ARNS NEUMANN'!D11+'CENTRO DE EDUCAÇÃO INFANTIL PRO'!D11+'CEI MONSENHOR PAULO ELIAS DAHER'!D11+'COLÉGIO GUNNAR VINGREN DE PETRÓ'!D11+'EDUCANDÁRIO TERRA SANTA'!D11+'CEI LIONS CLUBE DE PETRÓPOLIS'!D11+'ESCOLA PAROQUIAL NOSSA SENHO 2'!D11+'CENTRO DE EDUCAÇÃO INFANTIL IRM'!D11+'E M LUIZ CARLOS SOARES'!D11+'ESCOLA GERMANO VALENTE'!D11+'ESCOLA PAROQUIAL NOSSA SENHO 3'!D11+'CEI JORGE ROLANDO DA SILVA'!D11+'E M CLEMENTE FERNANDES'!D11+'E M GERALDO VENTURA DIAS'!D11+'ESCOLA DAS COMUNIDADES SANTO AN'!D11+'CEI PROFª ROSANGELA DA SILVA LE'!D11+'CEI DEISE ELOY GOMES'!D11+'CEI PROFª SONIA REGINA SCUDESE '!D11+'CEI TIA ALICE'!D11+'E M BATAILLARD'!D11+'E M SOROPTIMISTA'!D11+'E M SALVADOR KLING'!D11+'ESCOLA MUNICIPALIZADA FREI ANIC'!D11+'ESCOLA SÃO JUDAS TADEU'!D11+'CEI PEDRAS BRANCAS'!D11+'CEI MARIA THEREZA KLING DO VALL'!D11+'CEI DONA ESPERANZA DE BOURBON D'!D11+'CEI GIUSEPPE-NEVA VOLONTERIO'!D11+'CENTRO DE EDUCAÇÃO INFANTIL SÃO'!D11+'E M LEONARDO BOFF'!D11+'ESCOLA MUNICIPAL GENERAL HEITOR'!D11+'E M JOHANN NOEL'!D11+'ESCOLA SANTA MARIA GORETTI'!D11+'ESCOLA SANTA RITA DE CASSIA'!D11+'ESCOLA SÃO JOÃO BATISTA'!D11+'CEI CASA DA SOLIDARIEDADE DE NO'!D11+'CEI A SEMENTEIRA'!D11+'CEI VILA SAO JOSE'!D11+'E M DR RUBENS DE CASTRO BOMTEMP'!D11+'CEI FREI LEÃO'!D11+'CEI SÃO JOÃO BATISTA'!D11+'CEI JURACI PINTO DO AMARAL DE C'!D11+'E M PEDRO AMADO'!D11+'E M ABELARDO DE LAMARE'!D11+'ESCOLA MUNICIPAL SENADOR MARIO '!D11+'ESCOLA PAROQUIAL SÃO PIO X'!D11+'CEI SÃO CHARBEL'!D11+'E M ROSALINA NICOLAY'!D11+'CEI INÊS BELARMINO DE SOUZA'!D11+'E M PROFª MARIA DA GLÓRIA QUEIR'!D11+'CENTRO EDUCACIONAL COMUNIDADE S'!D11+'CEI ROMANO CANAVESE'!D11+'CEI CÉLIA LÔBO PAULO'!D11+'CEI PROFª DORA KILLER'!D11+'CEI ALTO INDEPENDÊNCIA'!D11+'ESCOLA MUNICIPAL ALTO INDEPENDÊ'!D11+'E M PAPA JOÃO PAULO II'!D11+'CEI ANDRÉ REBOUÇAS'!D11+'CEI PROFª HERMÍNIA MATHEUS'!D11+'ESCOLA MUNICIPAL MAJOR JÚLIO FR'!D11+'E M ALMIRANTE TAMANDARÉ'!D11+'ESCOLA PAROQUIAL CARLOS DEMIÁ'!D11+'CENTRO PAROQUIAL DE EDUCAÇÃO IN'!D11+'CEI IRMÃ SILVANA'!D11+'CEI OLÍVIA MACHADO DA COSTA NOG'!D11+'E M GOVERNADOR MARCELLO ALENCAR'!D11+'E M PROFESSOR FLÁVIO MACIEL'!D11+'E M PROFª JANDIRA PEIXOTO BORDI'!D11+'E M STEFAN ZWEIG'!D11+'ESCOLA PAROQUIAL BOM JESUS'!D11+'CEI MARLI SOARES FERREIRA NETTO'!D11+'CENTRO DE EDUCAÇÃO INFANTIL CHI'!D11+'CEI VILA IPANEMA'!D11+'E M ROBERT KENNEDY'!D11+'ESCOLA MUNICIPAL ANA MOHAMMAD'!D11+'ESCOLA SÃO CRISTÓVÃO'!D11+'CEI DÉA LÚCIA CORDEIRO'!D11+'CEI SAGRADA FAMÍLIA'!D11+'CEI SÃO JOSÉ DAS OBLATAS DE NAZ'!D11+'ESCOLA MUNICIPAL JORGE AMADO'!D11+'E M FÁBRICA DO SABER'!D11+'CIEP BRIZOLÃO 474 MAESTRO GUERR'!D11+'CENTRO DE ENSINO PROF DARCY RIB'!D11+'CEI ANDRÉ VANZAN'!D11+'CENTRO DE EDUCAÇÃO INFANTIL CAR'!D11+'CEI BOA VISTA'!D11+'ASSOCIAÇÃO DA CRECHE SÃO FRANCI'!D11+'ESCOLA MUNICIPAL PAULO SALDANHA'!D11+'ESCOLA MUNICIPAL LÚCIA DE ALMEI'!D11+'E M DOM MANOEL PEDRO DA CUNHA C'!D11+'ESCOLA SÃO GERALDO'!D11+'CEI LULU MONTEIRO DE CASTRO'!D11+'CEI CARANGOLA'!D11+'ASSOCIAÇÃO RECREAR'!D11+'CENTRO DE EDUCAÇÃO INFANTIL CAS'!D11+'E M ROSEMIRA DE OLIVEIRA CAVALC'!D11+'E MZDA CARMEM NUNES MARTINS'!D11+'CEI SÃO JOSÉ DO ITAMARATI'!D11+'E M DUQUE DE CAXIAS'!D11+'CENTRO DE EDUCAÇÃO INFANTIL 2'!D11+'E M ANTÔNIO LEITE GARCIA'!D11+'ESCOLA PAROQUIAL DA ALCOBAÇA'!D11+'CENTRO DE EDUCAÇÃO INFANTIL LOT'!D11+'ESCOLA PAROQUIAL DO LOTEAMENTO '!D11+'E M PROF JOAQUIM DEISTER'!D11+'E M MARIETA GONÇALVES'!D11+'ESCOLA MUNICIPAL ODETTE YOUNG M'!D11+'ESCOLA MUNICIPAL PROFESSOR JOSE'!D11+'E M HERCÍLIA HENRIQUES MORET'!D11+'COLEGIO VICENTINO PADRE CORRÊA'!D11+'CEI PROFª MARLUCE DE SOUZA PEST'!D11+'CEI IRINEU MARINHO'!D11+'CEI DAGMAR ROLANDO DE OLIVEIRA'!D11+'CEI NOSSA SENHORA DA GLÓRIA'!D11+'E M PROF NILTON COSTA PEREIRA D'!D11+'CENTRO DE EDUCAÇÃO INFANTIL SÉR'!D11+'CEI SANTO ANTÔNIO AGOSTINHO'!D11+'CEI OSWALDO CRUZ'!D11+'E M MAGDALENA TAGLIAFERRO'!D11+'ESCOLA SÃO JOSÉ DO CAETITU'!D11+'CRECHE-ESCOLA CASTELO SÃO MANOE'!D11+'CEI THEREZINHA DE JESUS LIMA'!D11+'ESCOLA MUNICIPAL PROFESSOR PAUL'!D11+'COLÉGIO ANGLICANO DE ARARAS'!D11+'ESCOLA PAROQUIAL SANTA BERNADET'!D11+'CEI VISTA ALEGRE'!D11+'CEI DENISE BESSA DE OLIVA MAYA'!D11+'CEI VIDEIRINHA'!D11+'E M AMÉRICO FERNANDES RIBEIRO'!D11+'ESCOLA MUNICIPAL AUGUSTO PUGNAL'!D11+'ESCOLA MUNICIPAL CELINA SCHECHN'!D11+'E M DARCY CORREA DA VEIGA'!D11+'E M DR PAULA BUARQUE'!D11+'LICEU SÃO JOSÉ DE ITAIPAVA'!D11+'CEI LUIZ MARCHIORI'!D11+'CENTRO DE EDUCAÇÃO INFANTIL AUG'!D11+'CEI PROFª ADRIANA CONSTÂNCIO TR'!D11+'E M AMÉLIA ANTUNES RABELLO'!D11+'CEI PREFEITO SÉRGIO FADEL'!D11+'E M DR THEODORO MACHADO'!D11+'ESCOLA SANTO ANTÔNIO'!D11+'E M TAQUARIL'!D11+'E M MONSENHOR JOÃO DE DEUS RODR'!D11+'CENTRO DE REFERÊNCIA EM EDUC 2'!D11+'CEI PROFª GRAÇA COSTA'!D11+'CEI VILA LEOPOLDINA'!D11+'CEI NILO PEÇANHA'!D11+'E MZDA SANTA TEREZINHA'!D11+'CEI CRIANÇA SANTA EDWIGES'!D11+'E M ARNALDO DYCKERHOFF'!D11+'E M CARLOS CANEDO'!D11+'E M BEATRIZ ZALESKI'!D11+'E M ANTÔNIO JOSÉ DE LIMA'!D11+'E M FELIX WAN ERVEN DE BARROS'!D11+'ESCOLA MUNICIPAL HILDEBRANDO DE'!D11+'E M OSWALDO DA COSTA FRIAS'!D11+'E MZDA AVELINO DE CARVALHO'!D11+'ESCOLA MUNICIPALIZADA MOYSÉS FU'!D11+'CEI ANGELA MARIA DA CONCEIÇÃO S'!D11+'CEI JOSÉ GONÇALVES DA MOTTA'!D11+'E M DR BARROS FRANCO'!D11+'E M MAJOR THEÓFILO DE CARVALHO'!D11+'E M JOÃO KOPKE'!D11+'CEI ASSOCIAÇÃO BENEFICENTE FAZE'!D11+'ESCOLA SAO FRANCISCO DE ASSIS'!D11+'CEI SÃO FRANCISCO ASSIS'!D11+'CEI ALDEIA DA CRIANCA'!D11+'ESCOLA MUNICIPAL ODETTE FONSECA'!D11+'CEI ANA CAROLINA TELLES'!D11+'E M SEBASTIÃO LACERDA'!D11+'E M DOM PEDRO DE ALCÂNTARA'!D11+'ESCOLA NOSSA SENHORA DE FÁTIMA'!D11+'ESCOLA PAROQUIAL SÃO FRANCISCO '!D11+'E M MONSENHOR CIRILLO CALAON'!D11 | D7: ='E M ABELARDO DE LAMARE'!M11+'E M BATAILLARD'!M11+'E M LEONARDO BOFF'!M11+'E M CLEMENTE FERNANDES'!M11+'E M DOM PEDRO DE ALCÂNTARA'!M11+'E M DUQUE DE CAXIAS'!M11+'E M LUIZ CARLOS SOARES'!M11+'ESCOLA MUNICIPAL GENERAL HEITOR'!M11+'E M JOÃO KOPKE'!M11+'ESCOLA MUNICIPAL ODETTE FONSECA'!M11+'E M GOVERNADOR MARCELLO ALENCAR'!M11+'E M PROF JOAQUIM DEISTER'!M11+'E M ROBERT KENNEDY'!M11+'E M ROTARY'!M11+'E M ROSALINA NICOLAY'!M11+'E M DE EDUCAÇÃO ESPECIAL SANTOS'!M11+'E M SOROPTIMISTA'!M11+'LICEU MUN PREFEITO CORDOLINO AM'!M11+'E M ANTÔNIO LEITE GARCIA'!M11+'ESCOLA MUNICIPAL JORGE AMADO'!M11+'ESCOLA MUNICIPAL LÚCIA DE ALMEI'!M11+'E M MAGDALENA TAGLIAFERRO'!M11+'ESCOLA MUNICIPAL MAJOR JÚLIO FR'!M11+'E M MARIETA GONÇALVES'!M11+'ESCOLA MUNICIPAL ODETTE YOUNG M'!M11+'E M FÁBRICA DO SABER'!M11+'ESCOLA MUNICIPAL PROFESSOR PAUL'!M11+'E M ROSEMIRA DE OLIVEIRA CAVALC'!M11+'E M AMÉLIA ANTUNES RABELLO'!M11+'ESCOLA MUNICIPAL AUGUSTO PUGNAL'!M11+'ESCOLA MUNICIPAL CELINA SCHECHN'!M11+'E M DARCY CORREA DA VEIGA'!M11+'E M DR PAULA BUARQUE'!M11+'E M DR THEODORO MACHADO'!M11+'E M ARNALDO DYCKERHOFF'!M11+'E M CARLOS CANEDO'!M11+'E M DR BARROS FRANCO'!M11+'E M MAJOR THEÓFILO DE CARVALHO'!M11+'E M TAQUARIL'!M11+'E M BEATRIZ ZALESKI'!M11+'E M ANTÔNIO JOSÉ DE LIMA'!M11+'E M FELIX WAN ERVEN DE BARROS'!M11+'ESCOLA MUNICIPAL HILDEBRANDO DE'!M11+'E M OSWALDO DA COSTA FRIAS'!M11+'E MZDA CARMEM NUNES MARTINS'!M11+'E MZDA AVELINO DE CARVALHO'!M11+'E M GERALDO VENTURA DIAS'!M11+'E M SALVADOR KLING'!M11+'E M PREFEITO JAMIL SABRÁ'!M11+'LICEU MUNICIPAL CARLOS CHAGAS F'!M11+'ESCOLA MUNICIPAL ANA MOHAMMAD'!M11+'ESCOLA MUNICIPAL ALTO INDEPENDÊ'!M11+'E M ALMIRANTE TAMANDARÉ'!M11+'ESCOLA MUNICIPALIZADA FREI ANIC'!M11+'E M PEDRO AMADO'!M11+'E M PROFª MARIA DA GLÓRIA QUEIR'!M11+'E M SEBASTIÃO LACERDA'!M11+'E M PROFESSOR FLÁVIO MACIEL'!M11+'ESCOLA MUNICIPAL PAULO SALDANHA'!M11+'ESCOLA MUNICIPAL PROFESSOR JOSE'!M11+'E M MONSENHOR CIRILLO CALAON'!M11+'E M AMÉRICO FERNANDES RIBEIRO'!M11+'E M PROFª JANDIRA PEIXOTO BORDI'!M11+'E M MONSENHOR JOÃO DE DEUS RODR'!M11+'E M DOM MANOEL PEDRO DA CUNHA C'!M11+'E M JOHANN NOEL'!M11+'E MZDA SANTA TEREZINHA'!M11+'E M PAPA JOÃO PAULO II'!M11+'E M STEFAN ZWEIG'!M11+'ESCOLA MUNICIPAL SENADOR MARIO '!M11+'E M DR RUBENS DE CASTRO BOMTEMP'!M11+'E M PAULO FREIRE'!M11+'E M PROFª MARIA CAMPOS DA SILVA'!M11+'E M HERCÍLIA HENRIQUES MORET'!M11+'ESCOLA MUNICIPALIZADA MOYSÉS FU'!M11+'CIEP BRIZOLÃO 474 MAESTRO GUERR'!M11+'CENTRO DE ENSINO PROF DARCY RIB'!M11+'CASA DA EDUCAÇÃO VISCONDE DE MA'!M11+'CENTRO DE REFERÊNCIA EM EDUCAÇÃ'!M11+'E M PROF NILTON COSTA PEREIRA D'!M11+'COLÉGIO GUNNAR VINGREN DE PETRÓ'!M11+'CENTRO DE REFERÊNCIA EM EDUC 2'!M11+'ESCOLA SANTA LUIZA DE MARILLAC'!M11+'CENTRO EDUCACIONAL COMUNIDADE S'!M11+'EDUCANDÁRIO TERRA SANTA'!M11+'ESCOLA GERMANO VALENTE'!M11+'ESCOLA DAS COMUNIDADES SANTO AN'!M11+'ESCOLA DOMÉSTICA NOSSA SENHORA '!M11+'ESCOLA PAROQUIAL NOSSA SENHO 3'!M11+'ESCOLA MONSENHOR GENTIL'!M11+'ESCOLA PAROQUIAL BOM JESUS'!M11+'ESCOLA PAROQUIAL CARLOS DEMIÁ'!M11+'ESCOLA PAROQUIAL NOSSA SENHO 2'!M11+'ESCOLA PAROQUIAL NOSSA SENHORA '!M11+'ESCOLA PAROQUIAL SÃO PEDRO DE A'!M11+'ESCOLA SANTA MARIA GORETTI'!M11+'ESCOLA SANTA RITA DE CASSIA'!M11+'ESCOLA SÃO CRISTÓVÃO'!M11+'ESCOLA PAROQUIAL SÃO FRANCISCO '!M11+'ESCOLA SAO FRANCISCO DE ASSIS'!M11+'ESCOLA SÃO JOÃO BATISTA'!M11+'ESCOLA SÃO JUDAS TADEU'!M11+'ESCOLA PAROQUIAL SÃO PIO X'!M11+'COLÉGIO ANGLICANO DE ARARAS'!M11+'COLEGIO VICENTINO PADRE CORRÊA'!M11+'ESCOLA NOSSA SENHORA DE FÁTIMA'!M11+'ESCOLA PAROQUIAL DA ALCOBAÇA'!M11+'ESCOLA PAROQUIAL DO LOTEAMENTO '!M11+'ESCOLA PAROQUIAL SANTA BERNADET'!M11+'ESCOLA SÃO GERALDO'!M11+'ESCOLA SANTO ANTÔNIO'!M11+'LICEU SÃO JOSÉ DE ITAIPAVA'!M11+'ESCOLA SÃO JOSÉ DO CAETITU'!M11+'CEI ASSOCIAÇÃO BENEFICENTE FAZE'!M11+'CEI CASA DA SOLIDARIEDADE DE NO'!M11+'CEI LULU MONTEIRO DE CASTRO'!M11+'CEI SÃO JOÃO BATISTA'!M11+'CEI SÃO FRANCISCO ASSIS'!M11+'CEI A SEMENTEIRA'!M11+'CEI FREI LEÃO'!M11+'CEI ROMANO CANAVESE'!M11+'CEI ANDRÉ VANZAN'!M11+'CEI CRIANÇA SANTA EDWIGES'!M11+'CENTRO DE EDUCAÇÃO INFANTIL IRM'!M11+'CEI PEDRAS BRANCAS'!M11+'CEI INÊS BELARMINO DE SOUZA'!M11+'CEI PROFª ROSANGELA DA SILVA LE'!M11+'CEI VILA SAO JOSE'!M11+'CEI MARIA THEREZA KLING DO VALL'!M11+'CEI DEISE ELOY GOMES'!M11+'CENTRO PAROQUIAL DE EDUCAÇÃO IN'!M11+'CEI VISTA ALEGRE'!M11+'CEI ALDEIA DA CRIANCA'!M11+'CEI DÉA LÚCIA CORDEIRO'!M11+'CENTRO DE EDUCAÇÃO INFANTIL CAR'!M11+'CEI IRMÃ SILVANA'!M11+'CEI MARLI SOARES FERREIRA NETTO'!M11+'CEI PROFª SONIA REGINA SCUDESE '!M11+'CEI DONA ESPERANZA DE BOURBON D'!M11+'CEI PREFEITO SÉRGIO FADEL'!M11+'CEI ANDRÉ REBOUÇAS'!M11+'CENTRO DE EDUCAÇÃO INFANTIL CHI'!M11+'CEI TIA ALICE'!M11+'CEI TERRA SANTA'!M11+'CEI JORGE ROLANDO DA SILVA'!M11+'CEI CARANGOLA'!M11+'CEI CÉLIA LÔBO PAULO'!M11+'CEI LIONS CLUBE DE PETRÓPOLIS'!M11+'CEI PROFª GRAÇA COSTA'!M11+'CEI ANGELA MARIA DA CONCEIÇÃO S'!M11+'CEI LUIZ MARCHIORI'!M11+'CEI PROFª MARLUCE DE SOUZA PEST'!M11+'CEI OLÍVIA MACHADO DA COSTA NOG'!M11+'CEI VILA IPANEMA'!M11+'CEI VILA LEOPOLDINA'!M11+'CENTRO DE EDUCAÇÃO INFANTIL CAS'!M11+'CEI PRIMEIRA INFÂNCIA'!M11+'CEI PROFª DORA KILLER'!M11+'CEI PROFª PATRÍCIA FERREIRA E S'!M11+'CEI DRA ZILDA ARNS NEUMANN'!M11+'CEI DENISE BESSA DE OLIVA MAYA'!M11+'CEI GIUSEPPE-NEVA VOLONTERIO'!M11+'CENTRO DE EDUCAÇÃO INFANTIL LOT'!M11+'CEI IRINEU MARINHO'!M11+'CEI OSWALDO CRUZ'!M11+'CEI ANA CAROLINA TELLES'!M11+'CEI JOSÉ GONÇALVES DA MOTTA'!M11+'CEI SAGRADA FAMÍLIA'!M11+'CEI PROFª HERMÍNIA MATHEUS'!M11+'CENTRO DE EDUCAÇÃO INFANTIL PRO'!M11+'CEI MONSENHOR PAULO ELIAS DAHER'!M11+'CEI DAGMAR ROLANDO DE OLIVEIRA'!M11+'CENTRO DE EDUCAÇÃO INFANTIL 2'!M11+'CEI BOA VISTA'!M11+'CEI NILO PEÇANHA'!M11+'CENTRO DE EDUCAÇÃO INFANTIL AUG'!M11+'CEI THEREZINHA DE JESUS LIMA'!M11+'CEI VIDEIRINHA'!M11+'CEI PROFª ADRIANA CONSTÂNCIO TR'!M11+'CENTRO DE EDUCAÇÃO INFANTIL SÉR'!M11+'CEI JURACI PINTO DO AMARAL DE C'!M11+'CEI NOSSA SENHORA DA GLÓRIA'!M11+'CEI ALTO INDEPENDÊNCIA'!M11+'CEI SÃO JOSÉ DAS OBLATAS DE NAZ'!M11+'CEI SANTO ANTÔNIO AGOSTINHO'!M11+'CEI SÃO CHARBEL'!M11+'ASSOCIAÇÃO DA CRECHE SÃO FRANCI'!M11+'CEI SÃO JOSÉ DO ITAMARATI'!M11+'ASSOCIAÇÃO RECREAR'!M11+'CRECHE-ESCOLA CASTELO SÃO MANOE'!M11+'CENTRO DE EDUCAÇÃO INFANTIL SÃO'!M11 | E7: ='Entrada de Dados'!E2 | F7: =D7*E7
