Workbook

Sheet ÍNDICE
A1: ÍNDICE — CLIQUE NO NOME PARA ABRIR A ABA
A3: ABAS DE TRABALHO
A4: =HYPERLINK("#'Entrada de Dados'!A1","Entrada de Dados") | B4: onde você digita pedido e entrega
A5: =HYPERLINK("#'RESUMO'!A1","RESUMO") | B5: o resultado final, calculado sozinho
A6: =HYPERLINK("#'BALANÇO FINANCEIRO'!A1","BALANÇO FINANCEIRO") | B6: custos reais da semana e saldo (positivo ou negativo)
A7: =HYPERLINK("#'DIFERENÇA'!A1","DIFERENÇA") | B7: quanto faltou entregar, produto por produto
A8: =HYPERLINK("#'MAPA DE MONTAGEM'!A1","MAPA DE MONTAGEM") | B8: separação da carga por rota — segunda e terça
A9: =HYPERLINK("#'MAPA DE PRODUÇÃO'!A1","MAPA DE PRODUÇÃO") | B9: quem planta o quê, por mês
A10: =HYPERLINK("#'MOTIVO'!A1","MOTIVO") | B10: lista de motivos de devolução
A12: COMO USAR — PASSO A PASSO
A13: 1. Pedido da prefeitura | B13: Entrada de Dados, bloco de cima → digite a quantidade de cada produto, na linha de cada escola.
A14: 2. Decidir quem entrega | B14: Abra o Mapa de Produção → veja quem planta cada produto e quanto planejou naquele mês.
A15: 3. Pedido aos produtores | B15: Entrada de Dados, bloco do meio → digite quanto vai pedir a cada produtor.
A16: 4. Entrega real | B16: Caminhão chegou → Entrada de Dados, bloco de baixo → digite quanto cada produtor realmente trouxe.
A17: 5. Devolução da escola (se houver) | B17: Clique no nome da escola (vira link) → anote a devolução e o motivo.
A18: 6. Devolução do produtor (se houver) | B18: Clique em "Anotar devolução" na linha do produtor → registre lá, com o motivo.
A19: 7. Montagem da carga | B19: Abra o Mapa de Montagem → escolha a rota do dia (S1–S10 segunda, T1–T8 terça) e separe os produtos na ordem da parada.
A20: 8. Resultado | B20: Abra o RESUMO — não precisa digitar nada, já mostra quanto cobrar, quanto pagar, e a margem.
A21: 9. Balanço financeiro | B21: Abra o Balanço Financeiro → digite os custos reais da semana (frete, montagem, etc.) e veja o saldo final.
A23: ESCOLAS
A24: CÓDIGO | B24: ESCOLA (clique para abrir) | C24: BAIRRO
A25: ='E M ABELARDO DE LAMARE'!B5 | B25: =HYPERLINK("#'E M ABELARDO DE LAMARE'!A1",'E M ABELARDO DE LAMARE'!B2) | C25: ='E M ABELARDO DE LAMARE'!B3
A26: ='E M BATAILLARD'!B5 | B26: =HYPERLINK("#'E M BATAILLARD'!A1",'E M BATAILLARD'!B2) | C26: ='E M BATAILLARD'!B3
A27: ='E M LEONARDO BOFF'!B5 | B27: =HYPERLINK("#'E M LEONARDO BOFF'!A1",'E M LEONARDO BOFF'!B2) | C27: ='E M LEONARDO BOFF'!B3
A28: ='E M CLEMENTE FERNANDES'!B5 | B28: =HYPERLINK("#'E M CLEMENTE FERNANDES'!A1",'E M CLEMENTE FERNANDES'!B2) | C28: ='E M CLEMENTE FERNANDES'!B3
A29: ='E M DOM PEDRO DE ALCÂNTARA'!B5 | B29: =HYPERLINK("#'E M DOM PEDRO DE ALCÂNTARA'!A1",'E M DOM PEDRO DE ALCÂNTARA'!B2) | C29: ='E M DOM PEDRO DE ALCÂNTARA'!B3
A30: ='E M DUQUE DE CAXIAS'!B5 | B30: =HYPERLINK("#'E M DUQUE DE CAXIAS'!A1",'E M DUQUE DE CAXIAS'!B2) | C30: ='E M DUQUE DE CAXIAS'!B3
A31: ='E M LUIZ CARLOS SOARES'!B5 | B31: =HYPERLINK("#'E M LUIZ CARLOS SOARES'!A1",'E M LUIZ CARLOS SOARES'!B2) | C31: ='E M LUIZ CARLOS SOARES'!B3
A32: ='ESCOLA MUNICIPAL GENERAL HEITOR'!B5 | B32: =HYPERLINK("#'ESCOLA MUNICIPAL GENERAL HEITOR'!A1",'ESCOLA MUNICIPAL GENERAL HEITOR'!B2) | C32: ='ESCOLA MUNICIPAL GENERAL HEITOR'!B3
A33: ='E M JOÃO KOPKE'!B5 | B33: =HYPERLINK("#'E M JOÃO KOPKE'!A1",'E M JOÃO KOPKE'!B2) | C33: ='E M JOÃO KOPKE'!B3
A34: ='ESCOLA MUNICIPAL ODETTE FONSECA'!B5 | B34: =HYPERLINK("#'ESCOLA MUNICIPAL ODETTE FONSECA'!A1",'ESCOLA MUNICIPAL ODETTE FONSECA'!B2) | C34: ='ESCOLA MUNICIPAL ODETTE FONSECA'!B3
A35: ='E M GOVERNADOR MARCELLO ALENCAR'!B5 | B35: =HYPERLINK("#'E M GOVERNADOR MARCELLO ALENCAR'!A1",'E M GOVERNADOR MARCELLO ALENCAR'!B2) | C35: ='E M GOVERNADOR MARCELLO ALENCAR'!B3
A36: ='E M PROF JOAQUIM DEISTER'!B5 | B36: =HYPERLINK("#'E M PROF JOAQUIM DEISTER'!A1",'E M PROF JOAQUIM DEISTER'!B2) | C36: ='E M PROF JOAQUIM DEISTER'!B3
A37: ='E M ROBERT KENNEDY'!B5 | B37: =HYPERLINK("#'E M ROBERT KENNEDY'!A1",'E M ROBERT KENNEDY'!B2) | C37: ='E M ROBERT KENNEDY'!B3
A38: ='E M ROTARY'!B5 | B38: =HYPERLINK("#'E M ROTARY'!A1",'E M ROTARY'!B2) | C38: ='E M ROTARY'!B3
A39: ='E M ROSALINA NICOLAY'!B5 | B39: =HYPERLINK("#'E M ROSALINA NICOLAY'!A1",'E M ROSALINA NICOLAY'!B2) | C39: ='E M ROSALINA NICOLAY'!B3
A40: ='E M DE EDUCAÇÃO ESPECIAL SANTOS'!B5 | B40: =HYPERLINK("#'E M DE EDUCAÇÃO ESPECIAL SANTOS'!A1",'E M DE EDUCAÇÃO ESPECIAL SANTOS'!B2) | C40: ='E M DE EDUCAÇÃO ESPECIAL SANTOS'!B3
A41: ='E M SOROPTIMISTA'!B5 | B41: =HYPERLINK("#'E M SOROPTIMISTA'!A1",'E M SOROPTIMISTA'!B2) | C41: ='E M SOROPTIMISTA'!B3
A42: ='LICEU MUN PREFEITO CORDOLINO AM'!B5 | B42: =HYPERLINK("#'LICEU MUN PREFEITO CORDOLINO AM'!A1",'LICEU MUN PREFEITO CORDOLINO AM'!B2) | C42: ='LICEU MUN PREFEITO CORDOLINO AM'!B3
A43: ='E M ANTÔNIO LEITE GARCIA'!B5 | B43: =HYPERLINK("#'E M ANTÔNIO LEITE GARCIA'!A1",'E M ANTÔNIO LEITE GARCIA'!B2) | C43: ='E M ANTÔNIO LEITE GARCIA'!B3
...

Sheet Entrada de Dados
A1: ENTRADA DE DADOS
A2: PREÇO (R$/kg) | C2: 15.57 | D2: 7.7 | E2: 16.94 | F2: 14.62 | G2: 12.05 | H2: 11.59 | I2: 9.87 | J2: 13.67 | K2: 10.2 | L2: 25.1 | M2: 8.56 | N2: 14.6 | O2: 19.11 | P2: 11.22 | Q2: 16.63 | R2: 65.68 | S2: 15.45 | T2: 10.24 | U2: 13.55
A4: PEDIDO DAS ESCOLAS (kg)
A5: CÓDIGO | B5: ESCOLA | C5: Abacate | D5: Abobrinha | E5: Agrião | F5: Alface lisa | G5: Banana prata | H5: Batata inglesa | I5: Beterraba | J5: Brócolis | K5: Cenoura | L5: Cheiro verde | M5: Chuchu | N5: Couve manteiga | O5: Couve-flor | P5: Espinafre | Q5: Maçã gala | R5: Mel | S5: Ovos (dz) | T5: Repolho | U5: Tangerina ponkan
A6: ='E M ABELARDO DE LAMARE'!B5 | B6: =HYPERLINK("#'E M ABELARDO DE LAMARE'!A1",'E M ABELARDO DE LAMARE'!B2) | C6: 0 | D6: 0 | E6: 0 | F6: 0 | G6: 0 | H6: 0 | I6: 0 | J6: 0 | K6: 0 | L6: 0 | M6: 0 | N6: 0 | O6: 0 | P6: 0 | Q6: 0 | R6: 0 | S6: 0 | T6: 0 | U6: 0
A7: ='E M BATAILLARD'!B5 | B7: =HYPERLINK("#'E M BATAILLARD'!A1",'E M BATAILLARD'!B2) | C7: 0 | D7: 0 | E7: 0 | F7: 0 | G7: 0 | H7: 0 | I7: 0 | J7: 0 | K7: 0 | L7: 0 | M7: 0 | N7: 0 | O7: 0 | P7: 0 | Q7: 0 | R7: 0 | S7: 0 | T7: 0 | U7: 0
A8: ='E M LEONARDO BOFF'!B5 | B8: =HYPERLINK("#'E M LEONARDO BOFF'!A1",'E M LEONARDO BOFF'!B2) | C8: 0 | D8: 0 | E8: 0 | F8: 0 | G8: 0 | H8: 0 | I8: 0 | J8: 0 | K8: 0 | L8: 0 | M8: 0 | N8: 0 | O8: 0 | P8: 0 | Q8: 0 | R8: 0 | S8: 0 | T8: 0 | U8: 0
A9: ='E M CLEMENTE FERNANDES'!B5 | B9: =HYPERLINK("#'E M CLEMENTE FERNANDES'!A1",'E M CLEMENTE FERNANDES'!B2) | C9: 0 | D9: 0 | E9: 0 | F9: 0 | G9: 0 | H9: 0 | I9: 0 | J9: 0 | K9: 0 | L9: 0 | M9: 0 | N9: 0 | O9: 0 | P9: 0 | Q9: 0 | R9: 0 | S9: 0 | T9: 0 | U9: 0
A10: ='E M DOM PEDRO DE ALCÂNTARA'!B5 | B10: =HYPERLINK("#'E M DOM PEDRO DE ALCÂNTARA'!A1",'E M DOM PEDRO DE ALCÂNTARA'!B2) | C10: 0 | D10: 0 | E10: 0 | F10: 0 | G10: 0 | H10: 0 | I10: 0 | J10: 0 | K10: 0 | L10: 0 | M10: 0 | N10: 0 | O10: 0 | P10: 0 | Q10: 0 | R10: 0 | S10: 0 | T10: 0 | U10: 0
A11: ='E M DUQUE DE CAXIAS'!B5 | B11: =HYPERLINK("#'E M DUQUE DE CAXIAS'!A1",'E M DUQUE DE CAXIAS'!B2) | C11: 0 | D11: 0 | E11: 0 | F11: 0 | G11: 0 | H11: 0 | I11: 0 | J11: 0 | K11: 0 | L11: 0 | M11: 0 | N11: 0 | O11: 0 | P11: 0 | Q11: 0 | R11: 0 | S11: 0 | T11: 0 | U11: 0
A12: ='E M LUIZ CARLOS SOARES'!B5 | B12: =HYPERLINK("#'E M LUIZ CARLOS SOARES'!A1",'E M LUIZ CARLOS SOARES'!B2) | C12: 0 | D12: 0 | E12: 0 | F12: 0 | G12: 0 | H12: 0 | I12: 0 | J12: 0 | K12: 0 | L12: 0 | M12: 0 | N12: 0 | O12: 0 | P12: 0 | Q12: 0 | R12: 0 | S12: 0 | T12: 0 | U12: 0
A13: ='ESCOLA MUNICIPAL GENERAL HEITOR'!B5 | B13: =HYPERLINK("#'ESCOLA MUNICIPAL GENERAL HEITOR'!A1",'ESCOLA MUNICIPAL GENERAL HEITOR'!B2) | C13: 0 | D13: 0 | E13: 0 | F13: 0 | G13: 0 | H13: 0 | I13: 0 | J13: 0 | K13: 0 | L13: 0 | M13: 0 | N13: 0 | O13: 0 | P13: 0 | Q13: 0 | R13: 0 | S13: 0 | T13: 0 | U13: 0
A14: ='E M JOÃO KOPKE'!B5 | B14: =HYPERLINK("#'E M JOÃO KOPKE'!A1",'E M JOÃO KOPKE'!B2) | C14: 0 | D14: 0 | E14: 0 | F14: 0 | G14: 0 | H14: 0 | I14: 0 | J14: 0 | K14: 0 | L14: 0 | M14: 0 | N14: 0 | O14: 0 | P14: 0 | Q14: 0 | R14: 0 | S14: 0 | T14: 0 | U14: 0
A15: ='ESCOLA MUNICIPAL ODETTE FONSECA'!B5 | B15: =HYPERLINK("#'ESCOLA MUNICIPAL ODETTE FONSECA'!A1",'ESCOLA MUNICIPAL ODETTE FONSECA'!B2) | C15: 0 | D15: 0 | E15: 0 | F15: 0 | G15: 0 | H15: 0 | I15: 0 | J15: 0 | K15: 0 | L15: 0 | M15: 0 | N15: 0 | O15: 0 | P15: 0 | Q15: 0 | R15: 0 | S15: 0 | T15: 0 | U15: 0
A16: ='E M GOVERNADOR MARCELLO ALENCAR'!B5 | B16: =HYPERLINK("#'E M GOVERNADOR MARCELLO ALENCAR'!A1",'E M GOVERNADOR MARCELLO ALENCAR'!B2) | C16: 0 | D16: 0 | E16: 0 | F16: 0 | G16: 0 | H16: 0 | I16: 0 | J16: 0 | K16: 0 | L16: 0 | M16: 0 | N16: 0 | O16: 0 | P16: 0 | Q16: 0 | R16: 0 | S16: 0 | T16: 0 | U16: 0
A17: ='E M PROF JOAQUIM DEISTER'!B5 | B17: =HYPERLINK("#'E M PROF JOAQUIM DEISTER'!A1",'E M PROF JOAQUIM DEISTER'!B2) | C17: 0 | D17: 0 | E17: 0 | F17: 0 | G17: 0 | H17: 0 | I17: 0 | J17: 0 | K17: 0 | L17: 0 | M17: 0 | N17: 0 | O17: 0 | P17: 0 | Q17: 0 | R17: 0 | S17: 0 | T17: 0 | U17: 0
A18: ='E M ROBERT KENNEDY'!B5 | B18: =HYPERLINK("#'E M ROBERT KENNEDY'!A1",'E M ROBERT KENNEDY'!B2) | C18: 0 | D18: 0 | E18: 0 | F18: 0 | G18: 0 | H18: 0 | I18: 0 | J18: 0 | K18: 0 | L18: 0 | M18: 0 | N18: 0 | O18: 0 | P18: 0 | Q18: 0 | R18: 0 | S18: 0 | T18: 0 | U18: 0
A19: ='E M ROTARY'!B5 | B19: =HYPERLINK("#'E M ROTARY'!A1",'E M ROTARY'!B2) | C19: 0 | D19: 0 | E19: 0 | F19: 0 | G19: 0 | H19: 0 | I19: 0 | J19: 0 | K19: 0 | L19: 0 | M19: 0 | N19: 0 | O19: 0 | P19: 0 | Q19: 0 | R19: 0 | S19: 0 | T19: 0 | U19: 0
A20: ='E M ROSALINA NICOLAY'!B5 | B20: =HYPERLINK("#'E M ROSALINA NICOLAY'!A1",'E M ROSALINA NICOLAY'!B2) | C20: 0 | D20: 0 | E20: 0 | F20: 0 | G20: 0 | H20: 0 | I20: 0 | J20: 0 | K20: 0 | L20: 0 | M20: 0 | N20: 0 | O20: 0 | P20: 0 | Q20: 0 | R20: 0 | S20: 0 | T20: 0 | U20: 0
A21: ='E M DE EDUCAÇÃO ESPECIAL SANTOS'!B5 | B21: =HYPERLINK("#'E M DE EDUCAÇÃO ESPECIAL SANTOS'!A1",'E M DE EDUCAÇÃO ESPECIAL SANTOS'!B2) | C21: 0 | D21: 0 | E21: 0 | F21: 0 | G21: 0 | H21: 0 | I21: 0 | J21: 0 | K21: 0 | L21: 0 | M21: 0 | N21: 0 | O21: 0 | P21: 0 | Q21: 0 | R21: 0 | S21: 0 | T21: 0 | U21: 0
A22: ='E M SOROPTIMISTA'!B5 | B22: =HYPERLINK("#'E M SOROPTIMISTA'!A1",'E M SOROPTIMISTA'!B2) | C22: 0 | D22: 0 | E22: 0 | F22: 0 | G22: 0 | H22: 0 | I22: 0 | J22: 0 | K22: 0 | L22: 0 | M22: 0 | N22: 0 | O22: 0 | P22: 0 | Q22: 0 | R22: 0 | S22: 0 | T22: 0 | U22: 0
A23: ='LICEU MUN PREFEITO CORDOLINO AM'!B5 | B23: =HYPERLINK("#'LICEU MUN PREFEITO CORDOLINO AM'!A1",'LICEU MUN PREFEITO CORDOLINO AM'!B2) | C23: 0 | D23: 0 | E23: 0 | F23: 0 | G23: 0 | H23: 0 | I23: 0 | J23: 0 | K23: 0 | L23: 0 | M23: 0 | N23: 0 | O23: 0 | P23: 0 | Q23: 0 | R23: 0 | S23: 0 | T23: 0 | U23: 0
A24: ='E M ANTÔNIO LEITE GARCIA'!B5 | B24: =HYPERLINK("#'E M ANTÔNIO LEITE GARCIA'!A1",'E M ANTÔNIO LEITE GARCIA'!B2) | C24: 0 | D24: 0 | E24: 0 | F24: 0 | G24: 0 | H24: 0 | I24: 0 | J24: 0 | K24: 0 | L24: 0 | M24: 0 | N24: 0 | O24: 0 | P24: 0 | Q24: 0 | R24: 0 | S24: 0 | T24: 0 | U24: 0
A25: ='ESCOLA MUNICIPAL JORGE AMADO'!B5 | B25: =HYPERLINK("#'ESCOLA MUNICIPAL JORGE AMADO'!A1",'ESCOLA MUNICIPAL JORGE AMADO'!B2) | C25: 0 | D25: 0 | E25: 0 | F25: 0 | G25: 0 | H25: 0 | I25: 0 | J25: 0 | K25: 0 | L25: 0 | M25: 0 | N25: 0 | O25: 0 | P25: 0 | Q25: 0 | R25: 0 | S25: 0 | T25: 0 | U25: 0
A26: ='ESCOLA MUNICIPAL LÚCIA DE ALMEI'!B5 | B26: =HYPERLINK("#'ESCOLA MUNICIPAL LÚCIA DE ALMEI'!A1",'ESCOLA MUNICIPAL LÚCIA DE ALMEI'!B2) | C26: 0 | D26: 0 | E26: 0 | F26: 0 | G26: 0 | H26: 0 | I26: 0 | J26: 0 | K26: 0 | L26: 0 | M26: 0 | N26: 0 | O26: 0 | P26: 0 | Q26: 0 | R26: 0 | S26: 0 | T26: 0 | U26: 0
A27: ='E M MAGDALENA TAGLIAFERRO'!B5 | B27: =HYPERLINK("#'E M MAGDALENA TAGLIAFERRO'!A1",'E M MAGDALENA TAGLIAFERRO'!B2) | C27: 0 | D27: 0 | E27: 0 | F27: 0 | G27: 0 | H27: 0 | I27: 0 | J27: 0 | K27: 0 | L27: 0 | M27: 0 | N27: 0 | O27: 0 | P27: 0 | Q27: 0 | R27: 0 | S27: 0 | T27: 0 | U27: 0
A28: ='ESCOLA MUNICIPAL MAJOR JÚLIO FR'!B5 | B28: =HYPERLINK("#'ESCOLA MUNICIPAL MAJOR JÚLIO FR'!A1",'ESCOLA MUNICIPAL MAJOR JÚLIO FR'!B2) | C28: 0 | D28: 0 | E28: 0 | F28: 0 | G28: 0 | H28: 0 | I28: 0 | J28: 0 | K28: 0 | L28: 0 | M28: 0 | N28: 0 | O28: 0 | P28: 0 | Q28: 0 | R28: 0 | S28: 0 | T28: 0 | U28: 0
A29: ='E M MARIETA GONÇALVES'!B5 | B29: =HYPERLINK("#'E M MARIETA GONÇALVES'!A1",'E M MARIETA GONÇALVES'!B2) | C29: 0 | D29: 0 | E29: 0 | F29: 0 | G29: 0 | H29: 0 | I29: 0 | J29: 0 | K29: 0 | L29: 0 | M29: 0 | N29: 0 | O29: 0 | P29: 0 | Q29: 0 | R29: 0 | S29: 0 | T29: 0 | U29: 0
A30: ='ESCOLA MUNICIPAL ODETTE YOUNG M'!B5 | B30: =HYPERLINK("#'ESCOLA MUNICIPAL ODETTE YOUNG M'!A1",'ESCOLA MUNICIPAL ODETTE YOUNG M'!B2) | C30: 0 | D30: 0 | E30: 0 | F30: 0 | G30: 0 | H30: 0 | I30: 0 | J30: 0 | K30: 0 | L30: 0 | M30: 0 | N30: 0 | O30: 0 | P30: 0 | Q30: 0 | R30: 0 | S30: 0 | T30: 0 | U30: 0
A31: ='E M FÁBRICA DO SABER'!B5 | B31: =HYPERLINK("#'E M FÁBRICA DO SABER'!A1",'E M FÁBRICA DO SABER'!B2) | C31: 0 | D31: 0 | E31: 0 | F31: 0 | G31: 0 | H31: 0 | I31: 0 | J31: 0 | K31: 0 | L31: 0 | M31: 0 | N31: 0 | O31: 0 | P31: 0 | Q31: 0 | R31: 0 | S31: 0 | T31: 0 | U31: 0
A32: ='ESCOLA MUNICIPAL PROFESSOR PAUL'!B5 | B32: =HYPERLINK("#'ESCOLA MUNICIPAL PROFESSOR PAUL'!A1",'ESCOLA MUNICIPAL PROFESSOR PAUL'!B2) | C32: 0 | D32: 0 | E32: 0 | F32: 0 | G32: 0 | H32: 0 | I32: 0 | J32: 0 | K32: 0 | L32: 0 | M32: 0 | N32: 0 | O32: 0 | P32: 0 | Q32: 0 | R32: 0 | S32: 0 | T32: 0 | U32: 0
A33: ='E M ROSEMIRA DE OLIVEIRA CAVALC'!B5 | B33: =HYPERLINK("#'E M ROSEMIRA DE OLIVEIRA CAVALC'!A1",'E M ROSEMIRA DE OLIVEIRA CAVALC'!B2) | C33: 0 | D33: 0 | E33: 0 | F33: 0 | G33: 0 | H33: 0 | I33: 0 | J33: 0 | K33: 0 | L33: 0 | M33: 0 | N33: 0 | O33: 0 | P33: 0 | Q33: 0 | R33: 0 | S33: 0 | T33: 0 | U33: 0
A34: ='E M AMÉLIA ANTUNES RABELLO'!B5 | B34: =HYPERLINK("#'E M AMÉLIA ANTUNES RABELLO'!A1",'E M AMÉLIA ANTUNES RABELLO'!B2) | C34: 0 | D34: 0 | E34: 0 | F34: 0 | G34: 0 | H34: 0 | I34: 0 | J34: 0 | K34: 0 | L34: 0 | M34: 0 | N34: 0 | O34: 0 | P34: 0 | Q34: 0 | R34: 0 | S34: 0 | T34: 0 | U34: 0
A35: ='ESCOLA MUNICIPAL AUGUSTO PUGNAL'!B5 | B35: =HYPERLINK("#'ESCOLA MUNICIPAL AUGUSTO PUGNAL'!A1",'ESCOLA MUNICIPAL AUGUSTO PUGNAL'!B2) | C35: 0 | D35: 0 | E35: 0 | F35: 0 | G35: 0 | H35: 0 | I35: 0 | J35: 0 | K35: 0 | L35: 0 | M35: 0 | N35: 0 | O35: 0 | P35: 0 | Q35: 0 | R35: 0 | S35: 0 | T35: 0 | U35: 0
A36: ='ESCOLA MUNICIPAL CELINA SCHECHN'!B5 | B36: =HYPERLINK("#'ESCOLA MUNICIPAL CELINA SCHECHN'!A1",'ESCOLA MUNICIPAL CELINA SCHECHN'!B2) | C36: 0 | D36: 0 | E36: 0 | F36: 0 | G36: 0 | H36: 0 | I36: 0 | J36: 0 | K36: 0 | L36: 0 | M36: 0 | N36: 0 | O36: 0 | P36: 0 | Q36: 0 | R36: 0 | S36: 0 | T36: 0 | U36: 0
A37: ='E M DARCY CORREA DA VEIGA'!B5 | B37: =HYPERLINK("#'E M DARCY CORREA DA VEIGA'!A1",'E M DARCY CORREA DA VEIGA'!B2) | C37: 0 | D37: 0 | E37: 0 | F37: 0 | G37: 0 | H37: 0 | I37: 0 | J37: 0 | K37: 0 | L37: 0 | M37: 0 | N37: 0 | O37: 0 | P37: 0 | Q37: 0 | R37: 0 | S37: 0 | T37: 0 | U37: 0
A38: ='E M DR PAULA BUARQUE'!B5 | B38: =HYPERLINK("#'E M DR PAULA BUARQUE'!A1",'E M DR PAULA BUARQUE'!B2) | C38: 0 | D38: 0 | E38: 0 | F38: 0 | G38: 0 | H38: 0 | I38: 0 | J38: 0 | K38: 0 | L38: 0 | M38: 0 | N38: 0 | O38: 0 | P38: 0 | Q38: 0 | R38: 0 | S38: 0 | T38: 0 | U38: 0
A39: ='E M DR THEODORO MACHADO'!B5 | B39: =HYPERLINK("#'E M DR THEODORO MACHADO'!A1",'E M DR THEODORO MACHADO'!B2) | C39: 0 | D39: 0 | E39: 0 | F39: 0 | G39: 0 | H39: 0 | I39: 0 | J39: 0 | K39: 0 | L39: 0 | M39: 0 | N39: 0 | O39: 0 | P39: 0 | Q39: 0 | R39: 0 | S39: 0 | T39: 0 | U39: 0
A40: ='E M ARNALDO DYCKERHOFF'!B5 | B40: =HYPERLINK("#'E M ARNALDO DYCKERHOFF'!A1",'E M ARNALDO DYCKERHOFF'!B2) | C40: 0 | D40: 0 | E40: 0 | F40: 0 | G40: 0 | H40: 0 | I40: 0 | J40: 0 | K40: 0 | L40: 0 | M40: 0 | N40: 0 | O40: 0 | P40: 0 | Q40: 0 | R40: 0 | S40: 0 | T40: 0 | U40: 0
A41: ='E M CARLOS CANEDO'!B5 | B41: =HYPERLINK("#'E M CARLOS CANEDO'!A1",'E M CARLOS CANEDO'!B2) | C41: 0 | D41: 0 | E41: 0 | F41: 0 | G41: 0 | H41: 0 | I41: 0 | J41: 0 | K41: 0 | L41: 0 | M41: 0 | N41: 0 | O41: 0 | P41: 0 | Q41: 0 | R41: 0 | S41: 0 | T41: 0 | U41: 0
...

Sheet RESUMO
A1: RESUMO GERAL | H1: =HYPERLINK("#'ÍNDICE'!A1","◄ Voltar ao Índice")
A3: 🏫 ESCOLAS — PEDIDO × DEVOLUÇÃO × VALOR A COBRAR DA PREFEITURA
A4: PRODUTO | B4: PEDIDO (kg) | C4: DEVOLUÇÃO (kg) | D4: LÍQUIDO (kg) | E4: VALOR (R$/kg) | F4: VALOR A COBRAR (R$)
A5: ='Entrada de Dados'!C5 | B5: ='Entrada de Dados'!C197 | C5: ='E M ROTARY'!C9+'E M DE EDUCAÇÃO ESPECIAL SANTOS'!C9+'LICEU MUN PREFEITO CORDOLINO AM'!C9+'E M PREFEITO JAMIL SABRÁ'!C9+'LICEU MUNICIPAL CARLOS CHAGAS F'!C9+'E M PAULO FREIRE'!C9+'E M PROFª MARIA CAMPOS DA SILVA'!C9+'CASA DA EDUCAÇÃO VISCONDE DE MA'!C9+'CENTRO DE REFERÊNCIA EM EDUCAÇÃ'!C9+'ESCOLA SANTA LUIZA DE MARILLAC'!C9+'ESCOLA DOMÉSTICA NOSSA SENHORA '!C9+'ESCOLA MONSENHOR GENTIL'!C9+'ESCOLA PAROQUIAL NOSSA SENHORA '!C9+'ESCOLA PAROQUIAL SÃO PEDRO DE A'!C9+'CEI TERRA SANTA'!C9+'CEI PRIMEIRA INFÂNCIA'!C9+'CEI PROFª PATRÍCIA FERREIRA E S'!C9+'CEI DRA ZILDA ARNS NEUMANN'!C9+'CENTRO DE EDUCAÇÃO INFANTIL PRO'!C9+'CEI MONSENHOR PAULO ELIAS DAHER'!C9+'COLÉGIO GUNNAR VINGREN DE PETRÓ'!C9+'EDUCANDÁRIO TERRA SANTA'!C9+'CEI LIONS CLUBE DE PETRÓPOLIS'!C9+'ESCOLA PAROQUIAL NOSSA SENHO 2'!C9+'CENTRO DE EDUCAÇÃO INFANTIL IRM'!C9+'E M LUIZ CARLOS SOARES'!C9+'ESCOLA GERMANO VALENTE'!C9+'ESCOLA PAROQUIAL NOSSA SENHO 3'!C9+'CEI JORGE ROLANDO DA SILVA'!C9+'E M CLEMENTE FERNANDES'!C9+'E M GERALDO VENTURA DIAS'!C9+'ESCOLA DAS COMUNIDADES SANTO AN'!C9+'CEI PROFª ROSANGELA DA SILVA LE'!C9+'CEI DEISE ELOY GOMES'!C9+'CEI PROFª SONIA REGINA SCUDESE '!C9+'CEI TIA ALICE'!C9+'E M BATAILLARD'!C9+'E M SOROPTIMISTA'!C9+'E M SALVADOR KLING'!C9+'ESCOLA MUNICIPALIZADA FREI ANIC'!C9+'ESCOLA SÃO JUDAS TADEU'!C9+'CEI PEDRAS BRANCAS'!C9+'CEI MARIA THEREZA KLING DO VALL'!C9+'CEI DONA ESPERANZA DE BOURBON D'!C9+'CEI GIUSEPPE-NEVA VOLONTERIO'!C9+'CENTRO DE EDUCAÇÃO INFANTIL SÃO'!C9+'E M LEONARDO BOFF'!C9+'ESCOLA MUNICIPAL GENERAL HEITOR'!C9+'E M JOHANN NOEL'!C9+'ESCOLA SANTA MARIA GORETTI'!C9+'ESCOLA SANTA RITA DE CASSIA'!C9+'ESCOLA SÃO JOÃO BATISTA'!C9+'CEI CASA DA SOLIDARIEDADE DE NO'!C9+'CEI A SEMENTEIRA'!C9+'CEI VILA SAO JOSE'!C9+'E M DR RUBENS DE CASTRO BOMTEMP'!C9+'CEI FREI LEÃO'!C9+'CEI SÃO JOÃO BATISTA'!C9+'CEI JURACI PINTO DO AMARAL DE C'!C9+'E M PEDRO AMADO'!C9+'E M ABELARDO DE LAMARE'!C9+'ESCOLA MUNICIPAL SENADOR MARIO '!C9+'ESCOLA PAROQUIAL SÃO PIO X'!C9+'CEI SÃO CHARBEL'!C9+'E M ROSALINA NICOLAY'!C9+'CEI INÊS BELARMINO DE SOUZA'!C9+'E M PROFª MARIA DA GLÓRIA QUEIR'!C9+'CENTRO EDUCACIONAL COMUNIDADE S'!C9+'CEI ROMANO CANAVESE'!C9+'CEI CÉLIA LÔBO PAULO'!C9+'CEI PROFª DORA KILLER'!C9+'CEI ALTO INDEPENDÊNCIA'!C9+'ESCOLA MUNICIPAL ALTO INDEPENDÊ'!C9+'E M PAPA JOÃO PAULO II'!C9+'CEI ANDRÉ REBOUÇAS'!C9+'CEI PROFª HERMÍNIA MATHEUS'!C9+'ESCOLA MUNICIPAL MAJOR JÚLIO FR'!C9+'E M ALMIRANTE TAMANDARÉ'!C9+'ESCOLA PAROQUIAL CARLOS DEMIÁ'!C9+'CENTRO PAROQUIAL DE EDUCAÇÃO IN'!C9+'CEI IRMÃ SILVANA'!C9+'CEI OLÍVIA MACHADO DA COSTA NOG'!C9+'E M GOVERNADOR MARCELLO ALENCAR'!C9+'E M PROFESSOR FLÁVIO MACIEL'!C9+'E M PROFª JANDIRA PEIXOTO BORDI'!C9+'E M STEFAN ZWEIG'!C9+'ESCOLA PAROQUIAL BOM JESUS'!C9+'CEI MARLI SOARES FERREIRA NETTO'!C9+'CENTRO DE EDUCAÇÃO INFANTIL CHI'!C9+'CEI VILA IPANEMA'!C9+'E M ROBERT KENNEDY'!C9+'ESCOLA MUNICIPAL ANA MOHAMMAD'!C9+'ESCOLA SÃO CRISTÓVÃO'!C9+'CEI DÉA LÚCIA CORDEIRO'!C9+'CEI SAGRADA FAMÍLIA'!C9+'CEI SÃO JOSÉ DAS OBLATAS DE NAZ'!C9+'ESCOLA MUNICIPAL JORGE AMADO'!C9+'E M FÁBRICA DO SABER'!C9+'CIEP BRIZOLÃO 474 MAESTRO GUERR'!C9+'CENTRO DE ENSINO PROF DARCY RIB'!C9+'CEI ANDRÉ VANZAN'!C9+'CENTRO DE EDUCAÇÃO INFANTIL CAR'!C9+'CEI BOA VISTA'!C9+'ASSOCIAÇÃO DA CRECHE SÃO FRANCI'!C9+'ESCOLA MUNICIPAL PAULO SALDANHA'!C9+'ESCOLA MUNICIPAL LÚCIA DE ALMEI'!C9+'E M DOM MANOEL PEDRO DA CUNHA C'!C9+'ESCOLA SÃO GERALDO'!C9+'CEI LULU MONTEIRO DE CASTRO'!C9+'CEI CARANGOLA'!C9+'ASSOCIAÇÃO RECREAR'!C9+'CENTRO DE EDUCAÇÃO INFANTIL CAS'!C9+'E M ROSEMIRA DE OLIVEIRA CAVALC'!C9+'E MZDA CARMEM NUNES MARTINS'!C9+'CEI SÃO JOSÉ DO ITAMARATI'!C9+'E M DUQUE DE CAXIAS'!C9+'CENTRO DE EDUCAÇÃO INFANTIL 2'!C9+'E M ANTÔNIO LEITE GARCIA'!C9+'ESCOLA PAROQUIAL DA ALCOBAÇA'!C9+'CENTRO DE EDUCAÇÃO INFANTIL LOT'!C9+'ESCOLA PAROQUIAL DO LOTEAMENTO '!C9+'E M PROF JOAQUIM DEISTER'!C9+'E M MARIETA GONÇALVES'!C9+'ESCOLA MUNICIPAL ODETTE YOUNG M'!C9+'ESCOLA MUNICIPAL PROFESSOR JOSE'!C9+'E M HERCÍLIA HENRIQUES MORET'!C9+'COLEGIO VICENTINO PADRE CORRÊA'!C9+'CEI PROFª MARLUCE DE SOUZA PEST'!C9+'CEI IRINEU MARINHO'!C9+'CEI DAGMAR ROLANDO DE OLIVEIRA'!C9+'CEI NOSSA SENHORA DA GLÓRIA'!C9+'E M PROF NILTON COSTA PEREIRA D'!C9+'CENTRO DE EDUCAÇÃO INFANTIL SÉR'!C9+'CEI SANTO ANTÔNIO AGOSTINHO'!C9+'CEI OSWALDO CRUZ'!C9+'E M MAGDALENA TAGLIAFERRO'!C9+'ESCOLA SÃO JOSÉ DO CAETITU'!C9+'CRECHE-ESCOLA CASTELO SÃO MANOE'!C9+'CEI THEREZINHA DE JESUS LIMA'!C9+'ESCOLA MUNICIPAL PROFESSOR PAUL'!C9+'COLÉGIO ANGLICANO DE ARARAS'!C9+'ESCOLA PAROQUIAL SANTA BERNADET'!C9+'CEI VISTA ALEGRE'!C9+'CEI DENISE BESSA DE OLIVA MAYA'!C9+'CEI VIDEIRINHA'!C9+'E M AMÉRICO FERNANDES RIBEIRO'!C9+'ESCOLA MUNICIPAL AUGUSTO PUGNAL'!C9+'ESCOLA MUNICIPAL CELINA SCHECHN'!C9+'E M DARCY CORREA DA VEIGA'!C9+'E M DR PAULA BUARQUE'!C9+'LICEU SÃO JOSÉ DE ITAIPAVA'!C9+'CEI LUIZ MARCHIORI'!C9+'CENTRO DE EDUCAÇÃO INFANTIL AUG'!C9+'CEI PROFª ADRIANA CONSTÂNCIO TR'!C9+'E M AMÉLIA ANTUNES RABELLO'!C9+'CEI PREFEITO SÉRGIO FADEL'!C9+'E M DR THEODORO MACHADO'!C9+'ESCOLA SANTO ANTÔNIO'!C9+'E M TAQUARIL'!C9+'E M MONSENHOR JOÃO DE DEUS RODR'!C9+'CENTRO DE REFERÊNCIA EM EDUC 2'!C9+'CEI PROFª GRAÇA COSTA'!C9+'CEI VILA LEOPOLDINA'!C9+'CEI NILO PEÇANHA'!C9+'E MZDA SANTA TEREZINHA'!C9+'CEI CRIANÇA SANTA EDWIGES'!C9+'E M ARNALDO DYCKERHOFF'!C9+'E M CARLOS CANEDO'!C9+'E M BEATRIZ ZALESKI'!C9+'E M ANTÔNIO JOSÉ DE LIMA'!C9+'E M FELIX WAN ERVEN DE BARROS'!C9+'ESCOLA MUNICIPAL HILDEBRANDO DE'!C9+'E M OSWALDO DA COSTA FRIAS'!C9+'E MZDA AVELINO DE CARVALHO'!C9+'ESCOLA MUNICIPALIZADA MOYSÉS FU'!C9+'CEI ANGELA MARIA DA CONCEIÇÃO S'!C9+'CEI JOSÉ GONÇALVES DA MOTTA'!C9+'E M DR BARROS FRANCO'!C9+'E M MAJOR THEÓFILO DE CARVALHO'!C9+'E M JOÃO KOPKE'!C9+'CEI ASSOCIAÇÃO BENEFICENTE FAZE'!C9+'ESCOLA SAO FRANCISCO DE ASSIS'!C9+'CEI SÃO FRANCISCO ASSIS'!C9+'CEI ALDEIA DA CRIANCA'!C9+'ESCOLA MUNICIPAL ODETTE FONSECA'!C9+'CEI ANA CAROLINA TELLES'!C9+'E M SEBASTIÃO LACERDA'!C9+'E M DOM PEDRO DE ALCÂNTARA'!C9+'ESCOLA NOSSA SENHORA DE FÁTIMA'!C9+'ESCOLA PAROQUIAL SÃO FRANCISCO '!C9+'E M MONSENHOR CIRILLO CALAON'!C9 | D5: =B5-C5 | E5: ='Entrada de Dados'!C2 | F5: =D5*E5
A6: ='Entrada de Dados'!D5 | B6: ='Entrada de Dados'!D197 | C6: ='E M ROTARY'!C10+'E M DE EDUCAÇÃO ESPECIAL SANTOS'!C10+'LICEU MUN PREFEITO CORDOLINO AM'!C10+'E M PREFEITO JAMIL SABRÁ'!C10+'LICEU MUNICIPAL CARLOS CHAGAS F'!C10+'E M PAULO FREIRE'!C10+'E M PROFª MARIA CAMPOS DA SILVA'!C10+'CASA DA EDUCAÇÃO VISCONDE DE MA'!C10+'CENTRO DE REFERÊNCIA EM EDUCAÇÃ'!C10+'ESCOLA SANTA LUIZA DE MARILLAC'!C10+'ESCOLA DOMÉSTICA NOSSA SENHORA '!C10+'ESCOLA MONSENHOR GENTIL'!C10+'ESCOLA PAROQUIAL NOSSA SENHORA '!C10+'ESCOLA PAROQUIAL SÃO PEDRO DE A'!C10+'CEI TERRA SANTA'!C10+'CEI PRIMEIRA INFÂNCIA'!C10+'CEI PROFª PATRÍCIA FERREIRA E S'!C10+'CEI DRA ZILDA ARNS NEUMANN'!C10+'CENTRO DE EDUCAÇÃO INFANTIL PRO'!C10+'CEI MONSENHOR PAULO ELIAS DAHER'!C10+'COLÉGIO GUNNAR VINGREN DE PETRÓ'!C10+'EDUCANDÁRIO TERRA SANTA'!C10+'CEI LIONS CLUBE DE PETRÓPOLIS'!C10+'ESCOLA PAROQUIAL NOSSA SENHO 2'!C10+'CENTRO DE EDUCAÇÃO INFANTIL IRM'!C10+'E M LUIZ CARLOS SOARES'!C10+'ESCOLA GERMANO VALENTE'!C10+'ESCOLA PAROQUIAL NOSSA SENHO 3'!C10+'CEI JORGE ROLANDO DA SILVA'!C10+'E M CLEMENTE FERNANDES'!C10+'E M GERALDO VENTURA DIAS'!C10+'ESCOLA DAS COMUNIDADES SANTO AN'!C10+'CEI PROFª ROSANGELA DA SILVA LE'!C10+'CEI DEISE ELOY GOMES'!C10+'CEI PROFª SONIA REGINA SCUDESE '!C10+'CEI TIA ALICE'!C10+'E M BATAILLARD'!C10+'E M SOROPTIMISTA'!C10+'E M SALVADOR KLING'!C10+'ESCOLA MUNICIPALIZADA FREI ANIC'!C10+'ESCOLA SÃO JUDAS TADEU'!C10+'CEI PEDRAS BRANCAS'!C10+'CEI MARIA THEREZA KLING DO VALL'!C10+'CEI DONA ESPERANZA DE BOURBON D'!C10+'CEI GIUSEPPE-NEVA VOLONTERIO'!C10+'CENTRO DE EDUCAÇÃO INFANTIL SÃO'!C10+'E M LEONARDO BOFF'!C10+'ESCOLA MUNICIPAL GENERAL HEITOR'!C10+'E M JOHANN NOEL'!C10+'ESCOLA SANTA MARIA GORETTI'!C10+'ESCOLA SANTA RITA DE CASSIA'!C10+'ESCOLA SÃO JOÃO BATISTA'!C10+'CEI CASA DA SOLIDARIEDADE DE NO'!C10+'CEI A SEMENTEIRA'!C10+'CEI VILA SAO JOSE'!C10+'E M DR RUBENS DE CASTRO BOMTEMP'!C10+'CEI FREI LEÃO'!C10+'CEI SÃO JOÃO BATISTA'!C10+'CEI JURACI PINTO DO AMARAL DE C'!C10+'E M PEDRO AMADO'!C10+'E M ABELARDO DE LAMARE'!C10+'ESCOLA MUNICIPAL SENADOR MARIO '!C10+'ESCOLA PAROQUIAL SÃO PIO X'!C10+'CEI SÃO CHARBEL'!C10+'E M ROSALINA NICOLAY'!C10+'CEI INÊS BELARMINO DE SOUZA'!C10+'E M PROFª MARIA DA GLÓRIA QUEIR'!C10+'CENTRO EDUCACIONAL COMUNIDADE S'!C10+'CEI ROMANO CANAVESE'!C10+'CEI CÉLIA LÔBO PAULO'!C10+'CEI PROFª DORA KILLER'!C10+'CEI ALTO INDEPENDÊNCIA'!C10+'ESCOLA MUNICIPAL ALTO INDEPENDÊ'!C10+'E M PAPA JOÃO PAULO II'!C10+'CEI ANDRÉ REBOUÇAS'!C10+'CEI PROFª HERMÍNIA MATHEUS'!C10+'ESCOLA MUNICIPAL MAJOR JÚLIO FR'!C10+'E M ALMIRANTE TAMANDARÉ'!C10+'ESCOLA PAROQUIAL CARLOS DEMIÁ'!C10+'CENTRO PAROQUIAL DE EDUCAÇÃO IN'!C10+'CEI IRMÃ SILVANA'!C10+'CEI OLÍVIA MACHADO DA COSTA NOG'!C10+'E M GOVERNADOR MARCELLO ALENCAR'!C10+'E M PROFESSOR FLÁVIO MACIEL'!C10+'E M PROFª JANDIRA PEIXOTO BORDI'!C10+'E M STEFAN ZWEIG'!C10+'ESCOLA PAROQUIAL BOM JESUS'!C10+'CEI MARLI SOARES FERREIRA NETTO'!C10+'CENTRO DE EDUCAÇÃO INFANTIL CHI'!C10+'CEI VILA IPANEMA'!C10+'E M ROBERT KENNEDY'!C10+'ESCOLA MUNICIPAL ANA MOHAMMAD'!C10+'ESCOLA SÃO CRISTÓVÃO'!C10+'CEI DÉA LÚCIA CORDEIRO'!C10+'CEI SAGRADA FAMÍLIA'!C10+'CEI SÃO JOSÉ DAS OBLATAS DE NAZ'!C10+'ESCOLA MUNICIPAL JORGE AMADO'!C10+'E M FÁBRICA DO SABER'!C10+'CIEP BRIZOLÃO 474 MAESTRO GUERR'!C10+'CENTRO DE ENSINO PROF DARCY RIB'!C10+'CEI ANDRÉ VANZAN'!C10+'CENTRO DE EDUCAÇÃO INFANTIL CAR'!C10+'CEI BOA VISTA'!C10+'ASSOCIAÇÃO DA CRECHE SÃO FRANCI'!C10+'ESCOLA MUNICIPAL PAULO SALDANHA'!C10+'ESCOLA MUNICIPAL LÚCIA DE ALMEI'!C10+'E M DOM MANOEL PEDRO DA CUNHA C'!C10+'ESCOLA SÃO GERALDO'!C10+'CEI LULU MONTEIRO DE CASTRO'!C10+'CEI CARANGOLA'!C10+'ASSOCIAÇÃO RECREAR'!C10+'CENTRO DE EDUCAÇÃO INFANTIL CAS'!C10+'E M ROSEMIRA DE OLIVEIRA CAVALC'!C10+'E MZDA CARMEM NUNES MARTINS'!C10+'CEI SÃO JOSÉ DO ITAMARATI'!C10+'E M DUQUE DE CAXIAS'!C10+'CENTRO DE EDUCAÇÃO INFANTIL 2'!C10+'E M ANTÔNIO LEITE GARCIA'!C10+'ESCOLA PAROQUIAL DA ALCOBAÇA'!C10+'CENTRO DE EDUCAÇÃO INFANTIL LOT'!C10+'ESCOLA PAROQUIAL DO LOTEAMENTO '!C10+'E M PROF JOAQUIM DEISTER'!C10+'E M MARIETA GONÇALVES'!C10+'ESCOLA MUNICIPAL ODETTE YOUNG M'!C10+'ESCOLA MUNICIPAL PROFESSOR JOSE'!C10+'E M HERCÍLIA HENRIQUES MORET'!C10+'COLEGIO VICENTINO PADRE CORRÊA'!C10+'CEI PROFª MARLUCE DE SOUZA PEST'!C10+'CEI IRINEU MARINHO'!C10+'CEI DAGMAR ROLANDO DE OLIVEIRA'!C10+'CEI NOSSA SENHORA DA GLÓRIA'!C10+'E M PROF NILTON COSTA PEREIRA D'!C10+'CENTRO DE EDUCAÇÃO INFANTIL SÉR'!C10+'CEI SANTO ANTÔNIO AGOSTINHO'!C10+'CEI OSWALDO CRUZ'!C10+'E M MAGDALENA TAGLIAFERRO'!C10+'ESCOLA SÃO JOSÉ DO CAETITU'!C10+'CRECHE-ESCOLA CASTELO SÃO MANOE'!C10+'CEI THEREZINHA DE JESUS LIMA'!C10+'ESCOLA MUNICIPAL PROFESSOR PAUL'!C10+'COLÉGIO ANGLICANO DE ARARAS'!C10+'ESCOLA PAROQUIAL SANTA BERNADET'!C10+'CEI VISTA ALEGRE'!C10+'CEI DENISE BESSA DE OLIVA MAYA'!C10+'CEI VIDEIRINHA'!C10+'E M AMÉRICO FERNANDES RIBEIRO'!C10+'ESCOLA MUNICIPAL AUGUSTO PUGNAL'!C10+'ESCOLA MUNICIPAL CELINA SCHECHN'!C10+'E M DARCY CORREA DA VEIGA'!C10+'E M DR PAULA BUARQUE'!C10+'LICEU SÃO JOSÉ DE ITAIPAVA'!C10+'CEI LUIZ MARCHIORI'!C10+'CENTRO DE EDUCAÇÃO INFANTIL AUG'!C10+'CEI PROFª ADRIANA CONSTÂNCIO TR'!C10+'E M AMÉLIA ANTUNES RABELLO'!C10+'CEI PREFEITO SÉRGIO FADEL'!C10+'E M DR THEODORO MACHADO'!C10+'ESCOLA SANTO ANTÔNIO'!C10+'E M TAQUARIL'!C10+'E M MONSENHOR JOÃO DE DEUS RODR'!C10+'CENTRO DE REFERÊNCIA EM EDUC 2'!C10+'CEI PROFª GRAÇA COSTA'!C10+'CEI VILA LEOPOLDINA'!C10+'CEI NILO PEÇANHA'!C10+'E MZDA SANTA TEREZINHA'!C10+'CEI CRIANÇA SANTA EDWIGES'!C10+'E M ARNALDO DYCKERHOFF'!C10+'E M CARLOS CANEDO'!C10+'E M BEATRIZ ZALESKI'!C10+'E M ANTÔNIO JOSÉ DE LIMA'!C10+'E M FELIX WAN ERVEN DE BARROS'!C10+'ESCOLA MUNICIPAL HILDEBRANDO DE'!C10+'E M OSWALDO DA COSTA FRIAS'!C10+'E MZDA AVELINO DE CARVALHO'!C10+'ESCOLA MUNICIPALIZADA MOYSÉS FU'!C10+'CEI ANGELA MARIA DA CONCEIÇÃO S'!C10+'CEI JOSÉ GONÇALVES DA MOTTA'!C10+'E M DR BARROS FRANCO'!C10+'E M MAJOR THEÓFILO DE CARVALHO'!C10+'E M JOÃO KOPKE'!C10+'CEI ASSOCIAÇÃO BENEFICENTE FAZE'!C10+'ESCOLA SAO FRANCISCO DE ASSIS'!C10+'CEI SÃO FRANCISCO ASSIS'!C10+'CEI ALDEIA DA CRIANCA'!C10+'ESCOLA MUNICIPAL ODETTE FONSECA'!C10+'CEI ANA CAROLINA TELLES'!C10+'E M SEBASTIÃO LACERDA'!C10+'E M DOM PEDRO DE ALCÂNTARA'!C10+'ESCOLA NOSSA SENHORA DE FÁTIMA'!C10+'ESCOLA PAROQUIAL SÃO FRANCISCO '!C10+'E M MONSENHOR CIRILLO CALAON'!C10 | D6: =B6-C6 | E6: ='Entrada de Dados'!D2 | F6: =D6*E6
A7: ='Entrada de Dados'!E5 | B7: ='Entrada de Dados'!E197 | C7: ='E M ROTARY'!C11+'E M DE EDUCAÇÃO ESPECIAL SANTOS'!C11+'LICEU MUN PREFEITO CORDOLINO AM'!C11+'E M PREFEITO JAMIL SABRÁ'!C11+'LICEU MUNICIPAL CARLOS CHAGAS F'!C11+'E M PAULO FREIRE'!C11+'E M PROFª MARIA CAMPOS DA SILVA'!C11+'CASA DA EDUCAÇÃO VISCONDE DE MA'!C11+'CENTRO DE REFERÊNCIA EM EDUCAÇÃ'!C11+'ESCOLA SANTA LUIZA DE MARILLAC'!C11+'ESCOLA DOMÉSTICA NOSSA SENHORA '!C11+'ESCOLA MONSENHOR GENTIL'!C11+'ESCOLA PAROQUIAL NOSSA SENHORA '!C11+'ESCOLA PAROQUIAL SÃO PEDRO DE A'!C11+'CEI TERRA SANTA'!C11+'CEI PRIMEIRA INFÂNCIA'!C11+'CEI PROFª PATRÍCIA FERREIRA E S'!C11+'CEI DRA ZILDA ARNS NEUMANN'!C11+'CENTRO DE EDUCAÇÃO INFANTIL PRO'!C11+'CEI MONSENHOR PAULO ELIAS DAHER'!C11+'COLÉGIO GUNNAR VINGREN DE PETRÓ'!C11+'EDUCANDÁRIO TERRA SANTA'!C11+'CEI LIONS CLUBE DE PETRÓPOLIS'!C11+'ESCOLA PAROQUIAL NOSSA SENHO 2'!C11+'CENTRO DE EDUCAÇÃO INFANTIL IRM'!C11+'E M LUIZ CARLOS SOARES'!C11+'ESCOLA GERMANO VALENTE'!C11+'ESCOLA PAROQUIAL NOSSA SENHO 3'!C11+'CEI JORGE ROLANDO DA SILVA'!C11+'E M CLEMENTE FERNANDES'!C11+'E M GERALDO VENTURA DIAS'!C11+'ESCOLA DAS COMUNIDADES SANTO AN'!C11+'CEI PROFª ROSANGELA DA SILVA LE'!C11+'CEI DEISE ELOY GOMES'!C11+'CEI PROFª SONIA REGINA SCUDESE '!C11+'CEI TIA ALICE'!C11+'E M BATAILLARD'!C11+'E M SOROPTIMISTA'!C11+'E M SALVADOR KLING'!C11+'ESCOLA MUNICIPALIZADA FREI ANIC'!C11+'ESCOLA SÃO JUDAS TADEU'!C11+'CEI PEDRAS BRANCAS'!C11+'CEI MARIA THEREZA KLING DO VALL'!C11+'CEI DONA ESPERANZA DE BOURBON D'!C11+'CEI GIUSEPPE-NEVA VOLONTERIO'!C11+'CENTRO DE EDUCAÇÃO INFANTIL SÃO'!C11+'E M LEONARDO BOFF'!C11+'ESCOLA MUNICIPAL GENERAL HEITOR'!C11+'E M JOHANN NOEL'!C11+'ESCOLA SANTA MARIA GORETTI'!C11+'ESCOLA SANTA RITA DE CASSIA'!C11+'ESCOLA SÃO JOÃO BATISTA'!C11+'CEI CASA DA SOLIDARIEDADE DE NO'!C11+'CEI A SEMENTEIRA'!C11+'CEI VILA SAO JOSE'!C11+'E M DR RUBENS DE CASTRO BOMTEMP'!C11+'CEI FREI LEÃO'!C11+'CEI SÃO JOÃO BATISTA'!C11+'CEI JURACI PINTO DO AMARAL DE C'!C11+'E M PEDRO AMADO'!C11+'E M ABELARDO DE LAMARE'!C11+'ESCOLA MUNICIPAL SENADOR MARIO '!C11+'ESCOLA PAROQUIAL SÃO PIO X'!C11+'CEI SÃO CHARBEL'!C11+'E M ROSALINA NICOLAY'!C11+'CEI INÊS BELARMINO DE SOUZA'!C11+'E M PROFª MARIA DA GLÓRIA QUEIR'!C11+'CENTRO EDUCACIONAL COMUNIDADE S'!C11+'CEI ROMANO CANAVESE'!C11+'CEI CÉLIA LÔBO PAULO'!C11+'CEI PROFª DORA KILLER'!C11+'CEI ALTO INDEPENDÊNCIA'!C11+'ESCOLA MUNICIPAL ALTO INDEPENDÊ'!C11+'E M PAPA JOÃO PAULO II'!C11+'CEI ANDRÉ REBOUÇAS'!C11+'CEI PROFª HERMÍNIA MATHEUS'!C11+'ESCOLA MUNICIPAL MAJOR JÚLIO FR'!C11+'E M ALMIRANTE TAMANDARÉ'!C11+'ESCOLA PAROQUIAL CARLOS DEMIÁ'!C11+'CENTRO PAROQUIAL DE EDUCAÇÃO IN'!C11+'CEI IRMÃ SILVANA'!C11+'CEI OLÍVIA MACHADO DA COSTA NOG'!C11+'E M GOVERNADOR MARCELLO ALENCAR'!C11+'E M PROFESSOR FLÁVIO MACIEL'!C11+'E M PROFª JANDIRA PEIXOTO BORDI'!C11+'E M STEFAN ZWEIG'!C11+'ESCOLA PAROQUIAL BOM JESUS'!C11+'CEI MARLI SOARES FERREIRA NETTO'!C11+'CENTRO DE EDUCAÇÃO INFANTIL CHI'!C11+'CEI VILA IPANEMA'!C11+'E M ROBERT KENNEDY'!C11+'ESCOLA MUNICIPAL ANA MOHAMMAD'!C11+'ESCOLA SÃO CRISTÓVÃO'!C11+'CEI DÉA LÚCIA CORDEIRO'!C11+'CEI SAGRADA FAMÍLIA'!C11+'CEI SÃO JOSÉ DAS OBLATAS DE NAZ'!C11+'ESCOLA MUNICIPAL JORGE AMADO'!C11+'E M FÁBRICA DO SABER'!C11+'CIEP BRIZOLÃO 474 MAESTRO GUERR'!C11+'CENTRO DE ENSINO PROF DARCY RIB'!C11+'CEI ANDRÉ VANZAN'!C11+'CENTRO DE EDUCAÇÃO INFANTIL CAR'!C11+'CEI BOA VISTA'!C11+'ASSOCIAÇÃO DA CRECHE SÃO FRANCI'!C11+'ESCOLA MUNICIPAL PAULO SALDANHA'!C11+'ESCOLA MUNICIPAL LÚCIA DE ALMEI'!C11+'E M DOM MANOEL PEDRO DA CUNHA C'!C11+'ESCOLA SÃO GERALDO'!C11+'CEI LULU MONTEIRO DE CASTRO'!C11+'CEI CARANGOLA'!C11+'ASSOCIAÇÃO RECREAR'!C11+'CENTRO DE EDUCAÇÃO INFANTIL CAS'!C11+'E M ROSEMIRA DE OLIVEIRA CAVALC'!C11+'E MZDA CARMEM NUNES MARTINS'!C11+'CEI SÃO JOSÉ DO ITAMARATI'!C11+'E M DUQUE DE CAXIAS'!C11+'CENTRO DE EDUCAÇÃO INFANTIL 2'!C11+'E M ANTÔNIO LEITE GARCIA'!C11+'ESCOLA PAROQUIAL DA ALCOBAÇA'!C11+'CENTRO DE EDUCAÇÃO INFANTIL LOT'!C11+'ESCOLA PAROQUIAL DO LOTEAMENTO '!C11+'E M PROF JOAQUIM DEISTER'!C11+'E M MARIETA GONÇALVES'!C11+'ESCOLA MUNICIPAL ODETTE YOUNG M'!C11+'ESCOLA MUNICIPAL PROFESSOR JOSE'!C11+'E M HERCÍLIA HENRIQUES MORET'!C11+'COLEGIO VICENTINO PADRE CORRÊA'!C11+'CEI PROFª MARLUCE DE SOUZA PEST'!C11+'CEI IRINEU MARINHO'!C11+'CEI DAGMAR ROLANDO DE OLIVEIRA'!C11+'CEI NOSSA SENHORA DA GLÓRIA'!C11+'E M PROF NILTON COSTA PEREIRA D'!C11+'CENTRO DE EDUCAÇÃO INFANTIL SÉR'!C11+'CEI SANTO ANTÔNIO AGOSTINHO'!C11+'CEI OSWALDO CRUZ'!C11+'E M MAGDALENA TAGLIAFERRO'!C11+'ESCOLA SÃO JOSÉ DO CAETITU'!C11+'CRECHE-ESCOLA CASTELO SÃO MANOE'!C11+'CEI THEREZINHA DE JESUS LIMA'!C11+'ESCOLA MUNICIPAL PROFESSOR PAUL'!C11+'COLÉGIO ANGLICANO DE ARARAS'!C11+'ESCOLA PAROQUIAL SANTA BERNADET'!C11+'CEI VISTA ALEGRE'!C11+'CEI DENISE BESSA DE OLIVA MAYA'!C11+'CEI VIDEIRINHA'!C11+'E M AMÉRICO FERNANDES RIBEIRO'!C11+'ESCOLA MUNICIPAL AUGUSTO PUGNAL'!C11+'ESCOLA MUNICIPAL CELINA SCHECHN'!C11+'E M DARCY CORREA DA VEIGA'!C11+'E M DR PAULA BUARQUE'!C11+'LICEU SÃO JOSÉ DE ITAIPAVA'!C11+'CEI LUIZ MARCHIORI'!C11+'CENTRO DE EDUCAÇÃO INFANTIL AUG'!C11+'CEI PROFª ADRIANA CONSTÂNCIO TR'!C11+'E M AMÉLIA ANTUNES RABELLO'!C11+'CEI PREFEITO SÉRGIO FADEL'!C11+'E M DR THEODORO MACHADO'!C11+'ESCOLA SANTO ANTÔNIO'!C11+'E M TAQUARIL'!C11+'E M MONSENHOR JOÃO DE DEUS RODR'!C11+'CENTRO DE REFERÊNCIA EM EDUC 2'!C11+'CEI PROFª GRAÇA COSTA'!C11+'CEI VILA LEOPOLDINA'!C11+'CEI NILO PEÇANHA'!C11+'E MZDA SANTA TEREZINHA'!C11+'CEI CRIANÇA SANTA EDWIGES'!C11+'E M ARNALDO DYCKERHOFF'!C11+'E M CARLOS CANEDO'!C11+'E M BEATRIZ ZALESKI'!C11+'E M ANTÔNIO JOSÉ DE LIMA'!C11+'E M FELIX WAN ERVEN DE BARROS'!C11+'ESCOLA MUNICIPAL HILDEBRANDO DE'!C11+'E M OSWALDO DA COSTA FRIAS'!C11+'E MZDA AVELINO DE CARVALHO'!C11+'ESCOLA MUNICIPALIZADA MOYSÉS FU'!C11+'CEI ANGELA MARIA DA CONCEIÇÃO S'!C11+'CEI JOSÉ GONÇALVES DA MOTTA'!C11+'E M DR BARROS FRANCO'!C11+'E M MAJOR THEÓFILO DE CARVALHO'!C11+'E M JOÃO KOPKE'!C11+'CEI ASSOCIAÇÃO BENEFICENTE FAZE'!C11+'ESCOLA SAO FRANCISCO DE ASSIS'!C11+'CEI SÃO FRANCISCO ASSIS'!C11+'CEI ALDEIA DA CRIANCA'!C11+'ESCOLA MUNICIPAL ODETTE FONSECA'!C11+'CEI ANA CAROLINA TELLES'!C11+'E M SEBASTIÃO LACERDA'!C11+'E M DOM PEDRO DE ALCÂNTARA'!C11+'ESCOLA NOSSA SENHORA DE FÁTIMA'!C11+'ESCOLA PAROQUIAL SÃO FRANCISCO '!C11+'E M MONSENHOR CIRILLO CALAON'!C11 | D7: =B7-C7 | E7: ='Entrada de Dados'!E2 | F7: =D7*E7
A8: ='Entrada de Dados'!F5 | B8: ='Entrada de Dados'!F197 | C8: ='E M ROTARY'!C12+'E M DE EDUCAÇÃO ESPECIAL SANTOS'!C12+'LICEU MUN PREFEITO CORDOLINO AM'!C12+'E M PREFEITO JAMIL SABRÁ'!C12+'LICEU MUNICIPAL CARLOS CHAGAS F'!C12+'E M PAULO FREIRE'!C12+'E M PROFª MARIA CAMPOS DA SILVA'!C12+'CASA DA EDUCAÇÃO VISCONDE DE MA'!C12+'CENTRO DE REFERÊNCIA EM EDUCAÇÃ'!C12+'ESCOLA SANTA LUIZA DE MARILLAC'!C12+'ESCOLA DOMÉSTICA NOSSA SENHORA '!C12+'ESCOLA MONSENHOR GENTIL'!C12+'ESCOLA PAROQUIAL NOSSA SENHORA '!C12+'ESCOLA PAROQUIAL SÃO PEDRO DE A'!C12+'CEI TERRA SANTA'!C12+'CEI PRIMEIRA INFÂNCIA'!C12+'CEI PROFª PATRÍCIA FERREIRA E S'!C12+'CEI DRA ZILDA ARNS NEUMANN'!C12+'CENTRO DE EDUCAÇÃO INFANTIL PRO'!C12+'CEI MONSENHOR PAULO ELIAS DAHER'!C12+'COLÉGIO GUNNAR VINGREN DE PETRÓ'!C12+'EDUCANDÁRIO TERRA SANTA'!C12+'CEI LIONS CLUBE DE PETRÓPOLIS'!C12+'ESCOLA PAROQUIAL NOSSA SENHO 2'!C12+'CENTRO DE EDUCAÇÃO INFANTIL IRM'!C12+'E M LUIZ CARLOS SOARES'!C12+'ESCOLA GERMANO VALENTE'!C12+'ESCOLA PAROQUIAL NOSSA SENHO 3'!C12+'CEI JORGE ROLANDO DA SILVA'!C12+'E M CLEMENTE FERNANDES'!C12+'E M GERALDO VENTURA DIAS'!C12+'ESCOLA DAS COMUNIDADES SANTO AN'!C12+'CEI PROFª ROSANGELA DA SILVA LE'!C12+'CEI DEISE ELOY GOMES'!C12+'CEI PROFª SONIA REGINA SCUDESE '!C12+'CEI TIA ALICE'!C12+'E M BATAILLARD'!C12+'E M SOROPTIMISTA'!C12+'E M SALVADOR KLING'!C12+'ESCOLA MUNICIPALIZADA FREI ANIC'!C12+'ESCOLA SÃO JUDAS TADEU'!C12+'CEI PEDRAS BRANCAS'!C12+'CEI MARIA THEREZA KLING DO VALL'!C12+'CEI DONA ESPERANZA DE BOURBON D'!C12+'CEI GIUSEPPE-NEVA VOLONTERIO'!C12+'CENTRO DE EDUCAÇÃO INFANTIL SÃO'!C12+'E M LEONARDO BOFF'!C12+'ESCOLA MUNICIPAL GENERAL HEITOR'!C12+'E M JOHANN NOEL'!C12+'ESCOLA SANTA MARIA GORETTI'!C12+'ESCOLA SANTA RITA DE CASSIA'!C12+'ESCOLA SÃO JOÃO BATISTA'!C12+'CEI CASA DA SOLIDARIEDADE DE NO'!C12+'CEI A SEMENTEIRA'!C12+'CEI VILA SAO JOSE'!C12+'E M DR RUBENS DE CASTRO BOMTEMP'!C12+'CEI FREI LEÃO'!C12+'CEI SÃO JOÃO BATISTA'!C12+'CEI JURACI PINTO DO AMARAL DE C'!C12+'E M PEDRO AMADO'!C12+'E M ABELARDO DE LAMARE'!C12+'ESCOLA MUNICIPAL SENADOR MARIO '!C12+'ESCOLA PAROQUIAL SÃO PIO X'!C12+'CEI SÃO CHARBEL'!C12+'E M ROSALINA NICOLAY'!C12+'CEI INÊS BELARMINO DE SOUZA'!C12+'E M PROFª MARIA DA GLÓRIA QUEIR'!C12+'CENTRO EDUCACIONAL COMUNIDADE S'!C12+'CEI ROMANO CANAVESE'!C12+'CEI CÉLIA LÔBO PAULO'!C12+'CEI PROFª DORA KILLER'!C12+'CEI ALTO INDEPENDÊNCIA'!C12+'ESCOLA MUNICIPAL ALTO INDEPENDÊ'!C12+'E M PAPA JOÃO PAULO II'!C12+'CEI ANDRÉ REBOUÇAS'!C12+'CEI PROFª HERMÍNIA MATHEUS'!C12+'ESCOLA MUNICIPAL MAJOR JÚLIO FR'!C12+'E M ALMIRANTE TAMANDARÉ'!C12+'ESCOLA PAROQUIAL CARLOS DEMIÁ'!C12+'CENTRO PAROQUIAL DE EDUCAÇÃO IN'!C12+'CEI IRMÃ SILVANA'!C12+'CEI OLÍVIA MACHADO DA COSTA NOG'!C12+'E M GOVERNADOR MARCELLO ALENCAR'!C12+'E M PROFESSOR FLÁVIO MACIEL'!C12+'E M PROFª JANDIRA PEIXOTO BORDI'!C12+'E M STEFAN ZWEIG'!C12+'ESCOLA PAROQUIAL BOM JESUS'!C12+'CEI MARLI SOARES FERREIRA NETTO'!C12+'CENTRO DE EDUCAÇÃO INFANTIL CHI'!C12+'CEI VILA IPANEMA'!C12+'E M ROBERT KENNEDY'!C12+'ESCOLA MUNICIPAL ANA MOHAMMAD'!C12+'ESCOLA SÃO CRISTÓVÃO'!C12+'CEI DÉA LÚCIA CORDEIRO'!C12+'CEI SAGRADA FAMÍLIA'!C12+'CEI SÃO JOSÉ DAS OBLATAS DE NAZ'!C12+'ESCOLA MUNICIPAL JORGE AMADO'!C12+'E M FÁBRICA DO SABER'!C12+'CIEP BRIZOLÃO 474 MAESTRO GUERR'!C12+'CENTRO DE ENSINO PROF DARCY RIB'!C12+'CEI ANDRÉ VANZAN'!C12+'CENTRO DE EDUCAÇÃO INFANTIL CAR'!C12+'CEI BOA VISTA'!C12+'ASSOCIAÇÃO DA CRECHE SÃO FRANCI'!C12+'ESCOLA MUNICIPAL PAULO SALDANHA'!C12+'ESCOLA MUNICIPAL LÚCIA DE ALMEI'!C12+'E M DOM MANOEL PEDRO DA CUNHA C'!C12+'ESCOLA SÃO GERALDO'!C12+'CEI LULU MONTEIRO DE CASTRO'!C12+'CEI CARANGOLA'!C12+'ASSOCIAÇÃO RECREAR'!C12+'CENTRO DE EDUCAÇÃO INFANTIL CAS'!C12+'E M ROSEMIRA DE OLIVEIRA CAVALC'!C12+'E MZDA CARMEM NUNES MARTINS'!C12+'CEI SÃO JOSÉ DO ITAMARATI'!C12+'E M DUQUE DE CAXIAS'!C12+'CENTRO DE EDUCAÇÃO INFANTIL 2'!C12+'E M ANTÔNIO LEITE GARCIA'!C12+'ESCOLA PAROQUIAL DA ALCOBAÇA'!C12+'CENTRO DE EDUCAÇÃO INFANTIL LOT'!C12+'ESCOLA PAROQUIAL DO LOTEAMENTO '!C12+'E M PROF JOAQUIM DEISTER'!C12+'E M MARIETA GONÇALVES'!C12+'ESCOLA MUNICIPAL ODETTE YOUNG M'!C12+'ESCOLA MUNICIPAL PROFESSOR JOSE'!C12+'E M HERCÍLIA HENRIQUES MORET'!C12+'COLEGIO VICENTINO PADRE CORRÊA'!C12+'CEI PROFª MARLUCE DE SOUZA PEST'!C12+'CEI IRINEU MARINHO'!C12+'CEI DAGMAR ROLANDO DE OLIVEIRA'!C12+'CEI NOSSA SENHORA DA GLÓRIA'!C12+'E M PROF NILTON COSTA PEREIRA D'!C12+'CENTRO DE EDUCAÇÃO INFANTIL SÉR'!C12+'CEI SANTO ANTÔNIO AGOSTINHO'!C12+'CEI OSWALDO CRUZ'!C12+'E M MAGDALENA TAGLIAFERRO'!C12+'ESCOLA SÃO JOSÉ DO CAETITU'!C12+'CRECHE-ESCOLA CASTELO SÃO MANOE'!C12+'CEI THEREZINHA DE JESUS LIMA'!C12+'ESCOLA MUNICIPAL PROFESSOR PAUL'!C12+'COLÉGIO ANGLICANO DE ARARAS'!C12+'ESCOLA PAROQUIAL SANTA BERNADET'!C12+'CEI VISTA ALEGRE'!C12+'CEI DENISE BESSA DE OLIVA MAYA'!C12+'CEI VIDEIRINHA'!C12+'E M AMÉRICO FERNANDES RIBEIRO'!C12+'ESCOLA MUNICIPAL AUGUSTO PUGNAL'!C12+'ESCOLA MUNICIPAL CELINA SCHECHN'!C12+'E M DARCY CORREA DA VEIGA'!C12+'E M DR PAULA BUARQUE'!C12+'LICEU SÃO JOSÉ DE ITAIPAVA'!C12+'CEI LUIZ MARCHIORI'!C12+'CENTRO DE EDUCAÇÃO INFANTIL AUG'!C12+'CEI PROFª ADRIANA CONSTÂNCIO TR'!C12+'E M AMÉLIA ANTUNES RABELLO'!C12+'CEI PREFEITO SÉRGIO FADEL'!C12+'E M DR THEODORO MACHADO'!C12+'ESCOLA SANTO ANTÔNIO'!C12+'E M TAQUARIL'!C12+'E M MONSENHOR JOÃO DE DEUS RODR'!C12+'CENTRO DE REFERÊNCIA EM EDUC 2'!C12+'CEI PROFª GRAÇA COSTA'!C12+'CEI VILA LEOPOLDINA'!C12+'CEI NILO PEÇANHA'!C12+'E MZDA SANTA TEREZINHA'!C12+'CEI CRIANÇA SANTA EDWIGES'!C12+'E M ARNALDO DYCKERHOFF'!C12+'E M CARLOS CANEDO'!C12+'E M BEATRIZ ZALESKI'!C12+'E M ANTÔNIO JOSÉ DE LIMA'!C12+'E M FELIX WAN ERVEN DE BARROS'!C12+'ESCOLA MUNICIPAL HILDEBRANDO DE'!C12+'E M OSWALDO DA COSTA FRIAS'!C12+'E MZDA AVELINO DE CARVALHO'!C12+'ESCOLA MUNICIPALIZADA MOYSÉS FU'!C12+'CEI ANGELA MARIA DA CONCEIÇÃO S'!C12+'CEI JOSÉ GONÇALVES DA MOTTA'!C12+'E M DR BARROS FRANCO'!C12+'E M MAJOR THEÓFILO DE CARVALHO'!C12+'E M JOÃO KOPKE'!C12+'CEI ASSOCIAÇÃO BENEFICENTE FAZE'!C12+'ESCOLA SAO FRANCISCO DE ASSIS'!C12+'CEI SÃO FRANCISCO ASSIS'!C12+'CEI ALDEIA DA CRIANCA'!C12+'ESCOLA MUNICIPAL ODETTE FONSECA'!C12+'CEI ANA CAROLINA TELLES'!C12+'E M SEBASTIÃO LACERDA'!C12+'E M DOM PEDRO DE ALCÂNTARA'!C12+'ESCOLA NOSSA SENHORA DE FÁTIMA'!C12+'ESCOLA PAROQUIAL SÃO FRANCISCO '!C12+'E M MONSENHOR CIRILLO CALAON'!C12 | D8: =B8-C8 | E8: ='Entrada de Dados'!F2 | F8: =D8*E8
A9: ='Entrada de Dados'!G5 | B9: ='Entrada de Dados'!G197 | C9: ='E M ROTARY'!C13+'E M DE EDUCAÇÃO ESPECIAL SANTOS'!C13+'LICEU MUN PREFEITO CORDOLINO AM'!C13+'E M PREFEITO JAMIL SABRÁ'!C13+'LICEU MUNICIPAL CARLOS CHAGAS F'!C13+'E M PAULO FREIRE'!C13+'E M PROFª MARIA CAMPOS DA SILVA'!C13+'CASA DA EDUCAÇÃO VISCONDE DE MA'!C13+'CENTRO DE REFERÊNCIA EM EDUCAÇÃ'!C13+'ESCOLA SANTA LUIZA DE MARILLAC'!C13+'ESCOLA DOMÉSTICA NOSSA SENHORA '!C13+'ESCOLA MONSENHOR GENTIL'!C13+'ESCOLA PAROQUIAL NOSSA SENHORA '!C13+'ESCOLA PAROQUIAL SÃO PEDRO DE A'!C13+'CEI TERRA SANTA'!C13+'CEI PRIMEIRA INFÂNCIA'!C13+'CEI PROFª PATRÍCIA FERREIRA E S'!C13+'CEI DRA ZILDA ARNS NEUMANN'!C13+'CENTRO DE EDUCAÇÃO INFANTIL PRO'!C13+'CEI MONSENHOR PAULO ELIAS DAHER'!C13+'COLÉGIO GUNNAR VINGREN DE PETRÓ'!C13+'EDUCANDÁRIO TERRA SANTA'!C13+'CEI LIONS CLUBE DE PETRÓPOLIS'!C13+'ESCOLA PAROQUIAL NOSSA SENHO 2'!C13+'CENTRO DE EDUCAÇÃO INFANTIL IRM'!C13+'E M LUIZ CARLOS SOARES'!C13+'ESCOLA GERMANO VALENTE'!C13+'ESCOLA PAROQUIAL NOSSA SENHO 3'!C13+'CEI JORGE ROLANDO DA SILVA'!C13+'E M CLEMENTE FERNANDES'!C13+'E M GERALDO VENTURA DIAS'!C13+'ESCOLA DAS COMUNIDADES SANTO AN'!C13+'CEI PROFª ROSANGELA DA SILVA LE'!C13+'CEI DEISE ELOY GOMES'!C13+'CEI PROFª SONIA REGINA SCUDESE '!C13+'CEI TIA ALICE'!C13+'E M BATAILLARD'!C13+'E M SOROPTIMISTA'!C13+'E M SALVADOR KLING'!C13+'ESCOLA MUNICIPALIZADA FREI ANIC'!C13+'ESCOLA SÃO JUDAS TADEU'!C13+'CEI PEDRAS BRANCAS'!C13+'CEI MARIA THEREZA KLING DO VALL'!C13+'CEI DONA ESPERANZA DE BOURBON D'!C13+'CEI GIUSEPPE-NEVA VOLONTERIO'!C13+'CENTRO DE EDUCAÇÃO INFANTIL SÃO'!C13+'E M LEONARDO BOFF'!C13+'ESCOLA MUNICIPAL GENERAL HEITOR'!C13+'E M JOHANN NOEL'!C13+'ESCOLA SANTA MARIA GORETTI'!C13+'ESCOLA SANTA RITA DE CASSIA'!C13+'ESCOLA SÃO JOÃO BATISTA'!C13+'CEI CASA DA SOLIDARIEDADE DE NO'!C13+'CEI A SEMENTEIRA'!C13+'CEI VILA SAO JOSE'!C13+'E M DR RUBENS DE CASTRO BOMTEMP'!C13+'CEI FREI LEÃO'!C13+'CEI SÃO JOÃO BATISTA'!C13+'CEI JURACI PINTO DO AMARAL DE C'!C13+'E M PEDRO AMADO'!C13+'E M ABELARDO DE LAMARE'!C13+'ESCOLA MUNICIPAL SENADOR MARIO '!C13+'ESCOLA PAROQUIAL SÃO PIO X'!C13+'CEI SÃO CHARBEL'!C13+'E M ROSALINA NICOLAY'!C13+'CEI INÊS BELARMINO DE SOUZA'!C13+'E M PROFª MARIA DA GLÓRIA QUEIR'!C13+'CENTRO EDUCACIONAL COMUNIDADE S'!C13+'CEI ROMANO CANAVESE'!C13+'CEI CÉLIA LÔBO PAULO'!C13+'CEI PROFª DORA KILLER'!C13+'CEI ALTO INDEPENDÊNCIA'!C13+'ESCOLA MUNICIPAL ALTO INDEPENDÊ'!C13+'E M PAPA JOÃO PAULO II'!C13+'CEI ANDRÉ REBOUÇAS'!C13+'CEI PROFª HERMÍNIA MATHEUS'!C13+'ESCOLA MUNICIPAL MAJOR JÚLIO FR'!C13+'E M ALMIRANTE TAMANDARÉ'!C13+'ESCOLA PAROQUIAL CARLOS DEMIÁ'!C13+'CENTRO PAROQUIAL DE EDUCAÇÃO IN'!C13+'CEI IRMÃ SILVANA'!C13+'CEI OLÍVIA MACHADO DA COSTA NOG'!C13+'E M GOVERNADOR MARCELLO ALENCAR'!C13+'E M PROFESSOR FLÁVIO MACIEL'!C13+'E M PROFª JANDIRA PEIXOTO BORDI'!C13+'E M STEFAN ZWEIG'!C13+'ESCOLA PAROQUIAL BOM JESUS'!C13+'CEI MARLI SOARES FERREIRA NETTO'!C13+'CENTRO DE EDUCAÇÃO INFANTIL CHI'!C13+'CEI VILA IPANEMA'!C13+'E M ROBERT KENNEDY'!C13+'ESCOLA MUNICIPAL ANA MOHAMMAD'!C13+'ESCOLA SÃO CRISTÓVÃO'!C13+'CEI DÉA LÚCIA CORDEIRO'!C13+'CEI SAGRADA FAMÍLIA'!C13+'CEI SÃO JOSÉ DAS OBLATAS DE NAZ'!C13+'ESCOLA MUNICIPAL JORGE AMADO'!C13+'E M FÁBRICA DO SABER'!C13+'CIEP BRIZOLÃO 474 MAESTRO GUERR'!C13+'CENTRO DE ENSINO PROF DARCY RIB'!C13+'CEI ANDRÉ VANZAN'!C13+'CENTRO DE EDUCAÇÃO INFANTIL CAR'!C13+'CEI BOA VISTA'!C13+'ASSOCIAÇÃO DA CRECHE SÃO FRANCI'!C13+'ESCOLA MUNICIPAL PAULO SALDANHA'!C13+'ESCOLA MUNICIPAL LÚCIA DE ALMEI'!C13+'E M DOM MANOEL PEDRO DA CUNHA C'!C13+'ESCOLA SÃO GERALDO'!C13+'CEI LULU MONTEIRO DE CASTRO'!C13+'CEI CARANGOLA'!C13+'ASSOCIAÇÃO RECREAR'!C13+'CENTRO DE EDUCAÇÃO INFANTIL CAS'!C13+'E M ROSEMIRA DE OLIVEIRA CAVALC'!C13+'E MZDA CARMEM NUNES MARTINS'!C13+'CEI SÃO JOSÉ DO ITAMARATI'!C13+'E M DUQUE DE CAXIAS'!C13+'CENTRO DE EDUCAÇÃO INFANTIL 2'!C13+'E M ANTÔNIO LEITE GARCIA'!C13+'ESCOLA PAROQUIAL DA ALCOBAÇA'!C13+'CENTRO DE EDUCAÇÃO INFANTIL LOT'!C13+'ESCOLA PAROQUIAL DO LOTEAMENTO '!C13+'E M PROF JOAQUIM DEISTER'!C13+'E M MARIETA GONÇALVES'!C13+'ESCOLA MUNICIPAL ODETTE YOUNG M'!C13+'ESCOLA MUNICIPAL PROFESSOR JOSE'!C13+'E M HERCÍLIA HENRIQUES MORET'!C13+'COLEGIO VICENTINO PADRE CORRÊA'!C13+'CEI PROFª MARLUCE DE SOUZA PEST'!C13+'CEI IRINEU MARINHO'!C13+'CEI DAGMAR ROLANDO DE OLIVEIRA'!C13+'CEI NOSSA SENHORA DA GLÓRIA'!C13+'E M PROF NILTON COSTA PEREIRA D'!C13+'CENTRO DE EDUCAÇÃO INFANTIL SÉR'!C13+'CEI SANTO ANTÔNIO AGOSTINHO'!C13+'CEI OSWALDO CRUZ'!C13+'E M MAGDALENA TAGLIAFERRO'!C13+'ESCOLA SÃO JOSÉ DO CAETITU'!C13+'CRECHE-ESCOLA CASTELO SÃO MANOE'!C13+'CEI THEREZINHA DE JESUS LIMA'!C13+'ESCOLA MUNICIPAL PROFESSOR PAUL'!C13+'COLÉGIO ANGLICANO DE ARARAS'!C13+'ESCOLA PAROQUIAL SANTA BERNADET'!C13+'CEI VISTA ALEGRE'!C13+'CEI DENISE BESSA DE OLIVA MAYA'!C13+'CEI VIDEIRINHA'!C13+'E M AMÉRICO FERNANDES RIBEIRO'!C13+'ESCOLA MUNICIPAL AUGUSTO PUGNAL'!C13+'ESCOLA MUNICIPAL CELINA SCHECHN'!C13+'E M DARCY CORREA DA VEIGA'!C13+'E M DR PAULA BUARQUE'!C13+'LICEU SÃO JOSÉ DE ITAIPAVA'!C13+'CEI LUIZ MARCHIORI'!C13+'CENTRO DE EDUCAÇÃO INFANTIL AUG'!C13+'CEI PROFª ADRIANA CONSTÂNCIO TR'!C13+'E M AMÉLIA ANTUNES RABELLO'!C13+'CEI PREFEITO SÉRGIO FADEL'!C13+'E M DR THEODORO MACHADO'!C13+'ESCOLA SANTO ANTÔNIO'!C13+'E M TAQUARIL'!C13+'E M MONSENHOR JOÃO DE DEUS RODR'!C13+'CENTRO DE REFERÊNCIA EM EDUC 2'!C13+'CEI PROFª GRAÇA COSTA'!C13+'CEI VILA LEOPOLDINA'!C13+'CEI NILO PEÇANHA'!C13+'E MZDA SANTA TEREZINHA'!C13+'CEI CRIANÇA SANTA EDWIGES'!C13+'E M ARNALDO DYCKERHOFF'!C13+'E M CARLOS CANEDO'!C13+'E M BEATRIZ ZALESKI'!C13+'E M ANTÔNIO JOSÉ DE LIMA'!C13+'E M FELIX WAN ERVEN DE BARROS'!C13+'ESCOLA MUNICIPAL HILDEBRANDO DE'!C13+'E M OSWALDO DA COSTA FRIAS'!C13+'E MZDA AVELINO DE CARVALHO'!C13+'ESCOLA MUNICIPALIZADA MOYSÉS FU'!C13+'CEI ANGELA MARIA DA CONCEIÇÃO S'!C13+'CEI JOSÉ GONÇALVES DA MOTTA'!C13+'E M DR BARROS FRANCO'!C13+'E M MAJOR THEÓFILO DE CARVALHO'!C13+'E M JOÃO KOPKE'!C13+'CEI ASSOCIAÇÃO BENEFICENTE FAZE'!C13+'ESCOLA SAO FRANCISCO DE ASSIS'!C13+'CEI SÃO FRANCISCO ASSIS'!C13+'CEI ALDEIA DA CRIANCA'!C13+'ESCOLA MUNICIPAL ODETTE FONSECA'!C13+'CEI ANA CAROLINA TELLES'!C13+'E M SEBASTIÃO LACERDA'!C13+'E M DOM PEDRO DE ALCÂNTARA'!C13+'ESCOLA NOSSA SENHORA DE FÁTIMA'!C13+'ESCOLA PAROQUIAL SÃO FRANCISCO '!C13+'E M MONSENHOR CIRILLO CALAON'!C13 | D9: =B9-C9 | E9: ='Entrada de Dados'!G2 | F9: =D9*E9
A10: ='Entrada de Dados'!H5 | B10: ='Entrada de Dados'!H197 | C10: ='E M ROTARY'!C14+'E M DE EDUCAÇÃO ESPECIAL SANTOS'!C14+'LICEU MUN PREFEITO CORDOLINO AM'!C14+'E M PREFEITO JAMIL SABRÁ'!C14+'LICEU MUNICIPAL CARLOS CHAGAS F'!C14+'E M PAULO FREIRE'!C14+'E M PROFª MARIA CAMPOS DA SILVA'!C14+'CASA DA EDUCAÇÃO VISCONDE DE MA'!C14+'CENTRO DE REFERÊNCIA EM EDUCAÇÃ'!C14+'ESCOLA SANTA LUIZA DE MARILLAC'!C14+'ESCOLA DOMÉSTICA NOSSA SENHORA '!C14+'ESCOLA MONSENHOR GENTIL'!C14+'ESCOLA PAROQUIAL NOSSA SENHORA '!C14+'ESCOLA PAROQUIAL SÃO PEDRO DE A'!C14+'CEI TERRA SANTA'!C14+'CEI PRIMEIRA INFÂNCIA'!C14+'CEI PROFª PATRÍCIA FERREIRA E S'!C14+'CEI DRA ZILDA ARNS NEUMANN'!C14+'CENTRO DE EDUCAÇÃO INFANTIL PRO'!C14+'CEI MONSENHOR PAULO ELIAS DAHER'!C14+'COLÉGIO GUNNAR VINGREN DE PETRÓ'!C14+'EDUCANDÁRIO TERRA SANTA'!C14+'CEI LIONS CLUBE DE PETRÓPOLIS'!C14+'ESCOLA PAROQUIAL NOSSA SENHO 2'!C14+'CENTRO DE EDUCAÇÃO INFANTIL IRM'!C14+'E M LUIZ CARLOS SOARES'!C14+'ESCOLA GERMANO VALENTE'!C14+'ESCOLA PAROQUIAL NOSSA SENHO 3'!C14+'CEI JORGE ROLANDO DA SILVA'!C14+'E M CLEMENTE FERNANDES'!C14+'E M GERALDO VENTURA DIAS'!C14+'ESCOLA DAS COMUNIDADES SANTO AN'!C14+'CEI PROFª ROSANGELA DA SILVA LE'!C14+'CEI DEISE ELOY GOMES'!C14+'CEI PROFª SONIA REGINA SCUDESE '!C14+'CEI TIA ALICE'!C14+'E M BATAILLARD'!C14+'E M SOROPTIMISTA'!C14+'E M SALVADOR KLING'!C14+'ESCOLA MUNICIPALIZADA FREI ANIC'!C14+'ESCOLA SÃO JUDAS TADEU'!C14+'CEI PEDRAS BRANCAS'!C14+'CEI MARIA THEREZA KLING DO VALL'!C14+'CEI DONA ESPERANZA DE BOURBON D'!C14+'CEI GIUSEPPE-NEVA VOLONTERIO'!C14+'CENTRO DE EDUCAÇÃO INFANTIL SÃO'!C14+'E M LEONARDO BOFF'!C14+'ESCOLA MUNICIPAL GENERAL HEITOR'!C14+'E M JOHANN NOEL'!C14+'ESCOLA SANTA MARIA GORETTI'!C14+'ESCOLA SANTA RITA DE CASSIA'!C14+'ESCOLA SÃO JOÃO BATISTA'!C14+'CEI CASA DA SOLIDARIEDADE DE NO'!C14+'CEI A SEMENTEIRA'!C14+'CEI VILA SAO JOSE'!C14+'E M DR RUBENS DE CASTRO BOMTEMP'!C14+'CEI FREI LEÃO'!C14+'CEI SÃO JOÃO BATISTA'!C14+'CEI JURACI PINTO DO AMARAL DE C'!C14+'E M PEDRO AMADO'!C14+'E M ABELARDO DE LAMARE'!C14+'ESCOLA MUNICIPAL SENADOR MARIO '!C14+'ESCOLA PAROQUIAL SÃO PIO X'!C14+'CEI SÃO CHARBEL'!C14+'E M ROSALINA NICOLAY'!C14+'CEI INÊS BELARMINO DE SOUZA'!C14+'E M PROFª MARIA DA GLÓRIA QUEIR'!C14+'CENTRO EDUCACIONAL COMUNIDADE S'!C14+'CEI ROMANO CANAVESE'!C14+'CEI CÉLIA LÔBO PAULO'!C14+'CEI PROFª DORA KILLER'!C14+'CEI ALTO INDEPENDÊNCIA'!C14+'ESCOLA MUNICIPAL ALTO INDEPENDÊ'!C14+'E M PAPA JOÃO PAULO II'!C14+'CEI ANDRÉ REBOUÇAS'!C14+'CEI PROFª HERMÍNIA MATHEUS'!C14+'ESCOLA MUNICIPAL MAJOR JÚLIO FR'!C14+'E M ALMIRANTE TAMANDARÉ'!C14+'ESCOLA PAROQUIAL CARLOS DEMIÁ'!C14+'CENTRO PAROQUIAL DE EDUCAÇÃO IN'!C14+'CEI IRMÃ SILVANA'!C14+'CEI OLÍVIA MACHADO DA COSTA NOG'!C14+'E M GOVERNADOR MARCELLO ALENCAR'!C14+'E M PROFESSOR FLÁVIO MACIEL'!C14+'E M PROFª JANDIRA PEIXOTO BORDI'!C14+'E M STEFAN ZWEIG'!C14+'ESCOLA PAROQUIAL BOM JESUS'!C14+'CEI MARLI SOARES FERREIRA NETTO'!C14+'CENTRO DE EDUCAÇÃO INFANTIL CHI'!C14+'CEI VILA IPANEMA'!C14+'E M ROBERT KENNEDY'!C14+'ESCOLA MUNICIPAL ANA MOHAMMAD'!C14+'ESCOLA SÃO CRISTÓVÃO'!C14+'CEI DÉA LÚCIA CORDEIRO'!C14+'CEI SAGRADA FAMÍLIA'!C14+'CEI SÃO JOSÉ DAS OBLATAS DE NAZ'!C14+'ESCOLA MUNICIPAL JORGE AMADO'!C14+'E M FÁBRICA DO SABER'!C14+'CIEP BRIZOLÃO 474 MAESTRO GUERR'!C14+'CENTRO DE ENSINO PROF DARCY RIB'!C14+'CEI ANDRÉ VANZAN'!C14+'CENTRO DE EDUCAÇÃO INFANTIL CAR'!C14+'CEI BOA VISTA'!C14+'ASSOCIAÇÃO DA CRECHE SÃO FRANCI'!C14+'ESCOLA MUNICIPAL PAULO SALDANHA'!C14+'ESCOLA MUNICIPAL LÚCIA DE ALMEI'!C14+'E M DOM MANOEL PEDRO DA CUNHA C'!C14+'ESCOLA SÃO GERALDO'!C14+'CEI LULU MONTEIRO DE CASTRO'!C14+'CEI CARANGOLA'!C14+'ASSOCIAÇÃO RECREAR'!C14+'CENTRO DE EDUCAÇÃO INFANTIL CAS'!C14+'E M ROSEMIRA DE OLIVEIRA CAVALC'!C14+'E MZDA CARMEM NUNES MARTINS'!C14+'CEI SÃO JOSÉ DO ITAMARATI'!C14+'E M DUQUE DE CAXIAS'!C14+'CENTRO DE EDUCAÇÃO INFANTIL 2'!C14+'E M ANTÔNIO LEITE GARCIA'!C14+'ESCOLA PAROQUIAL DA ALCOBAÇA'!C14+'CENTRO DE EDUCAÇÃO INFANTIL LOT'!C14+'ESCOLA PAROQUIAL DO LOTEAMENTO '!C14+'E M PROF JOAQUIM DEISTER'!C14+'E M MARIETA GONÇALVES'!C14+'ESCOLA MUNICIPAL ODETTE YOUNG M'!C14+'ESCOLA MUNICIPAL PROFESSOR JOSE'!C14+'E M HERCÍLIA HENRIQUES MORET'!C14+'COLEGIO VICENTINO PADRE CORRÊA'!C14+'CEI PROFª MARLUCE DE SOUZA PEST'!C14+'CEI IRINEU MARINHO'!C14+'CEI DAGMAR ROLANDO DE OLIVEIRA'!C14+'CEI NOSSA SENHORA DA GLÓRIA'!C14+'E M PROF NILTON COSTA PEREIRA D'!C14+'CENTRO DE EDUCAÇÃO INFANTIL SÉR'!C14+'CEI SANTO ANTÔNIO AGOSTINHO'!C14+'CEI OSWALDO CRUZ'!C14+'E M MAGDALENA TAGLIAFERRO'!C14+'ESCOLA SÃO JOSÉ DO CAETITU'!C14+'CRECHE-ESCOLA CASTELO SÃO MANOE'!C14+'CEI THEREZINHA DE JESUS LIMA'!C14+'ESCOLA MUNICIPAL PROFESSOR PAUL'!C14+'COLÉGIO ANGLICANO DE ARARAS'!C14+'ESCOLA PAROQUIAL SANTA BERNADET'!C14+'CEI VISTA ALEGRE'!C14+'CEI DENISE BESSA DE OLIVA MAYA'!C14+'CEI VIDEIRINHA'!C14+'E M AMÉRICO FERNANDES RIBEIRO'!C14+'ESCOLA MUNICIPAL AUGUSTO PUGNAL'!C14+'ESCOLA MUNICIPAL CELINA SCHECHN'!C14+'E M DARCY CORREA DA VEIGA'!C14+'E M DR PAULA BUARQUE'!C14+'LICEU SÃO JOSÉ DE ITAIPAVA'!C14+'CEI LUIZ MARCHIORI'!C14+'CENTRO DE EDUCAÇÃO INFANTIL AUG'!C14+'CEI PROFª ADRIANA CONSTÂNCIO TR'!C14+'E M AMÉLIA ANTUNES RABELLO'!C14+'CEI PREFEITO SÉRGIO FADEL'!C14+'E M DR THEODORO MACHADO'!C14+'ESCOLA SANTO ANTÔNIO'!C14+'E M TAQUARIL'!C14+'E M MONSENHOR JOÃO DE DEUS RODR'!C14+'CENTRO DE REFERÊNCIA EM EDUC 2'!C14+'CEI PROFª GRAÇA COSTA'!C14+'CEI VILA LEOPOLDINA'!C14+'CEI NILO PEÇANHA'!C14+'E MZDA SANTA TEREZINHA'!C14+'CEI CRIANÇA SANTA EDWIGES'!C14+'E M ARNALDO DYCKERHOFF'!C14+'E M CARLOS CANEDO'!C14+'E M BEATRIZ ZALESKI'!C14+'E M ANTÔNIO JOSÉ DE LIMA'!C14+'E M FELIX WAN ERVEN DE BARROS'!C14+'ESCOLA MUNICIPAL HILDEBRANDO DE'!C14+'E M OSWALDO DA COSTA FRIAS'!C14+'E MZDA AVELINO DE CARVALHO'!C14+'ESCOLA MUNICIPALIZADA MOYSÉS FU'!C14+'CEI ANGELA MARIA DA CONCEIÇÃO S'!C14+'CEI JOSÉ GONÇALVES DA MOTTA'!C14+'E M DR BARROS FRANCO'!C14+'E M MAJOR THEÓFILO DE CARVALHO'!C14+'E M JOÃO KOPKE'!C14+'CEI ASSOCIAÇÃO BENEFICENTE FAZE'!C14+'ESCOLA SAO FRANCISCO DE ASSIS'!C14+'CEI SÃO FRANCISCO ASSIS'!C14+'CEI ALDEIA DA CRIANCA'!C14+'ESCOLA MUNICIPAL ODETTE FONSECA'!C14+'CEI ANA CAROLINA TELLES'!C14+'E M SEBASTIÃO LACERDA'!C14+'E M DOM PEDRO DE ALCÂNTARA'!C14+'ESCOLA NOSSA SENHORA DE FÁTIMA'!C14+'ESCOLA PAROQUIAL SÃO FRANCISCO '!C14+'E M MONSENHOR CIRILLO CALAON'!C14 | D10: =B10-C10 | E10: ='Entrada de Dados'!H2 | F10: =D10*E10
A11: ='Entrada de Dados'!I5 | B11: ='Entrada de Dados'!I197 | C11: ='E M ROTARY'!C15+'E M DE EDUCAÇÃO ESPECIAL SANTOS'!C15+'LICEU MUN PREFEITO CORDOLINO AM'!C15+'E M PREFEITO JAMIL SABRÁ'!C15+'LICEU MUNICIPAL CARLOS CHAGAS F'!C15+'E M PAULO FREIRE'!C15+'E M PROFª MARIA CAMPOS DA SILVA'!C15+'CASA DA EDUCAÇÃO VISCONDE DE MA'!C15+'CENTRO DE REFERÊNCIA EM EDUCAÇÃ'!C15+'ESCOLA SANTA LUIZA DE MARILLAC'!C15+'ESCOLA DOMÉSTICA NOSSA SENHORA '!C15+'ESCOLA MONSENHOR GENTIL'!C15+'ESCOLA PAROQUIAL NOSSA SENHORA '!C15+'ESCOLA PAROQUIAL SÃO PEDRO DE A'!C15+'CEI TERRA SANTA'!C15+'CEI PRIMEIRA INFÂNCIA'!C15+'CEI PROFª PATRÍCIA FERREIRA E S'!C15+'CEI DRA ZILDA ARNS NEUMANN'!C15+'CENTRO DE EDUCAÇÃO INFANTIL PRO'!C15+'CEI MONSENHOR PAULO ELIAS DAHER'!C15+'COLÉGIO GUNNAR VINGREN DE PETRÓ'!C15+'EDUCANDÁRIO TERRA SANTA'!C15+'CEI LIONS CLUBE DE PETRÓPOLIS'!C15+'ESCOLA PAROQUIAL NOSSA SENHO 2'!C15+'CENTRO DE EDUCAÇÃO INFANTIL IRM'!C15+'E M LUIZ CARLOS SOARES'!C15+'ESCOLA GERMANO VALENTE'!C15+'ESCOLA PAROQUIAL NOSSA SENHO 3'!C15+'CEI JORGE ROLANDO DA SILVA'!C15+'E M CLEMENTE FERNANDES'!C15+'E M GERALDO VENTURA DIAS'!C15+'ESCOLA DAS COMUNIDADES SANTO AN'!C15+'CEI PROFª ROSANGELA DA SILVA LE'!C15+'CEI DEISE ELOY GOMES'!C15+'CEI PROFª SONIA REGINA SCUDESE '!C15+'CEI TIA ALICE'!C15+'E M BATAILLARD'!C15+'E M SOROPTIMISTA'!C15+'E M SALVADOR KLING'!C15+'ESCOLA MUNICIPALIZADA FREI ANIC'!C15+'ESCOLA SÃO JUDAS TADEU'!C15+'CEI PEDRAS BRANCAS'!C15+'CEI MARIA THEREZA KLING DO VALL'!C15+'CEI DONA ESPERANZA DE BOURBON D'!C15+'CEI GIUSEPPE-NEVA VOLONTERIO'!C15+'CENTRO DE EDUCAÇÃO INFANTIL SÃO'!C15+'E M LEONARDO BOFF'!C15+'ESCOLA MUNICIPAL GENERAL HEITOR'!C15+'E M JOHANN NOEL'!C15+'ESCOLA SANTA MARIA GORETTI'!C15+'ESCOLA SANTA RITA DE CASSIA'!C15+'ESCOLA SÃO JOÃO BATISTA'!C15+'CEI CASA DA SOLIDARIEDADE DE NO'!C15+'CEI A SEMENTEIRA'!C15+'CEI VILA SAO JOSE'!C15+'E M DR RUBENS DE CASTRO BOMTEMP'!C15+'CEI FREI LEÃO'!C15+'CEI SÃO JOÃO BATISTA'!C15+'CEI JURACI PINTO DO AMARAL DE C'!C15+'E M PEDRO AMADO'!C15+'E M ABELARDO DE LAMARE'!C15+'ESCOLA MUNICIPAL SENADOR MARIO '!C15+'ESCOLA PAROQUIAL SÃO PIO X'!C15+'CEI SÃO CHARBEL'!C15+'E M ROSALINA NICOLAY'!C15+'CEI INÊS BELARMINO DE SOUZA'!C15+'E M PROFª MARIA DA GLÓRIA QUEIR'!C15+'CENTRO EDUCACIONAL COMUNIDADE S'!C15+'CEI ROMANO CANAVESE'!C15+'CEI CÉLIA LÔBO PAULO'!C15+'CEI PROFª DORA KILLER'!C15+'CEI ALTO INDEPENDÊNCIA'!C15+'ESCOLA MUNICIPAL ALTO INDEPENDÊ'!C15+'E M PAPA JOÃO PAULO II'!C15+'CEI ANDRÉ REBOUÇAS'!C15+'CEI PROFª HERMÍNIA MATHEUS'!C15+'ESCOLA MUNICIPAL MAJOR JÚLIO FR'!C15+'E M ALMIRANTE TAMANDARÉ'!C15+'ESCOLA PAROQUIAL CARLOS DEMIÁ'!C15+'CENTRO PAROQUIAL DE EDUCAÇÃO IN'!C15+'CEI IRMÃ SILVANA'!C15+'CEI OLÍVIA MACHADO DA COSTA NOG'!C15+'E M GOVERNADOR MARCELLO ALENCAR'!C15+'E M PROFESSOR FLÁVIO MACIEL'!C15+'E M PROFª JANDIRA PEIXOTO BORDI'!C15+'E M STEFAN ZWEIG'!C15+'ESCOLA PAROQUIAL BOM JESUS'!C15+'CEI MARLI SOARES FERREIRA NETTO'!C15+'CENTRO DE EDUCAÇÃO INFANTIL CHI'!C15+'CEI VILA IPANEMA'!C15+'E M ROBERT KENNEDY'!C15+'ESCOLA MUNICIPAL ANA MOHAMMAD'!C15+'ESCOLA SÃO CRISTÓVÃO'!C15+'CEI DÉA LÚCIA CORDEIRO'!C15+'CEI SAGRADA FAMÍLIA'!C15+'CEI SÃO JOSÉ DAS OBLATAS DE NAZ'!C15+'ESCOLA MUNICIPAL JORGE AMADO'!C15+'E M FÁBRICA DO SABER'!C15+'CIEP BRIZOLÃO 474 MAESTRO GUERR'!C15+'CENTRO DE ENSINO PROF DARCY RIB'!C15+'CEI ANDRÉ VANZAN'!C15+'CENTRO DE EDUCAÇÃO INFANTIL CAR'!C15+'CEI BOA VISTA'!C15+'ASSOCIAÇÃO DA CRECHE SÃO FRANCI'!C15+'ESCOLA MUNICIPAL PAULO SALDANHA'!C15+'ESCOLA MUNICIPAL LÚCIA DE ALMEI'!C15+'E M DOM MANOEL PEDRO DA CUNHA C'!C15+'ESCOLA SÃO GERALDO'!C15+'CEI LULU MONTEIRO DE CASTRO'!C15+'CEI CARANGOLA'!C15+'ASSOCIAÇÃO RECREAR'!C15+'CENTRO DE EDUCAÇÃO INFANTIL CAS'!C15+'E M ROSEMIRA DE OLIVEIRA CAVALC'!C15+'E MZDA CARMEM NUNES MARTINS'!C15+'CEI SÃO JOSÉ DO ITAMARATI'!C15+'E M DUQUE DE CAXIAS'!C15+'CENTRO DE EDUCAÇÃO INFANTIL 2'!C15+'E M ANTÔNIO LEITE GARCIA'!C15+'ESCOLA PAROQUIAL DA ALCOBAÇA'!C15+'CENTRO DE EDUCAÇÃO INFANTIL LOT'!C15+'ESCOLA PAROQUIAL DO LOTEAMENTO '!C15+'E M PROF JOAQUIM DEISTER'!C15+'E M MARIETA GONÇALVES'!C15+'ESCOLA MUNICIPAL ODETTE YOUNG M'!C15+'ESCOLA MUNICIPAL PROFESSOR JOSE'!C15+'E M HERCÍLIA HENRIQUES MORET'!C15+'COLEGIO VICENTINO PADRE CORRÊA'!C15+'CEI PROFª MARLUCE DE SOUZA PEST'!C15+'CEI IRINEU MARINHO'!C15+'CEI DAGMAR ROLANDO DE OLIVEIRA'!C15+'CEI NOSSA SENHORA DA GLÓRIA'!C15+'E M PROF NILTON COSTA PEREIRA D'!C15+'CENTRO DE EDUCAÇÃO INFANTIL SÉR'!C15+'CEI SANTO ANTÔNIO AGOSTINHO'!C15+'CEI OSWALDO CRUZ'!C15+'E M MAGDALENA TAGLIAFERRO'!C15+'ESCOLA SÃO JOSÉ DO CAETITU'!C15+'CRECHE-ESCOLA CASTELO SÃO MANOE'!C15+'CEI THEREZINHA DE JESUS LIMA'!C15+'ESCOLA MUNICIPAL PROFESSOR PAUL'!C15+'COLÉGIO ANGLICANO DE ARARAS'!C15+'ESCOLA PAROQUIAL SANTA BERNADET'!C15+'CEI VISTA ALEGRE'!C15+'CEI DENISE BESSA DE OLIVA MAYA'!C15+'CEI VIDEIRINHA'!C15+'E M AMÉRICO FERNANDES RIBEIRO'!C15+'ESCOLA MUNICIPAL AUGUSTO PUGNAL'!C15+'ESCOLA MUNICIPAL CELINA SCHECHN'!C15+'E M DARCY CORREA DA VEIGA'!C15+'E M DR PAULA BUARQUE'!C15+'LICEU SÃO JOSÉ DE ITAIPAVA'!C15+'CEI LUIZ MARCHIORI'!C15+'CENTRO DE EDUCAÇÃO INFANTIL AUG'!C15+'CEI PROFª ADRIANA CONSTÂNCIO TR'!C15+'E M AMÉLIA ANTUNES RABELLO'!C15+'CEI PREFEITO SÉRGIO FADEL'!C15+'E M DR THEODORO MACHADO'!C15+'ESCOLA SANTO ANTÔNIO'!C15+'E M TAQUARIL'!C15+'E M MONSENHOR JOÃO DE DEUS RODR'!C15+'CENTRO DE REFERÊNCIA EM EDUC 2'!C15+'CEI PROFª GRAÇA COSTA'!C15+'CEI VILA LEOPOLDINA'!C15+'CEI NILO PEÇANHA'!C15+'E MZDA SANTA TEREZINHA'!C15+'CEI CRIANÇA SANTA EDWIGES'!C15+'E M ARNALDO DYCKERHOFF'!C15+'E M CARLOS CANEDO'!C15+'E M BEATRIZ ZALESKI'!C15+'E M ANTÔNIO JOSÉ DE LIMA'!C15+'E M FELIX WAN ERVEN DE BARROS'!C15+'ESCOLA MUNICIPAL HILDEBRANDO DE'!C15+'E M OSWALDO DA COSTA FRIAS'!C15+'E MZDA AVELINO DE CARVALHO'!C15+'ESCOLA MUNICIPALIZADA MOYSÉS FU'!C15+'CEI ANGELA MARIA DA CONCEIÇÃO S'!C15+'CEI JOSÉ GONÇALVES DA MOTTA'!C15+'E M DR BARROS FRANCO'!C15+'E M MAJOR THEÓFILO DE CARVALHO'!C15+'E M JOÃO KOPKE'!C15+'CEI ASSOCIAÇÃO BENEFICENTE FAZE'!C15+'ESCOLA SAO FRANCISCO DE ASSIS'!C15+'CEI SÃO FRANCISCO ASSIS'!C15+'CEI ALDEIA DA CRIANCA'!C15+'ESCOLA MUNICIPAL ODETTE FONSECA'!C15+'CEI ANA CAROLINA TELLES'!C15+'E M SEBASTIÃO LACERDA'!C15+'E M DOM PEDRO DE ALCÂNTARA'!C15+'ESCOLA NOSSA SENHORA DE FÁTIMA'!C15+'ESCOLA PAROQUIAL SÃO FRANCISCO '!C15+'E M MONSENHOR CIRILLO CALAON'!C15 | D11: =B11-C11 | E11: ='Entrada de Dados'!I2 | F11: =D11*E11
